Workbook

Sheet Сводка
B2: План работы отдела ОТ, ПБ и экологии — 4 квартал 2026 г.
B3: ООО «Авиационные интерьеры – СН» · 8 площадок: Москва (головной офис), Внуково, Воронеж, Жуковский, Казань, Машково, Руднево, Ульяновск
B4: Отдел: Айкешева А.К. (начальник отдела), Батушин А.В. (ведущий специалист по ООС), Грисли И.В. (специалист по ОТ). Куратор: Пенский А.К., директор по персоналу
B6: Всего мероприятий | C6: Приоритет «Высокий» | E6: Уже в работе / на согласовании | G6: Выполнено
B7: =COUNT('План 4 кв'!A6:A70) -> 57 | C7: =COUNTIF('План 4 кв'!I6:I70,"Высокий") -> 27 | E7: =COUNTIF('План 4 кв'!M6:M70,"В работе")+COUNTIF('План 4 кв'!M6:M70,"На согласовании") -> 23 | G7: =COUNTIF('План 4 кв'!M6:M70,"Выполнено") -> 0
B9: Распределение по направлениям
B10: Направление | C10: Всего | D10: Высокий | E10: Не начато | F10: В работе / согл. | G10: Выполнено | H10: % выполн.
B11: 1. Служба ОТ и СУОТ | C11: =COUNTIF('План 4 кв'!$B$6:$B$70,B11) -> 8 | D11: =COUNTIFS('План 4 кв'!$B$6:$B$70,B11,'План 4 кв'!$I$6:$I$70,"Высокий") -> 4 | E11: =COUNTIFS('План 4 кв'!$B$6:$B$70,B11,'План 4 кв'!$M$6:$M$70,"Не начато") -> 7 | F11: =COUNTIFS('План 4 кв'!$B$6:$B$70,B11,'План 4 кв'!$M$6:$M$70,"В работе")+COUNTIFS('План 4 кв'!$B$6:$B$70,B11,'План 4 кв'!$M$6:$M$70,"На согласовании") -> 1 | G11: =COUNTIFS('План 4 кв'!$B$6:$B$70,B11,'План 4 кв'!$M$6:$M$70,"Выполнено") -> 0 | H11: =IF(C11=0,0,G11/C11) -> 0
B12: 2. СОУТ и оценка профрисков | C12: =COUNTIF('План 4 кв'!$B$6:$B$70,B12) -> 6 | D12: =COUNTIFS('План 4 кв'!$B$6:$B$70,B12,'План 4 кв'!$I$6:$I$70,"Высокий") -> 4 | E12: =COUNTIFS('План 4 кв'!$B$6:$B$70,B12,'План 4 кв'!$M$6:$M$70,"Не начато") -> 5 | F12: =COUNTIFS('План 4 кв'!$B$6:$B$70,B12,'План 4 кв'!$M$6:$M$70,"В работе")+COUNTIFS('План 4 кв'!$B$6:$B$70,B12,'План 4 кв'!$M$6:$M$70,"На согласовании") -> 1 | G12: =COUNTIFS('План 4 кв'!$B$6:$B$70,B12,'План 4 кв'!$M$6:$M$70,"Выполнено") -> 0 | H12: =IF(C12=0,0,G12/C12) -> 0
B13: 3. Обучение и инструктажи | C13: =COUNTIF('План 4 кв'!$B$6:$B$70,B13) -> 6 | D13: =COUNTIFS('План 4 кв'!$B$6:$B$70,B13,'План 4 кв'!$I$6:$I$70,"Высокий") -> 5 | E13: =COUNTIFS('План 4 кв'!$B$6:$B$70,B13,'План 4 кв'!$M$6:$M$70,"Не начато") -> 1 | F13: =COUNTIFS('План 4 кв'!$B$6:$B$70,B13,'План 4 кв'!$M$6:$M$70,"В работе")+COUNTIFS('План 4 кв'!$B$6:$B$70,B13,'План 4 кв'!$M$6:$M$70,"На согласовании") -> 5 | G13: =COUNTIFS('План 4 кв'!$B$6:$B$70,B13,'План 4 кв'!$M$6:$M$70,"Выполнено") -> 0 | H13: =IF(C13=0,0,G13/C13) -> 0
B14: 4. Медосмотры и психосвидетельствование | C14: =COUNTIF('План 4 кв'!$B$6:$B$70,B14) -> 5 | D14: =COUNTIFS('План 4 кв'!$B$6:$B$70,B14,'План 4 кв'!$I$6:$I$70,"Высокий") -> 4 | E14: =COUNTIFS('План 4 кв'!$B$6:$B$70,B14,'План 4 кв'!$M$6:$M$70,"Не начато") -> 3 | F14: =COUNTIFS('План 4 кв'!$B$6:$B$70,B14,'План 4 кв'!$M$6:$M$70,"В работе")+COUNTIFS('План 4 кв'!$B$6:$B$70,B14,'План 4 кв'!$M$6:$M$70,"На согласовании") -> 2 | G14: =COUNTIFS('План 4 кв'!$B$6:$B$70,B14,'План 4 кв'!$M$6:$M$70,"Выполнено") -> 0 | H14: =IF(C14=0,0,G14/C14) -> 0
B15: 5. СИЗ, смывающие средства, аптечки | C15: =COUNTIF('План 4 кв'!$B$6:$B$70,B15) -> 4 | D15: =COUNTIFS('План 4 кв'!$B$6:$B$70,B15,'План 4 кв'!$I$6:$I$70,"Высокий") -> 2 | E15: =COUNTIFS('План 4 кв'!$B$6:$B$70,B15,'План 4 кв'!$M$6:$M$70,"Не начато") -> 2 | F15: =COUNTIFS('План 4 кв'!$B$6:$B$70,B15,'План 4 кв'!$M$6:$M$70,"В работе")+COUNTIFS('План 4 кв'!$B$6:$B$70,B15,'План 4 кв'!$M$6:$M$70,"На согласовании") -> 2 | G15: =COUNTIFS('План 4 кв'!$B$6:$B$70,B15,'План 4 кв'!$M$6:$M$70,"Выполнено") -> 0 | H15: =IF(C15=0,0,G15/C15) -> 0
B16: 6. Несчастные случаи, микротравмы, подрядчики | C16: =COUNTIF('План 4 кв'!$B$6:$B$70,B16) -> 3 | D16: =COUNTIFS('План 4 кв'!$B$6:$B$70,B16,'План 4 кв'!$I$6:$I$70,"Высокий") -> 0 | E16: =COUNTIFS('План 4 кв'!$B$6:$B$70,B16,'План 4 кв'!$M$6:$M$70,"Не начато") -> 3 | F16: =COUNTIFS('План 4 кв'!$B$6:$B$70,B16,'План 4 кв'!$M$6:$M$70,"В работе")+COUNTIFS('План 4 кв'!$B$6:$B$70,B16,'План 4 кв'!$M$6:$M$70,"На согласовании") -> 0 | G16: =COUNTIFS('План 4 кв'!$B$6:$B$70,B16,'План 4 кв'!$M$6:$M$70,"Выполнено") -> 0 | H16: =IF(C16=0,0,G16/C16) -> 0
B17: 7. Экология и обращение с отходами | C17: =COUNTIF('План 4 кв'!$B$6:$B$70,B17) -> 17 | D17: =COUNTIFS('План 4 кв'!$B$6:$B$70,B17,'План 4 кв'!$I$6:$I$70,"Высокий") -> 7 | E17: =COUNTIFS('План 4 кв'!$B$6:$B$70,B17,'План 4 кв'!$M$6:$M$70,"Не начато") -> 9 | F17: =COUNTIFS('План 4 кв'!$B$6:$B$70,B17,'План 4 кв'!$M$6:$M$70,"В работе")+COUNTIFS('План 4 кв'!$B$6:$B$70,B17,'План 4 кв'!$M$6:$M$70,"На согласовании") -> 8 | G17: =COUNTIFS('План 4 кв'!$B$6:$B$70,B17,'План 4 кв'!$M$6:$M$70,"Выполнено") -> 0 | H17: =IF(C17=0,0,G17/C17) -> 0
B18: 8. Управление отделом и отчётность | C18: =COUNTIF('План 4 кв'!$B$6:$B$70,B18) -> 8 | D18: =COUNTIFS('План 4 кв'!$B$6:$B$70,B18,'План 4 кв'!$I$6:$I$70,"Высокий") -> 1 | E18: =COUNTIFS('План 4 кв'!$B$6:$B$70,B18,'План 4 кв'!$M$6:$M$70,"Не начато") -> 4 | F18: =COUNTIFS('План 4 кв'!$B$6:$B$70,B18,'План 4 кв'!$M$6:$M$70,"В работе")+COUNTIFS('План 4 кв'!$B$6:$B$70,B18,'План 4 кв'!$M$6:$M$70,"На согласовании") -> 4 | G18: =COUNTIFS('План 4 кв'!$B$6:$B$70,B18,'План 4 кв'!$M$6:$M$70,"Выполнено") -> 0 | H18: =IF(C18=0,0,G18/C18) -> 0
B19: ИТОГО | C19: =SUM(C11:C18) -> 57 | D19: =SUM(D11:D18) -> 27 | E19: =SUM(E11:E18) -> 34 | F19: =SUM(F11:F18) -> 23 | G19: =SUM(G11:G18) -> 0 | H19: =IF(C19=0,0,G19/C19) -> 0
B21: Ключевые результаты к 31.12.2026
B22: ▪ СУОТ приведена в соответствие с приказом № 776н: служба ОТ формализована, ответственные назначены, введён трёхступенчатый контроль.
B23: ▪ СОУТ офисного персонала головного подразделения завершена; утверждён график СОУТ обособленных подразделений на 2027 г.
B24: ▪ Инструктажи (вводный, первичный, повторный) проводятся на всех площадках; бэк-офис обучен по программе Б и первой помощи.
B25: ▪ Проведён периодический медосмотр; организовано психиатрическое освидетельствование.
B26: ▪ Нормы выдачи СИЗ утверждены по всем профессиям; введены личные карточки учёта.
B27: ▪ Экоаудит 8 площадок завершён; поданы заявки на постановку на учёт НВОС (Воронеж, Казань, Ульяновск); ЖДО ведутся на всех площадках.
B28: ▪ Закрыто 12 нарушений из акта проверки от 11.08.2026 (полностью или с переходом работ по ОПР и СОУТ ОП на 2027 г. в рамках утверждённого бюджета).
B29: ▪ Утверждён План мероприятий по улучшению условий и охраны труда на 2027 г. со сметой.
B31: Контрольные точки квартала
B32: Подписаны приказы: ответственные по ОТ, инструктажи, ответственные по экологии; договор на медосмотры | H32: 46304
B33: Подписан договор на СОУТ; получен доступ в ЛК Росприроднадзора | H33: 46311
B34: Авансовый платёж за НВОС за 3 кв. (Машково) — ст. 16.4 7-ФЗ | H34: 46315
B35: Итоговое интервью по испытательному сроку: пп. 8–11 чек-листа | H35: 46329
B36: Завершён экологический аудит 8 площадок | H36: 46346
B37: Завершён периодический медосмотр; обучены рабочие из перечня не прошедших | H37: 46374
B38: Отчёт о СОУТ головного офиса утверждён; отчёт отдела за 4 кв. сдан | H38: 46386

Sheet План 4 кв
A1: ПЛАН РАБОТЫ ОТДЕЛА ОХРАНЫ ТРУДА, ПРОМЫШЛЕННОЙ БЕЗОПАСНОСТИ И ЭКОЛОГИИ НА 4 КВАРТАЛ 2026 г.
A2: ООО «Авиационные интерьеры – СН» · период 01.10.2026–31.12.2026 · основание: акт проверки от 11.08.2026, отчёт HR за 3 кв. 2026, дорожная карта по экологии, чек-лист ИС
A3: Столбец «Статус» — выпадающий список, обновлять по факту. Диаграмма справа строится автоматически по датам «Начало» и «Срок» (синий — в работе/план, зелёный — выполнено).
A4: № | B4: Направление | C4: Мероприятие | D4: Результат / документ | E4: Площадки | F4: Ответственный | G4: Начало | H4: Срок | I4: Приоритет | J4: Основание (источник) | K4: Риск по КоАП (юрлицо) | L4: Задел 3 кв. / комментарий | M4: Статус | N4: ОКТЯБРЬ | S4: НОЯБРЬ | W4: ДЕКАБРЬ
N5: 46293 | O5: 46300 | P5: 46307 | Q5: 46314 | R5: 46321 | S5: 46328 | T5: 46335 | U5: 46342 | V5: 46349 | W5: 46356 | X5: 46363 | Y5: 46370 | Z5: 46377 | AA5: 46384
A6: 1. СЛУЖБА ОТ И СУОТ
A7: 1 | B7: 1. Служба ОТ и СУОТ | C7: Подписать приказ о назначении ответственных лиц по охране труда в подразделениях | D7: Подписанный приказ, ознакомление ответственных | E7: Все площадки | F7: Айкешева А.К. | G7: 46296 | H7: 46304 | I7: Высокий | J7: Акт 11.08 п.9; чек-лист акта №4; ИС п.11 | K7: ч.1 ст.5.27.1: 50–80 тыс. ₽ | L7: Приказ на согласовании в 1С:ДО | M7: На согласовании
A8: 2 | B8: 1. Служба ОТ и СУОТ | C8: Актуализировать приказ о создании службы ОТ и ПБ и Положение о службе ОТ; распределить зоны ответственности между специалистами | D8: Приказ, Положение о службе ОТ, должностные инструкции | E8: Головной офис | F8: Айкешева А.К. | G8: 46300 | H8: 46318 | I8: Высокий | J8: Акт 11.08 п.9; чек-лист акта №1–3 | K8: ч.1 ст.5.27.1: 50–80 тыс. ₽ | L8: Отдел создан, штат комплектуется | M8: Не начато
A9: 3 | B9: 1. Служба ОТ и СУОТ | C9: Актуализировать Положение о СУОТ и Политику в области ОТ (приказ Минтруда № 776н), переиздать приказы об утверждении | D9: Положение о СУОТ, Политика ОТ, приказ | E9: Все площадки | F9: Айкешева А.К. | G9: 46307 | H9: 46329 | I9: Высокий | J9: Акт 11.08 п.1; чек-лист акта №5–8; ИС п.11 | K9: ч.1 ст.5.27.1: 50–80 тыс. ₽ | L9: Действующее Положение неактуально | M9: Не начато
A10: 4 | B10: 1. Служба ОТ и СУОТ | C10: Ввести трёхступенчатый контроль: приказ, Положение о контроле ОТ, журнал и акт контроля | D10: Приказ, Положение, журнал трёхступенчатого контроля | E10: Все площадки | F10: Айкешева А.К., Грисли И.В. | G10: 46328 | H10: 46353 | I10: Средний | J10: Чек-лист акта №23–26; п. 65 Приказа № 776н | K10: ч.1 ст.5.27.1: 50–80 тыс. ₽ | L10: — | M10: Не начато
A11: 5 | B11: 1. Служба ОТ и СУОТ | C11: Создать комитет (комиссию) по охране труда: приказ, Положение, первое заседание | D11: Приказ, Положение о комитете, протокол | E11: Все площадки | F11: Айкешева А.К. | G11: 46335 | H11: 46356 | I11: Средний | J11: Перечень мероприятий п.1.3; ст. 224 ТК РФ | K11: ч.1 ст.5.27.1: 50–80 тыс. ₽ | L11: — | M11: Не начато
A12: 6 | B12: 1. Служба ОТ и СУОТ | C12: Разработать План мероприятий по улучшению условий и охраны труда на 2027 г. и смету (на базе бюджета 2027) | D12: Приказ, План мероприятий, смета расходов на ОТ | E12: Все площадки | F12: Айкешева А.К. | G12: 46357 | H12: 46381 | I12: Высокий | J12: Чек-лист акта №31–35; перечень п.1.4, 8.2; ст. 226 ТК РФ | K12: ч.1 ст.5.27.1: 50–80 тыс. ₽ | L12: Бюджет ОТ и экологии на 2027 г. сформирован | M12: Не начато
A13: 7 | B13: 1. Служба ОТ и СУОТ | C13: Сформировать перечень НПА с требованиями ОТ и перечень правил по ОТ | D13: Перечни, приказ об утверждении | E13: Все площадки | F13: Грисли И.В. | G13: 46357 | H13: 46381 | I13: Плановый | J13: Чек-лист акта №9, 36–40; Приказ № 772н | K13: ч.1 ст.5.27.1: 50–80 тыс. ₽ | L13: — | M13: Не начато
A14: 8 | B14: 1. Служба ОТ и СУОТ | C14: Подготовить отчёт о функционировании СУОТ за 2026 г. | D14: Отчёт о функционировании СУОТ | E14: Все площадки | F14: Айкешева А.К. | G14: 46370 | H14: 46386 | I14: Плановый | J14: Чек-лист акта №10 | K14: ч.1 ст.5.27.1: 50–80 тыс. ₽ | L14: — | M14: Не начато
A15: 2. СОУТ И ОЦЕНКА ПРОФРИСКОВ
A16: 9 | B16: 2. СОУТ и оценка профрисков | C16: Подписать договор на проведение СОУТ с выбранным подрядчиком (загрузка в 1С:ДО) | D16: Подписанный договор | E16: Головной офис (Москва) | F16: Пенский А.К., Айкешева А.К. | G16: 46296 | H16: 46311 | I16: Высокий | J16: Акт 11.08 п.4; ИС п.8; отчёт 3 кв. | K16: ч.2 ст.5.27.1: 60–80 тыс. ₽ | L16: ТЗ, конкурентный анализ, подрядчик выбран, документы подготовлены | M16: В работе
A17: 10 | B17: 2. СОУТ и оценка профрисков | C17: Издать приказ о комиссии по СОУТ; утвердить перечень рабочих мест и график проведения | D17: Приказ о комиссии, перечень РМ, график | E17: Головной офис (Москва) | F17: Айкешева А.К. | G17: 46300 | H17: 46318 | I17: Высокий | J17: Чек-лист акта №145–152; 426-ФЗ | K17: ч.2 ст.5.27.1: 60–80 тыс. ₽ | L17: — | M17: Не начато
A18: 11 | B18: 2. СОУТ и оценка профрисков | C18: Провести СОУТ рабочих мест офисного персонала головного подразделения (идентификация, замеры) | D18: Протокол комиссии по идентификации, замеры | E18: Головной офис (Москва) | F18: Айкешева А.К., подрядчик | G18: 46321 | H18: 46360 | I18: Высокий | J18: ИС п.8; отчёт 3 кв. (срок — до конца 2026 г.) | K18: ч.2 ст.5.27.1: 60–80 тыс. ₽ | L18: — | M18: Не начато
A19: 12 | B19: 2. СОУТ и оценка профрисков | C19: Утвердить отчёт о СОУТ; ознакомить работников с картами (≤30 кал. дней); подать декларацию в ГИТ; контроль передачи сведений во ФГИС СОУТ | D19: Отчёт, карты СОУТ с подписями, декларация, приказ о завершении | E19: Головной офис (Москва) | F19: Айкешева А.К., Грисли И.В. | G19: 46363 | H19: 46386 | I19: Высокий | J19: Чек-лист акта №154–160; ст. 15, 18 426-ФЗ | K19: ч.2 ст.5.27.1: 60–80 тыс. ₽ | L19: — | M19: Не начато
A20: 13 | B20: 2. СОУТ и оценка профрисков | C20: Сформировать график СОУТ обособленных подразделений на 2027 г. (Воронеж, Казань, Жуковский, Ульяновск, Внуково, Машково, Руднево) | D20: Утверждённый график СОУТ на 2027 г. | E20: Обособленные подразделения | F20: Айкешева А.К. | G20: 46356 | H20: 46381 | I20: Средний | J20: Акт 11.08 п.4; ИС п.8 | K20: ч.2 ст.5.27.1: 60–80 тыс. ₽ | L20: Расходы на СОУТ заложены в бюджет 2027 г. | M20: Не начато
A21: 14 | B21: 2. СОУТ и оценка профрисков | C21: Подготовить проведение ОПР: Положение об ОПР, приказ о комиссии, методика и форма реестра опасностей | D21: Положение об ОПР, приказ о комиссии | E21: Все площадки | F21: Айкешева А.К. | G21: 46342 | H21: 46381 | I21: Средний | J21: Акт 11.08 п.5; чек-лист акта №11–19 | K21: ч.1 ст.5.27.1: 50–80 тыс. ₽ | L21: ОПР заложена в бюджет 2027 г. | M21: Не начато
A22: 3. ОБУЧЕНИЕ И ИНСТРУКТАЖИ
A23: 15 | B23: 3. Обучение и инструктажи | C23: Подписать приказ о проведении вводного, первичного и повторного инструктажей; передать журналы и памятки руководителям подразделений | D23: Приказ, журналы и памятки выданы под подпись | E23: Все площадки | F23: Айкешева А.К., Грисли И.В. | G23: 46296 | H23: 46304 | I23: Высокий | J23: Акт 11.08 п.3; ИС п.9 | K23: ч.3 ст.5.27.1: 110–130 тыс. ₽ за каждого работника | L23: Приказ на согласовании в 1С:ДО; журналы закуплены; памятки разработаны | M23: На согласовании
A24: 16 | B24: 3. Обучение и инструктажи | C24: Утвердить программы вводного и первичного/повторного инструктажей; запустить инструктажи на всех площадках | D24: Приказ об утверждении программ; журналы инструктажей ведутся | E24: Все площадки | F24: Айкешева А.К., Грисли И.В. | G24: 46307 | H24: 46329 | I24: Высокий | J24: Чек-лист акта №63–67; ИС п.9 | K24: ч.3 ст.5.27.1: 110–130 тыс. ₽ за каждого работника | L24: Инструкции и программы для производства разработаны | M24: В работе
A25: 17 | B25: 3. Обучение и инструктажи | C25: Провести обучение бэк-офиса: «ОТ для руководителей и специалистов» (программа Б), «Первая помощь» | D25: Протоколы проверки знаний, записи в реестре обученных | E25: Головной офис (Москва) | F25: Айкешева А.К., Грисли И.В. | G25: 46300 | H25: 46339 | I25: Высокий | J25: Акт 11.08 п.3; ИС п.4 (срок 14.09 — перенос) | K25: ч.3 ст.5.27.1: 110–130 тыс. ₽ за каждого работника | L25: Перечень работников определён распоряжением; договор с УЦ заключён | M25: В работе
A26: 18 | B26: 3. Обучение и инструктажи | C26: Обучить рабочих, не прошедших обязательное обучение (программы А, Б, В, СИЗ, первая помощь) | D26: Протоколы, удостоверения; сводный перечень обновлён | E26: Все площадки | F26: Грисли И.В. | G26: 46300 | H26: 46374 | I26: Высокий | J26: Перечень п.3.2–3.3; ПП РФ № 2464 | K26: ч.3 ст.5.27.1: 110–130 тыс. ₽ за каждого работника | L26: Составлен сводный перечень прошедших/не прошедших обучение | M26: В работе
A27: 19 | B27: 3. Обучение и инструктажи | C27: Выстроить систему обучения: Положение о порядке обучения; комиссия по проверке знаний (≥3 чел.); перечни работ повышенной опасности, обучаемых первой помощи и СИЗ | D27: Положение, приказы, утверждённые перечни | E27: Все площадки | F27: Айкешева А.К. | G27: 46307 | H27: 46346 | I27: Высокий | J27: Акт 11.08 п.2; чек-лист акта №48–61, 68–73 | K27: ч.3 ст.5.27.1: 110–130 тыс. ₽ за каждого работника | L27: Перечень работ повышенной опасности на согласовании | M27: На согласовании
A28: 20 | B28: 3. Обучение и инструктажи | C28: Внедрить стажировку на рабочем месте: Положение, программа, перечень профессий, стажировочный лист | D28: Положение, программа, приказ | E28: Все площадки | F28: Грисли И.В. | G28: 46349 | H28: 46374 | I28: Средний | J28: Чек-лист акта №74–80 | K28: ч.3 ст.5.27.1: 110–130 тыс. ₽ за каждого работника | L28: — | M28: Не начато
A29: 4. МЕДОСМОТРЫ И ПСИХОСВИДЕТЕЛЬСТВОВАНИЕ
A30: 21 | B30: 4. Медосмотры и психосвидетельствование | C30: Подписать договор на медосмотры и психиатрические освидетельствования | D30: Подписанный договор | E30: Все площадки | F30: Айкешева А.К. | G30: 46296 | H30: 46304 | I30: Высокий | J30: Акт 11.08 п.6–7; ИС п.10 | K30: ч.3 ст.5.27.1: 110–130 тыс. ₽ за каждого работника | L30: Договор на согласовании в 1С:ДО; сроки и контингент определены | M30: На согласовании
A31: 22 | B31: 4. Медосмотры и психосвидетельствование | C31: Издать приказ о проведении периодического медосмотра; утвердить поимённый список и календарный план с медорганизацией | D31: Приказ, поимённый список, календарный план | E31: Все площадки | F31: Айкешева А.К., Грисли И.В. | G31: 46307 | H31: 46325 | I31: Высокий | J31: Чек-лист акта №81–88; приказ Минздрава № 29н | K31: ч.3 ст.5.27.1: 110–130 тыс. ₽ за каждого работника | L31: Контингент работников определён | M31: Не начато
A32: 23 | B32: 4. Медосмотры и психосвидетельствование | C32: Провести периодический медосмотр (выездной формат); получить заключительный акт | D32: Медицинские заключения, заключительный акт | E32: Все площадки | F32: Айкешева А.К., Грисли И.В. | G32: 46328 | H32: 46374 | I32: Высокий | J32: Акт 11.08 п.6; перечень п.4.1 | K32: ч.3 ст.5.27.1: 110–130 тыс. ₽ за каждого работника | L32: — | M32: Не начато
A33: 24 | B33: 4. Медосмотры и психосвидетельствование | C33: Организовать психиатрическое освидетельствование: перечень должностей, Положение, направления | D33: Перечень должностей, Положение, направления | E33: Все площадки | F33: Айкешева А.К. | G33: 46314 | H33: 46374 | I33: Высокий | J33: Акт 11.08 п.7; чек-лист акта №93–99; ПП РФ № 695 | K33: ч.3 ст.5.27.1: 110–130 тыс. ₽ за каждого работника | L33: — | M33: Не начато
A34: 25 | B34: 4. Медосмотры и психосвидетельствование | C34: Скорректировать предварительные медосмотры: альтернативные медцентры в регионах, журнал выдачи направлений, приказ о допуске/отстранении | D34: Договоры с медцентрами, журнал, приказ | E34: Все площадки | F34: Айкешева А.К. (совм. с HR) | G34: 46307 | H34: 46329 | I34: Средний | J34: ИС п.10; чек-лист акта №91–92 | K34: ч.3 ст.5.27.1: 110–130 тыс. ₽ за каждого работника | L34: Предварительные МО проводятся | M34: В работе
A35: 5. СИЗ, СМЫВАЮЩИЕ СРЕДСТВА, АПТЕЧКИ
A36: 26 | B36: 5. СИЗ, смывающие средства, аптечки | C36: Завершить нормы выдачи СИЗ по всем профессиям (ЕТН, приказ № 767н); согласовать и утвердить приказом | D36: Нормы выдачи СИЗ, приказ | E36: Все площадки | F36: Айкешева А.К. | G36: 46296 | H36: 46339 | I36: Высокий | J36: Акт 11.08 п.8; чек-лист акта №103 | K36: ч.4 ст.5.27.1: 130–150 тыс. ₽ | L36: Нормы по части должностей направлены на согласование руководителю площадки | M36: На согласовании
A37: 27 | B37: 5. СИЗ, смывающие средства, аптечки | C37: Утвердить Порядок обеспечения СИЗ; назначить ответственных за выдачу; ввести личные карточки учёта СИЗ | D37: Порядок обеспечения СИЗ, приказ, личные карточки | E37: Все площадки | F37: Айкешева А.К., Грисли И.В. | G37: 46342 | H37: 46374 | I37: Высокий | J37: Чек-лист акта №100–111; ст. 221 ТК РФ | K37: ч.4 ст.5.27.1: 130–150 тыс. ₽ | L37: — | M37: Не начато
A38: 28 | B38: 5. СИЗ, смывающие средства, аптечки | C38: Утвердить нормы и порядок выдачи смывающих средств | D38: Нормы, приказ, карточки учёта | E38: Все площадки | F38: Грисли И.В. | G38: 46356 | H38: 46381 | I38: Средний | J38: Чек-лист акта №112–118 | K38: ч.4 ст.5.27.1: 130–150 тыс. ₽ | L38: — | M38: Не начато
A39: 29 | B39: 5. СИЗ, смывающие средства, аптечки | C39: Аптечки: подписать приказ, назначить ответственных, ввести журнал, докомплектовать по площадкам | D39: Приказ, журнал, акты комплектации | E39: Все площадки | F39: Грисли И.В. | G39: 46296 | H39: 46325 | I39: Средний | J39: Акт 11.08 п.12; чек-лист акта №119–125 | K39: ч.1 ст.5.27.1: 50–80 тыс. ₽ | L39: Приказ на согласовании; проверена укомплектованность аптечек | M39: На согласовании
A40: 6. НЕСЧАСТНЫЕ СЛУЧАИ, МИКРОТРАВМЫ, ПОДРЯДЧИКИ
...

Sheet Чек-лист ИС
A1: Чек-лист испытательного срока (03.08.2026 – 03.11.2026): статус и связь с планом
A2: Айкешева А.К., начальник отдела ОТ и ПБ · наставник: Пенский А.К. · экватор 14.09.2026 · итоговое интервью 03.11.2026
A4: № | B4: Задача испытательного срока | C4: Срок по чек-листу | D4: Статус на 28.09.2026 | E4: Факт / подтверждение | F4: Действия в 4 кв. (№ в плане)
A5: 1 | B5: Ознакомление с положением об Отделе | C5: 46248 | D5: Подтвердить | E5: В отчёте 3 кв. не отражено — отметить факт у наставника | F5: —
A6: 2 | B6: Знакомство с руководителями подразделений. Посещение обособленных подразделений | C6: 46279 | D6: Выполнено | E6: Проверка состояния ОТ по всем ОП 03–11.08.2026 (акт от 11.08.2026) | F6: Плановые проверки площадок — №51
A7: 3 | B7: Аудит системы ОТ и экологии, идентификация рисков. Отчёт и план работы до конца года | C7: 46279 | D7: Выполнено | E7: Акт проверки от 11.08.2026 (12 нарушений, сводный чек-лист 177 позиций); дорожная карта по экологии; настоящий план | F7: План 4 кв. — весь документ
A8: 4 | B8: Обучение бэк-офиса «ОТ для руководителей», «Первая помощь» | C8: 46279 | D8: В работе | E8: Договор с УЦ заключён; перечень работников головного офиса определён распоряжением. Обучение не завершено — срок просрочен | F8: №17 (до 13.11)
A9: 5 | B9: Сбор документов для возмещения взносов ФСС (СФР) | C9: 46279 | D9: Подтвердить | E9: В отчёте 3 кв. не отражено. Срок подачи заявления в 2026 г. — до 01.08 (истёк) | F9: №54 — план на 2027 г.
A10: 6 | B10: Участие в обсуждении автоматизации ОТ в 1С | C10: 46286 | D10: Выполнено | E10: Участие во встречах, тестирование «1С: Охрана труда», перечень вопросов, сравнительный анализ предложений | F10: №52 — внедрение
A11: 7 | B11: Комплектование штата отдела ОТ и ПБ, перечень работ до конца 2026 г. | C11: 46286 | D11: В работе | E11: Задача принята; перечень работ — настоящий план | F11: №50
A12: 8 | B12: Выбор поставщика и начало работ по СОУТ (бэк-офис Мск и ОП) | C12: 46329 | D12: В работе | E12: ТЗ, конкурентный анализ КП, подрядчик выбран; договор готовится к загрузке в 1С:ДО | F12: №9, 11, 13
A13: 9 | B13: Внедрение системы первичных, повторных, внеплановых инструктажей | C13: 46329 | D13: В работе | E13: Программы и инструкции разработаны; журналы закуплены; памятки подготовлены; приказ на согласовании в 1С:ДО | F13: №15, 16
A14: 10 | B14: Корректировка медосмотров. Альтернативные контрагенты | C14: 46329 | D14: В работе | E14: Договор на МО и психосвидетельствование на согласовании; контингент и сроки ПМО определены | F14: №21, 25
A15: 11 | B15: Разработка локальных нормативных актов по ОТ | C15: 46329 | D15: В работе | E15: На согласовании: приказ об ответственных, приказ об инструктажах, приказ об аптечках, перечень работ повышенной опасности | F15: №1, 3
B17: Выполнено задач ИС | C17: =COUNTIF(D5:D15,"Выполнено")&" из "&COUNTA(B5:B15) -> 3 из 11

Sheet Итоги 3 кв
A1: Итоги 3 квартала 2026 г. — блок «ОТ и ТБ» (из отчёта по направлениям HR)
A3: № | B3: Задача | C3: Ответственный | D3: Результат 3 кв. | E3: Что переходит в 4 кв.
A4: 1 | B4: Создание отдела ОТ, ТБ, экологической безопасности | C4: Пенский А.К. | D4: Задача принята: комплектование штата, перечень работ до конца 2026 г. | E4: Комплектование штата — №50
A5: 2 | B5: План работы отдела и показатели оценки | C5: Пенский А.К. | D5: Задача принята. | E5: Настоящий план
A6: 3 | B6: СОУТ | C6: Пенский А.К. | D6: ТЗ подготовлено; конкурентный анализ КП; подрядчик выбран; документы для договора подготовлены. Расходы заложены в бюджет 2027 г. СОУТ офиса головного подразделения — до конца 2026 г. | E6: Договор, проведение СОУТ офиса — №9–13
A7: 4 | B7: ОПР | C7: Пенский А.К. | D7: Заложена в бюджет 2027 г. | E7: Подготовка ЛНА по ОПР — №14
A8: 5 | B8: Автоматизация процессов (1С: Охрана труда) | C8: Пенский А.К. | D8: Участие во встречах по выбору контрагента и тестировании; данные переданы подрядчикам; перечень вопросов; сравнительный анализ предложений. | E8: Внедрение — №52
A9: 6 | B9: Обучение по ОТ рабочих профессий (А, Б, СИЗ, первая помощь) | C9: Айкешева А.К. | D9: Новый договор с учебным центром на более выгодных условиях. Распоряжением определён перечень работников головного офиса. Составлен сводный перечень прошедших/не прошедших обучение. | E9: Обучение бэк-офиса и рабочих, система обучения — №17–19
A10: 7 | B10: Разработка ЛНА по ОТ и экологии | C10: Айкешева А.К. | D10: На согласовании: приказ об ответственных по ОТ; приказ об инструктажах; приказ об аптечках; перечень работ повышенной опасности. Инструкции по экобезопасности и управлению отходами — на подписи. В разработке: приказ по экобезопасности, приказ об экоаудите, приказ по экоинструктажу. Программа инструктажа для сторожа. Бюджет по экологии 2027. | E10: Подписание и ввод в действие — №1, 15, 19, 29, 33–34, 36
A11: 8 | B11: Нормы СИЗ по подразделениям и профессиям | C11: Айкешева А.К. | D11: Для части должностей разработаны нормы бесплатной выдачи СИЗ, направлены руководителю площадки на согласование. | E11: Нормы по всем профессиям — №26–27
A12: 9 | B12: Комплекты документов по ОТ для обособленных подразделений | C12: Айкешева А.К. | D12: Разработаны инструкции и программы инструктажей для производства. Журналы закуплены. Памятки: заполнение журналов, вводный инструктаж посетителей, инциденты и травмы, самочувствие работников. | E12: Передача после подписания приказа — №15–16
A13: 10 | B13: Обучение по экологической безопасности | C13: Батушин А.В. | D13: 7 сотрудников обучены. Приказ об ответственных за экобезопасность — в разработке. | E13: №33, 35
A14: 11 | B14: Инвентаризация отходов | C14: Батушин А.В. | D14: Получены инвентаризация и паспорта отходов, подписаны. В работе ДС по 3 видам отходов. СЗ по площадкам накопления — на согласовании. | E14: №37–38, 40
A15: 12 | B15: Вывоз отходов | C15: Батушин А.В. | D15: Вывезены металл и макулатура. Прорабатывается вывоз СОЖ (Руднево). Направлены запросы подрядчикам. | E15: №38
... A19: 16 | B19: Прочее | C19: Айкешева А.К. | D19: Участие в аттестации персонала совместно с отделом по управлению персоналом. | E19: —

Sheet Календарь сроков
A1: Календарь обязательных сроков: 4 кв. 2026 – 1 кв. 2027
A2: Колонка «Осталось дней» считается от текущей даты автоматически.
A4: Срок | B4: Осталось дней | C4: Что сдать / сделать | D4: Кто / площадки | E4: Основание | F4: Риск
A5: 46315 | B5: =A5-TODAY() -> 22 | C5: Авансовый платёж за НВОС за 3 кв. | D5: Машково (III кат.) | E5: ст. 16.4 7-ФЗ (кроме субъектов МСП) | F5: ст. 8.41 КоАП: 50–100 тыс. ₽
A6: 46329 | B6: =A6-TODAY() -> 36 | C6: Итоговое интервью по испытательному сроку | D6: Айкешева А.К. / Пенский А.К. | E6: Чек-лист ИС | F6: —
A7: 46387 | B7: =A7-TODAY() -> 94 | C7: Завершить СОУТ офисного персонала головного подразделения | D7: Головной офис | E7: Отчёт 3 кв.; 426-ФЗ | F7: ч.2 ст.5.27.1: 60–80 тыс. ₽
A8: 46408 | B8: =A8-TODAY() -> 115 | C8: Форма 1-Т «Условия труда» (при наличии обязанности) | D8: Компания | E8: Приказ Росстата № 338 | F8: ст. 19.7 КоАП: 3–5 тыс. ₽
A9: 46409 | B9: =A9-TODAY() -> 116 | C9: 2-ТП (воздух) | D9: Площадки со стационарными источниками | E9: Приказ Росстата | F9: ст. 13.19 КоАП: 20–70 тыс. ₽
A10: 46412 | B10: =A10-TODAY() -> 119 | C10: 4-ОС (затраты на охрану окружающей среды) | D10: Производственные площадки | E10: Приказ Росстата | F10: ст. 13.19 КоАП: 20–70 тыс. ₽
A11: 46419 | B11: =A11-TODAY() -> 126 | C11: 2-ТП (отходы) | D11: Производственные площадки | E11: Приказ Росстата | F11: ст. 13.19 КоАП: 20–70 тыс. ₽
A12: 46447 | B12: =A12-TODAY() -> 154 | C12: Итоговый платёж за НВОС за 2026 г. | D12: Машково + площадки после постановки на учёт | E12: ст. 16.4 7-ФЗ | F12: ст. 8.41 КоАП: 50–100 тыс. ₽
A13: 46456 | B13: =A13-TODAY() -> 163 | C13: Декларация о плате за НВОС | D13: Машково + площадки после постановки на учёт | E13: ст. 16.4 7-ФЗ; приказ Минприроды № 1043 | F13: ст. 8.5 КоАП
A14: 46471 | B14: =A14-TODAY() -> 178 | C14: Отчёт об организации и результатах ПЭК | D14: Машково (III кат.) | E14: ст. 67 7-ФЗ; приказ Минприроды № 109 | F14: ст. 8.5 КоАП
A15: 46600 | B15: =A15-TODAY() -> 307 | C15: Заявление в СФР на возмещение до 20% взносов на травматизм | D15: Компания | E15: Приказ Минтруда о финобеспечении предупредительных мер | F15: Упущенная выгода
A17: Ежемесячно: оплата по договорам с региональным оператором ТКО (все 8 площадок). Постоянно: ведение ЖДО на площадках; актуализация сведений НВОС — в течение 30 дней при изменениях.
