Workbook

Sheet Инструкция
A1: Учёт предварительных и периодических медицинских осмотров
A2: ООО «Авиационные интерьеры-СН»
A3: Составлено на основании Приказа №43 от 03.04.2026 «Об утверждении перечня должностей и профессий в ООО «Авиационные интерьеры-СН», подлежащих предварительному (периодическому) медицинскому осмотру» и штатного расписания (по состоянию на 05.10.2026; ранее — 04.09.2026).
A5: Лист «Перечень должностей»
A6: Перечень должностей и профессий из Приложения №1 к Приказу №43, пункты приказов №988н/1420н от 31.12.2020 и №29н от 28.01.2021. Столбец «Периодичность периодического осмотра, мес.» проверен по таблице периодичности из приложения к Порядку (Приказ №29н) и подтверждён на уровне 12 месяцев для всех 45 должностей; столбец «Обоснование периодичности» показывает, какой пункт это определяет. Поле остаётся редактируемым (выделено жёлтым) на случай изменения перечня факторов после специальной оценки условий труда.
A8: Лист «Учёт медосмотров»
A9: Построчно по каждому сотруднику: должность, пункты приказа, дата предварительного осмотра (жёлтым, вносится фактическая дата), дата последнего фактически пройденного периодического осмотра (жёлтым, заполняется по мере прохождения) и расчётная дата очередного периодического осмотра. Далее - подлежит ли должность психиатрическому освидетельствованию по Приказу №342н, дата его фактического прохождения (жёлтым) и внутренняя контрольная дата повторного освидетельствования (+5 лет; законом не требуется — см. п.6 ниже). Столбцы с расчётными датами окрашиваются автоматически: красный - срок уже прошёл, жёлтый - наступает в течение 30 дней, зелёный - срок ещё не подошёл. Пустая дата предварительного осмотра также подсвечивается красным. Последний столбец отмечает «ДА», если дата предварительного осмотра позже даты приёма на работу (возможное нарушение).
A11: Лист «Дашборд»
A12: Сводные показатели по компании и по площадкам: у скольких указаны даты предварительного, периодического и психиатрического освидетельствования, у скольких просрочена плановая дата, сколько случаев требуют проверки на нарушение сроков.
A14: Лист «Соответствие»
A15: Служебная таблица для формул ИНДЕКС и ПОИСКПОЗ: сопоставление названия должности пункту Перечня. Лист скрыт, редактировать не нужно.
A17: Источники данных:
... A37: Дата формирования файла: 10.09.2026. Последнее обновление: 13.10.2026 (сверка со штатным расписанием от 05.10.2026).

Sheet Сверка 05.10.2026
A1: Сверка учёта медосмотров со штатным расписанием от 05.10.2026 и Приказом №43 от 03.04.2026
A2: Дата сверки: 13.10.2026. Источник: «Штатка плоская» (выгрузка 1С, 737 строк, 129 подразделений).
A4: 1. Итоги
A5: Показатель | B5: Кол-во
A6: Было в учёте (до сверки) | B6: 365
A7: Исключено: нет в штатном расписании (уволены) — перенесены на лист «Выбывшие» | B7: 6
A8: Добавлено: должность входит в Перечень, сотрудника не было в учёте | B8: 12
A9: Стало в учёте | B9: =COUNTA('Учёт медосмотров'!$C$2:$C$372) -> 371
A10: Изменения должности/подразделения у сотрудников в учёте (см. ниже) | B10: 104
A11: Из них: должность после переименования отсутствует в Приказе №43 | B11: 33
A13: 2. Добавлены в учёт
A14: № | B14: ФИО | C14: Должность | D14: Подразделение | E14: Площадка | F14: Дата приёма | G14: Примечание
A15: 1 | B15: Картузов Павел Борисович | C15: Сборщик стеклопластиковых изделий 3 разряда | D15: Мебельный участок МШ | E15: Машково | F15: 46286 | G15: ДОБАВЛЕН 13.10.2026 по штатному расписанию от 05.10.2026 (принят 21.09.2026)
A16: 2 | B16: Кляцкин Антон Борисович | C16: Техник-сборщик 3 разряда | D16: Мебельный участок МШ | E16: Машково | F16: 46163 | G16: ДОБАВЛЕН 13.10.2026 по штатному расписанию от 05.10.2026 (принят 21.05.2026). Должности «Техник-сборщик 3 разряда» нет в Приказе №43 — пункты временно по п.21 Перечня (аналогичная профессия подразделения), требуется изменение Приказа №43
A17: 3 | B17: Каретников Роман Григорьевич | C17: Техник 3 разряда | D17: Участок декоративной отделки МШ | E17: Машково | F17: 46267 | G17: ДОБАВЛЕН 13.10.2026 по штатному расписанию от 05.10.2026 (принят 02.09.2026). Должности «Техник 3 разряда» нет в Приказе №43 — пункты временно по п.36 Перечня (аналогичная профессия подразделения), требуется изменение Приказа №43
A18: 4 | B18: Дубинкин Александр Сергеевич | C18: Мастер участка | D18: Механический участок МШ | E18: Машково | F18: 46290 | G18: ДОБАВЛЕН 13.10.2026 по штатному расписанию от 05.10.2026 (принят 25.09.2026)
A19: 5 | B19: Иванов Юрий Сергеевич | C19: Оператор станков с ЧПУ 4 разряда | D19: Механический участок МШ | E19: Машково | F19: 46286 | G19: ДОБАВЛЕН 13.10.2026 по штатному расписанию от 05.10.2026 (принят 21.09.2026). Написание должности отличается от Приказа №43 («Оператор станка с ЧПУ», п.30). Площадка в штатке не указана — проставлена по подразделению «МШ», уточнить
A20: 6 | B20: Серебреников Артем Андреевич | C20: Оператор станков с ЧПУ 3 разряда | D20: Механический участок МШ | E20: Машково | F20: 46296 | G20: ДОБАВЛЕН 13.10.2026 по штатному расписанию от 05.10.2026 (принят 01.10.2026). Написание должности отличается от Приказа №43 («Оператор станка с ЧПУ», п.30)
A21: 7 | B21: Тверитин Сергей Алексеевич | C21: Инженер-механик | D21: Служба главного инженера Р | E21: Руднево | F21: 46296 | G21: ДОБАВЛЕН 13.10.2026 по штатному расписанию от 05.10.2026 (принят 01.10.2026)
A22: 8 | B22: Коровин Сергей Юрьевич | C22: Кладовщик | D22: Склад Р | E22: Руднево | F22: 46297 | G22: ДОБАВЛЕН 13.10.2026 по штатному расписанию от 05.10.2026 (принят 02.10.2026)
A23: 9 | B23: Власова Ольга Вячеславовна | C23: Электромонтажник 3 разряда | D23: Участок РЭО В | E23: Воронеж | F23: 46293 | G23: ДОБАВЛЕН 13.10.2026 по штатному расписанию от 05.10.2026 (принят 28.09.2026)
A24: 10 | B24: Ефременко Роман Вадимович | C24: Слесарь-сборщик 5 разряда | D24: Участок сборки В | E24: Воронеж | F24: 46296 | G24: ДОБАВЛЕН 13.10.2026 по штатному расписанию от 05.10.2026 (принят 01.10.2026)
A25: 11 | B25: Проглядов Евгений Александрович | C25: Слесарь-сборщик 5 разряда | D25: Участок сборки В | E25: Воронеж | F25: 46286 | G25: ДОБАВЛЕН 13.10.2026 по штатному расписанию от 05.10.2026 (принят 21.09.2026)
A26: 12 | B26: Канавец Михаил Сергеевич | C26: Кладовщик | D26: Склад В | E26: Воронеж | F26: 46269 | G26: ДОБАВЛЕН 13.10.2026 по штатному расписанию от 05.10.2026 (принят 04.09.2026)
A28: 3. Исключены (нет в штатном расписании)
A29: № | B29: ФИО | C29: Должность | D29: Подразделение | E29: Площадка | F29: Дата приёма | G29: Примечание
A30: 52 | B30: Макарцова Инна Михайловна | C30: Кладовщик | D30: Производственное подразделение №6 | E30: Воронеж | F30: 45770 | G30: Перенесён на лист «Выбывшие»; дата предварительного осмотра в учёте отсутствовала
A31: 98 | B31: Бакланов Виктор Георгиевич | C31: Ведущий диспетчер | D31: Планово-диспетчерский отдел | E31: Машково | F31: 46139 | G31: Перенесён на лист «Выбывшие»
A32: 302 | B32: Федотов Кирилл Сергеевич | C32: Оператор станка с ЧПУ 4 разряда | D32: Механический участок | E32: Руднево | F32: 46140 | G32: Перенесён на лист «Выбывшие»
A33: 304 | B33: Щербинин Вадим Сергеевич | C33: Мастер участка | D33: Механический участок | E33: Руднево | F33: 46036 | G33: Перенесён на лист «Выбывшие»; дата предварительного осмотра в учёте отсутствовала
A34: 318 | B34: Лотоненко Александр Юрьевич | C34: Слесарь-сборщик 5 разряда | D34: Механический участок | E34: Руднево | F34: 45950 | G34: Перенесён на лист «Выбывшие»
A35: 322 | B35: Пилюта Артём Михайлович | C35: Слесарь механосборочных работ 2 разряда | D35: Механический участок | E35: Руднево | F35: 46156 | G35: Перенесён на лист «Выбывшие»
A37: 4. КРИТИЧНО: переименования/переводы, влияющие на применение Приказа №43
A38: № (стар.) | B38: ФИО | C38: Изменение
A39: 132 | B39: Богданов Александр Викторович | C39: Перевод: было «Монтажник электрооборудования летательных аппаратов 5 разряда» (п.37) → «Электромонтажник 5 разряда» (п.20). Пункты вредности изменились — проверить по карте СОУТ фактические факторы
A40: 133 | B40: Озорнов Игорь Валерьевич | C40: Перевод: было «Монтажник электрооборудования летательных аппаратов 5 разряда» (п.37) → «Электромонтажник 5 разряда» (п.20). Пункты вредности изменились — проверить по карте СОУТ фактические факторы
A41: 134 | B41: Романов Дмитрий Евгеньевич | C41: Перевод: было «Монтажник электрооборудования летательных аппаратов 5 разряда» (п.37) → «Электромонтажник 5 разряда» (п.20). Пункты вредности изменились — проверить по карте СОУТ фактические факторы
A42: 135 | B42: Шабалин Александр Сергеевич | C42: Перевод: было «Монтажник электрооборудования летательных аппаратов 5 разряда» (п.37) → «Электромонтажник 5 разряда» (п.20). Пункты вредности изменились — проверить по карте СОУТ фактические факторы
A43: 136 | B43: Бабенко Олег Анатольевич | C43: Переименование: было «Столяр 6 разряда» → «Техник-сборщик 5 разряда». Должности нет в Приказе №43 — пункты применены временно по прежней профессии (п.21 Перечня), требуется изменение Приказа №43
A44: 137 | B44: Макарский Станислав Иванович | C44: Переименование: было «Столяр 6 разряда» → «Техник-сборщик 5 разряда». Должности нет в Приказе №43 — пункты применены временно по прежней профессии (п.21 Перечня), требуется изменение Приказа №43
...

Sheet Перечень должностей
A1: № п/п | B1: Наименование должности, профессии | C1: Пункты приказа №988н/1420н от 31.12.2020; №29н от 28.01.2021 | D1: Периодичность периодического осмотра, мес. | E1: Обоснование периодичности (пункты с периодичностью 1 раз в год по Приложению к Порядку, Приказ №29н) | F1: Психиатрическое освидетельствование (Приказ №342н) | G1: Основание / примечание к психиатрическому освидетельствованию | H1: Численность по учёту (чел.)
A2: 1 | B2: Рабочий по комплексному обслуживанию и ремонту зданий | C2: п.4.3.1, п.4.4, п.4.7, п.4.8, п.5.1, п.6.1 | D2: 12 | E2: п.4.4, п.5.1, п.6.1 | F2: - | H2: =COUNTIF('Учёт медосмотров'!$H$2:$H$372,A2) -> 3
A3: 2 | B3: Электромонтер по ремонту и обслуживанию электрооборудования, инженер-электрик | C3: п.4.2.3, п.4.3.1, п.4.3.2, п.4.4, п.5.1, п.5.2, п.6.2, п.9 | D3: 12 | E3: п.4.4, п.5.1, п.6.2 | F3: Да | G3: п.11 Приложения №2 (сфера электроэнергетики: монтаж, наладка, техобслуживание, ремонт, управление режимом работы электроустановок). Применимо при обслуживании электроустановок предприятия (электротехнический персонал) | H3: =COUNTIF('Учёт медосмотров'!$H$2:$H$372,A3) -> 5
A4: 3 | B4: Механик | C4: п.1.50, п.4.3.2, п.4.4, п.4.7, п.4.8, п.5.1, п.5.2, п.6.2, п.15 | D4: 12 | E4: п.4.4, п.5.1, п.6.2 | F4: - | H4: =COUNTIF('Учёт медосмотров'!$H$2:$H$372,A4) -> 1
A5: 4 | B5: Инженер по эксплуатации зданий и сооружений | C5: п.4.3.1, п.4.4, п.5.1, п.5.2, п.6.2 | D5: 12 | E5: п.4.4, п.5.1, п.6.2 | F5: - | H5: =COUNTIF('Учёт медосмотров'!$H$2:$H$372,A5) -> 1
A6: 5 | B6: Главный энергетик | C6: п.4.4, п.5.2, п.6.2 | D6: 12 | E6: п.4.4, п.6.2 | F6: Да | G6: п.11-12 Приложения №2 (электроустановки и объекты теплоснабжения в ведении главного энергетика) | H6: =COUNTIF('Учёт медосмотров'!$H$2:$H$372,A6) -> 1
A7: 6 | B7: Главный механик | C7: п.4.4, п.5.2, п.6.2 | D7: 12 | E7: п.4.4, п.6.2 | F7: Нет | G7: уточнено специалистом по охране труда: главный механик психиатрическое освидетельствование не проходит. Условие: при непосредственном обслуживании оборудования под давлением >0,07 МПа, учтённого в Ростехнадзоре, — п.13 Прил.№2, тогда «Да» | H7: =COUNTIF('Учёт медосмотров'!$H$2:$H$372,A7) -> 1
A8: 7 | B8: Разнорабочий | C8: п.4.3.1, п.4.4, п.4.7, п.4.8, п.5.1, п.6.1 | D8: 12 | E8: п.4.4, п.5.1, п.6.1 | F8: - | H8: =COUNTIF('Учёт медосмотров'!$H$2:$H$372,A8) -> 3
A9: 8 | B9: Слесарь-ремонтник | C9: п.4.3.1, п.4.4, п.5.1, п.6.2, п.15 | D9: 12 | E9: п.4.4, п.5.1, п.6.2 | F9: - | H9: =COUNTIF('Учёт медосмотров'!$H$2:$H$372,A9) -> 1
A10: 9 | B10: Ведущий специалист по реставрации, реставратор | C10: п.4.3.1, п.4.4, п.5.1, п.5.2, п.15 | D10: 12 | E10: п.4.4, п.5.1 | F10: - | H10: =COUNTIF('Учёт медосмотров'!$H$2:$H$372,A10) -> 2
A11: 10 | B11: Уборщик производственных и служебных помещений, уборщик служебных помещений, старший технический работник, технический работник | C11: п.1.48, п.4.3.1, п.4.4, п.5.1 | D11: 12 | E11: п.4.4, п.5.1 | F11: - | H11: =COUNTIF('Учёт медосмотров'!$H$2:$H$372,A11) -> 16
A12: 11 | B12: Инженер-механик, механик-наладчик | C12: п.4.3.1, п.4.3.2, п.4.4, п.4.6, п.5.1, п.6.2 | D12: 12 | E12: п.4.4, п.4.6, п.5.1, п.6.2 | F12: - | H12: =COUNTIF('Учёт медосмотров'!$H$2:$H$372,A12) -> 2
A13: 12 | B13: Специалист | C13: п.4.4, п.5.1, п.5.2 | D13: 12 | E13: п.4.4, п.5.1 | F13: - | H13: =COUNTIF('Учёт медосмотров'!$H$2:$H$372,A13) -> 7
A14: 13 | B14: Инженер ОТК, контролер ОТК | C14: п.4.4, п.5.1, п.5.2 | D14: 12 | E14: п.4.4, п.5.1 | F14: - | H14: =COUNTIF('Учёт медосмотров'!$H$2:$H$372,A14) -> 14
A15: 14 | B15: Старший кладовщик, кладовщик, кладовщик-комплектовщик | C15: п.4.4, п.5.1, п.6.2 | D15: 12 | E15: п.4.4, п.5.1, п.6.2 | F15: - | G15: Условие: при управлении кранами, учтёнными в Ростехнадзоре, — п.6 Прил.№2, тогда «Да» | H15: =COUNTIF('Учёт медосмотров'!$H$2:$H$372,A15) -> 27
A16: 15 | B16: Лаборант | C16: п.1.49.2, п.1.49.14, п.1.50, п.4.3.1, п.4.4, п.6.2 | D16: 12 | E16: п.4.4, п.6.2 | F16: - | H16: =COUNTIF('Учёт медосмотров'!$H$2:$H$372,A16) -> 1
A17: 16 | B17: Оператор склада | C17: п.4.3.1, п.4.3.2, п.4.4, п.5.1, п.6.2, п.18.1 | D17: 12 | E17: п.4.4, п.5.1, п.6.2 | F17: - | H17: =COUNTIF('Учёт медосмотров'!$H$2:$H$372,A17) -> 3
A18: 17 | B18: Инженер по эксплуатации | C18: п.4.3.1, п.4.4, п.5.1, п.6.2 | D18: 12 | E18: п.4.4, п.5.1, п.6.2 | F18: - | H18: =COUNTIF('Учёт медосмотров'!$H$2:$H$372,A18) -> 0
A19: 18 | B19: Мастер участка, бригадир | C19: п.4.4, п.5.1, п.5.2 | D19: 12 | E19: п.4.4, п.5.1 | F19: - | H19: =COUNTIF('Учёт медосмотров'!$H$2:$H$372,A19) -> 14
A20: 19 | B20: Слесарь-сборщик, слесарь-сборщик (бригадир) | C20: п.4.3.1, п.4.3.2, п.4.4, п.5.1, п.6.2, п.15 | D20: 12 | E20: п.4.4, п.5.1, п.6.2 | F20: - | H20: =COUNTIF('Учёт медосмотров'!$H$2:$H$372,A20) -> 67
A21: 20 | B21: Электромонтажник | C21: п.4.3.1, п.4.3.2, п.4.4, п.4.9, п.5.1, п.5.2, п.6.2, п.9 | D21: 12 | E21: п.4.4, п.5.1, п.6.2 | F21: Проверить | G21: ПРОВЕРИТЬ (13.10.2026). п.11 Прил.№2 342н: «деятельность в сфере электроэнергетики, связанная с... монтажом, наладкой, техобслуживанием, ремонтом, управлением режимом работы ЭЛЕКТРОУСТАНОВОК»; сноска — ст.3 35-ФЗ и ГОСТ 12.1.009-2017. Официального разъяснения Минздрава нет. Распространённая экспертная позиция: критерий — работа именно с электроустановками (по ГОСТ 12.1.009-2017), а не статус организации. Монтаж бортового ЭО изделия в обесточенном состоянии — спорно; работы под напряжением (испытания, проверка цепей) — довод за «Да». Решение работодателя с письменным обоснованием; при сомнении — запрос в Минздрав или следовать консервативному варианту «Да». | H21: =COUNTIF('Учёт медосмотров'!$H$2:$H$372,A21) -> 32
A22: 21 | B22: Столяр | C22: п.1.49.2, п.1.49.14, п.4.3.1, п.4.3.2, п.4.4, п.5.1, п.15 | D22: 12 | E22: п.4.4, п.5.1 | F22: - | H22: =COUNTIF('Учёт медосмотров'!$H$2:$H$372,A22) -> 23
A23: 22 | B23: Менеджер-комплектовщик | C23: п.4.4, п.5.1, п.6.2 | D23: 12 | E23: п.4.4, п.5.1, п.6.2 | F23: - | H23: =COUNTIF('Учёт медосмотров'!$H$2:$H$372,A23) -> 1
A24: 23 | B24: Облицовщик деталей мебели | C24: п.1.49.2, п.1.49.14, п.4.3.1, п.4.3.2, п.4.4, п.5.1, п.15 | D24: 12 | E24: п.4.4, п.5.1 | F24: - | H24: =COUNTIF('Учёт медосмотров'!$H$2:$H$372,A24) -> 6
A25: 24 | B25: Столяр-краснодеревщик | C25: п.1.49.2, п.1.49.14, п.4.3.1, п.4.3.2, п.4.4, п.5.1, п.15 | D25: 12 | E25: п.4.4, п.5.1 | F25: - | H25: =COUNTIF('Учёт медосмотров'!$H$2:$H$372,A25) -> 0
A26: 25 | B26: Оператор-наладчик станков с ЧПУ | C26: п.4.3.1, п.4.3.2, п.4.4, п.5.1, п.5.2, п.15 | D26: 12 | E26: п.4.4, п.5.1 | F26: - | H26: =COUNTIF('Учёт медосмотров'!$H$2:$H$372,A26) -> 7
A27: 26 | B27: Сборщик стеклопластиковых изделий | C27: п.1.37.1, п.3.1.8.3, п.4.3.1, п.4.4, п.5.1, п.15 | D27: 12 | E27: п.1.37.1, п.4.4, п.5.1 | F27: Нет | G27: уточнено специалистом по охране труда: сборщик стеклопластиковых изделий психиатрическое освидетельствование не проходит. Условие: если сборщик непосредственно обслуживает автоклав (>0,07 МПа), учтённый в Ростехнадзоре, — п.13 Прил.№2, тогда «Да» | H27: =COUNTIF('Учёт медосмотров'!$H$2:$H$372,A27) -> 9
A28: 27 | B28: Ведущий специалист по учёту ПДО, ведущий инженер ПДО, инженер ПДО | C28: п.4.4, п.5.1, п.5.2 | D28: 12 | E28: п.4.4, п.5.1 | F28: - | H28: =COUNTIF('Учёт медосмотров'!$H$2:$H$372,A28) -> 5
A29: 28 | B29: Ведущий диспетчер ПДО, диспетчер ПДО | C29: п.4.4, п.5.1, п.5.2 | D29: 12 | E29: п.4.4, п.5.1 | F29: - | H29: =COUNTIF('Учёт медосмотров'!$H$2:$H$372,A29) -> 18
A30: 29 | B30: Мастер электромонтажного участка, мастер участка электромонтажных работ | C30: п.4.3.1, п.4.3.2, п.4.4, п.4.9, п.5.1, п.5.2, п.6.2, п.9 | D30: 12 | E30: п.4.4, п.5.1, п.6.2 | F30: Проверить | G30: ПРОВЕРИТЬ (13.10.2026). п.11 Прил.№2 342н: «деятельность в сфере электроэнергетики, связанная с... монтажом, наладкой, техобслуживанием, ремонтом, управлением режимом работы ЭЛЕКТРОУСТАНОВОК»; сноска — ст.3 35-ФЗ и ГОСТ 12.1.009-2017. Официального разъяснения Минздрава нет. Распространённая экспертная позиция: критерий — работа именно с электроустановками (по ГОСТ 12.1.009-2017), а не статус организации. Монтаж бортового ЭО изделия в обесточенном состоянии — спорно; работы под напряжением (испытания, проверка цепей) — довод за «Да». Решение работодателя с письменным обоснованием; при сомнении — запрос в Минздрав или следовать консервативному варианту «Да». | H30: =COUNTIF('Учёт медосмотров'!$H$2:$H$372,A30) -> 2
A31: 30 | B31: Оператор станка с ЧПУ | C31: п.4.3.1, п.4.3.2, п.4.4, п.5.1, п.5.2, п.15 | D31: 12 | E31: п.4.4, п.5.1 | F31: - | H31: =COUNTIF('Учёт медосмотров'!$H$2:$H$372,A31) -> 14
A32: 31 | B32: Оператор лазерных установок | C32: п.4.2.1, п.4.3.1, п.4.3.2, п.4.4, п.5.1, п.5.2, п.15 | D32: 12 | E32: п.4.4, п.5.1 | F32: - | H32: =COUNTIF('Учёт медосмотров'!$H$2:$H$372,A32) -> 1
A33: 32 | B33: Слесарь механосборочных работ | C33: п.4.3.1, п.4.3.2, п.4.4, п.5.1, п.15 | D33: 12 | E33: п.4.4, п.5.1 | F33: - | H33: =COUNTIF('Учёт медосмотров'!$H$2:$H$372,A33) -> 16
A34: 33 | B34: Фрезеровщик | C34: п.4.3.1, п.4.3.2, п.4.4, п.5.1, п.5.2, п.15 | D34: 12 | E34: п.4.4, п.5.1 | F34: - | H34: =COUNTIF('Учёт медосмотров'!$H$2:$H$372,A34) -> 2
A35: 34 | B35: Токарь | C35: п.4.3.1, п.4.3.2, п.4.4, п.5.1, п.5.2, п.15 | D35: 12 | E35: п.4.4, п.5.1 | F35: - | H35: =COUNTIF('Учёт медосмотров'!$H$2:$H$372,A35) -> 8
A36: 35 | B36: Оператор листогибочного оборудования | C36: п.4.3.1, п.4.3.2, п.4.4, п.5.1, п.5.2, п.15 | D36: 12 | E36: п.4.4, п.5.1 | F36: - | H36: =COUNTIF('Учёт медосмотров'!$H$2:$H$372,A36) -> 2
A37: 36 | B37: Маляр | C37: п.1.14.2, п.1.36, п.1.37.1, п.1.45.1, п.1.45.2, п.1.50, п.4.3.1, п.4.4, п.5.1, п.17 | D37: 12 | E37: п.1.14.2, п.1.36, п.1.37.1, п.1.45.1, п.1.45.2, п.4.4, п.5.1 | F37: - | H37: =COUNTIF('Учёт медосмотров'!$H$2:$H$372,A37) -> 15
A38: 37 | B38: Монтажник электрооборудования летательных аппаратов | C38: п.1.8.4, п.1.12, п.1.15, п.1.25, п.1.27, п.1.44, п.4.3.1, п.4.4, п.4.6, п.5.1, п.5.2, п.6.2 | D38: 12 | E38: п.1.8.4, п.1.12, п.1.15, п.1.27, п.1.44, п.4.4, п.4.6, п.5.1, п.6.2 | F38: - | H38: =COUNTIF('Учёт медосмотров'!$H$2:$H$372,A38) -> 0
A39: 38 | B39: Водитель автомобиля-экспедитор | C39: п.4.3.1, п.4.3.2, п.4.4, п.5.1, п.5.2, п.18 | D39: 12 | E39: п.4.4, п.5.1 | F39: Да | G39: п.1 Приложения №2 (управление транспортными средствами, Постановление Правительства №2349) | H39: =COUNTIF('Учёт медосмотров'!$H$2:$H$372,A39) -> 9
A40: 39 | B40: Водитель автомобиля (персональный 2 категории) | C40: п.4.3.1, п.4.3.2, п.4.4, п.5.1, п.5.2, п.18.1 | D40: 12 | E40: п.4.4, п.5.1 | F40: Да | G40: п.1 Приложения №2 (управление транспортными средствами, Постановление Правительства №2349) | H40: =COUNTIF('Учёт медосмотров'!$H$2:$H$372,A40) -> 1
...

Sheet Учёт медосмотров
A1: № | B1: Площадка / офис | C1: ФИО | D1: Должность | E1: Подразделение | F1: Дата приёма | G1: Ключ (служ.) | H1: № п/п по Перечню | I1: Пункты приказа | J1: Периодичность, мес. | K1: Дата предварительного мед. осмотра | L1: Факт. дата последнего пройденного периодического осмотра | M1: Дата очередного (планового) периодического осмотра | N1: Подлежит психиатр. освидетельствованию (342н) | O1: Дата прохождения психиатр. освидетельствования | P1: Контрольная дата повторного психиатр. освидетельствования (5 лет — внутренняя мера; Приказ №342н кратность не устанавливает) | Q1: Нарушение: осмотр после приёма | R1: Примечание сверки со штатным расписанием от 05.10.2026
A2: 1 | B2: Ульяновск | C2: Юдакова Регина Юрьевна | D2: Инженер 3 категории | E2: Отдел технического контроля М | F2: 45874 | G2: =IF(TRIM(SUBSTITUTE(SUBSTITUTE(SUBSTITUTE(SUBSTITUTE(SUBSTITUTE(SUBSTITUTE(SUBSTITUTE(SUBSTITUTE(SUBSTITUTE(SUBSTITUTE(SUBSTITUTE(LOWER(TRIM(D2)),"ё","е")," -","-"),"- ","-")," 2 разряда","")," 3 разряда","")," 4 разряда","")," 5 разряда","")," 6 разряда","")," 1 категории","")," 2 категории","")," 3 категории",""))="инженер",IF(AND(ISNUMBER(SEARCH("техническ",E2)),ISNUMBER(SEARCH("контрол",E2))),"инженер отк",IF(ISNUMBER(SEARCH("диспетч",E2)),"инженер пдо",TRIM(SUBSTITUTE(SUBSTITUTE(SUBSTITUTE(SUBSTITUTE(SUBSTITUTE(SUBSTITUTE(SUBSTITUTE(SUBSTITUTE(SUBSTITUTE(SUBSTITUTE(SUBSTITUTE(LOWER(TRIM(D2)),"ё","е")," -","-"),"- ","-")," 2 разряда","")," 3 разряда","")," 4 разряда","")," 5 разряда","")," 6 разряда","")," 1 категории","")," 2 категории","")," 3 категории","")))),IF(TRIM(SUBSTITUTE(SUBSTITUTE(SUBSTITUTE(SUBSTITUTE(SUBSTITUTE(SUBSTITUTE(SUBSTITUTE(SUBSTITUTE(SUBSTITUTE(SUBSTITUTE(SUBSTITUTE(LOWER(TRIM(D2)),"ё","е")," -","-"),"- ","-")," 2 разряда","")," 3 разряда","")," 4 разряда","")," 5 разряда","")," 6 разряда","")," 1 категории","")," 2 категории","")," 3 категории",""))="ведущий инженер",IF(ISNUMBER(SEARCH("диспетч",E2)),"ведущий инженер пдо",TRIM(SUBSTITUTE(SUBSTITUTE(SUBSTITUTE(SUBSTITUTE(SUBSTITUTE(SUBSTITUTE(SUBSTITUTE(SUBSTITUTE(SUBSTITUTE(SUBSTITUTE(SUBSTITUTE(LOWER(TRIM(D2)),"ё","е")," -","-"),"- ","-")," 2 разряда","")," 3 разряда","")," 4 разряда","")," 5 разряда","")," 6 разряда","")," 1 категории","")," 2 категории","")," 3 категории",""))),IF(TRIM(SUBSTITUTE(SUBSTITUTE(SUBSTITUTE(SUBSTITUTE(SUBSTITUTE(SUBSTITUTE(SUBSTITUTE(SUBSTITUTE(SUBSTITUTE(SUBSTITUTE(SUBSTITUTE(LOWER(TRIM(D2)),"ё","е")," -","-"),"- ","-")," 2 разряда","")," 3 разряда","")," 4 разряда","")," 5 разряда","")," 6 разряда","")," 1 категории","")," 2 категории","")," 3 категории",""))="контролер","контролер отк",TRIM(SUBSTITUTE(SUBSTITUTE(SUBSTITUTE(SUBSTITUTE(SUBSTITUTE(SUBSTITUTE(SUBSTITUTE(SUBSTITUTE(SUBSTITUTE(SUBSTITUTE(SUBSTITUTE(LOWER(TRIM(D2)),"ё","е")," -","-"),"- ","-")," 2 разряда","")," 3 разряда","")," 4 разряда","")," 5 разряда","")," 6 разряда","")," 1 категории","")," 2 категории","")," 3 категории",""))))) -> инженер отк | H2: =IFERROR(INDEX(Соответствие!$B$2:$B$76,MATCH(G2,Соответствие!$A$2:$A$76,0)),"?") -> 13 | I2: =IFERROR(INDEX('Перечень должностей'!$C$2:$C$46,MATCH(H2,'Перечень должностей'!$A$2:$A$46,0)),"") -> п.4.4, п.5.1, п.5.2 | J2: =IFERROR(INDEX('Перечень должностей'!$D$2:$D$46,MATCH(H2,'Перечень должностей'!$A$2:$A$46,0)),12) -> 12 | M2: =IF(K2="","",EDATE(IF(L2<>"",L2,K2),J2)) | N2: =IFERROR(INDEX('Перечень должностей'!$F$2:$F$46,MATCH(H2,'Перечень должностей'!$A$2:$A$46,0)),"") -> - | P2: =IF(O2="","",EDATE(O2,60)) | Q2: =IF(AND(K2<>"",F2<>"",K2>F2),"ДА","")
A3: 2 | B3: Казань | C3: Петрунина Людмила Александровна | D3: Инженер 1 категории | E3: Отдел технического контроля М | F3: 45870 | G3: =IF(TRIM(SUBSTITUTE(SUBSTITUTE(SUBSTITUTE(SUBSTITUTE(SUBSTITUTE(SUBSTITUTE(SUBSTITUTE(SUBSTITUTE(SUBSTITUTE(SUBSTITUTE(SUBSTITUTE(LOWER(TRIM(D3)),"ё","е")," -","-"),"- ","-")," 2 разряда","")," 3 разряда","")," 4 разряда","")," 5 разряда","")," 6 разряда","")," 1 категории","")," 2 категории","")," 3 категории",""))="инженер",IF(AND(ISNUMBER(SEARCH("техническ",E3)),ISNUMBER(SEARCH("контрол",E3))),"инженер отк",IF(ISNUMBER(SEARCH("диспетч",E3)),"инженер пдо",TRIM(SUBSTITUTE(SUBSTITUTE(SUBSTITUTE(SUBSTITUTE(SUBSTITUTE(SUBSTITUTE(SUBSTITUTE(SUBSTITUTE(SUBSTITUTE(SUBSTITUTE(SUBSTITUTE(LOWER(TRIM(D3)),"ё","е")," -","-"),"- ","-")," 2 разряда","")," 3 разряда","")," 4 разряда","")," 5 разряда","")," 6 разряда","")," 1 категории","")," 2 категории","")," 3 категории","")))),IF(TRIM(SUBSTITUTE(SUBSTITUTE(SUBSTITUTE(SUBSTITUTE(SUBSTITUTE(SUBSTITUTE(SUBSTITUTE(SUBSTITUTE(SUBSTITUTE(SUBSTITUTE(SUBSTITUTE(LOWER(TRIM(D3)),"ё","е")," -","-"),"- ","-")," 2 разряда","")," 3 разряда","")," 4 разряда","")," 5 разряда","")," 6 разряда","")," 1 категории","")," 2 категории","")," 3 категории",""))="ведущий инженер",IF(ISNUMBER(SEARCH("диспетч",E3)),"ведущий инженер пдо",TRIM(SUBSTITUTE(SUBSTITUTE(SUBSTITUTE(SUBSTITUTE(SUBSTITUTE(SUBSTITUTE(SUBSTITUTE(SUBSTITUTE(SUBSTITUTE(SUBSTITUTE(SUBSTITUTE(LOWER(TRIM(D3)),"ё","е")," -","-"),"- ","-")," 2 разряда","")," 3 разряда","")," 4 разряда","")," 5 разряда","")," 6 разряда","")," 1 категории","")," 2 категории","")," 3 категории",""))),IF(TRIM(SUBSTITUTE(SUBSTITUTE(SUBSTITUTE(SUBSTITUTE(SUBSTITUTE(SUBSTITUTE(SUBSTITUTE(SUBSTITUTE(SUBSTITUTE(SUBSTITUTE(SUBSTITUTE(LOWER(TRIM(D3)),"ё","е")," -","-"),"- ","-")," 2 разряда","")," 3 разряда","")," 4 разряда","")," 5 разряда","")," 6 разряда","")," 1 категории","")," 2 категории","")," 3 категории",""))="контролер","контролер отк",TRIM(SUBSTITUTE(SUBSTITUTE(SUBSTITUTE(SUBSTITUTE(SUBSTITUTE(SUBSTITUTE(SUBSTITUTE(SUBSTITUTE(SUBSTITUTE(SUBSTITUTE(SUBSTITUTE(LOWER(TRIM(D3)),"ё","е")," -","-"),"- ","-")," 2 разряда","")," 3 разряда","")," 4 разряда","")," 5 разряда","")," 6 разряда","")," 1 категории","")," 2 категории","")," 3 категории",""))))) -> инженер отк | H3: =IFERROR(INDEX(Соответствие!$B$2:$B$76,MATCH(G3,Соответствие!$A$2:$A$76,0)),"?") -> 13 | I3: =IFERROR(INDEX('Перечень должностей'!$C$2:$C$46,MATCH(H3,'Перечень должностей'!$A$2:$A$46,0)),"") -> п.4.4, п.5.1, п.5.2 | J3: =IFERROR(INDEX('Перечень должностей'!$D$2:$D$46,MATCH(H3,'Перечень должностей'!$A$2:$A$46,0)),12) -> 12 | M3: =IF(K3="","",EDATE(IF(L3<>"",L3,K3),J3)) | N3: =IFERROR(INDEX('Перечень должностей'!$F$2:$F$46,MATCH(H3,'Перечень должностей'!$A$2:$A$46,0)),"") -> - | P3: =IF(O3="","",EDATE(O3,60)) | Q3: =IF(AND(K3<>"",F3<>"",K3>F3),"ДА","")
A4: 3 | B4: Машково | C4: Ястребов Александр Сергеевич | D4: Инженер 1 категории | E4: Отдел технического контроля М | F4: 38664 | G4: =IF(TRIM(SUBSTITUTE(SUBSTITUTE(SUBSTITUTE(SUBSTITUTE(SUBSTITUTE(SUBSTITUTE(SUBSTITUTE(SUBSTITUTE(SUBSTITUTE(SUBSTITUTE(SUBSTITUTE(LOWER(TRIM(D4)),"ё","е")," -","-"),"- ","-")," 2 разряда","")," 3 разряда","")," 4 разряда","")," 5 разряда","")," 6 разряда","")," 1 категории","")," 2 категории","")," 3 категории",""))="инженер",IF(AND(ISNUMBER(SEARCH("техническ",E4)),ISNUMBER(SEARCH("контрол",E4))),"инженер отк",IF(ISNUMBER(SEARCH("диспетч",E4)),"инженер пдо",TRIM(SUBSTITUTE(SUBSTITUTE(SUBSTITUTE(SUBSTITUTE(SUBSTITUTE(SUBSTITUTE(SUBSTITUTE(SUBSTITUTE(SUBSTITUTE(SUBSTITUTE(SUBSTITUTE(LOWER(TRIM(D4)),"ё","е")," -","-"),"- ","-")," 2 разряда","")," 3 разряда","")," 4 разряда","")," 5 разряда","")," 6 разряда","")," 1 категории","")," 2 категории","")," 3 категории","")))),IF(TRIM(SUBSTITUTE(SUBSTITUTE(SUBSTITUTE(SUBSTITUTE(SUBSTITUTE(SUBSTITUTE(SUBSTITUTE(SUBSTITUTE(SUBSTITUTE(SUBSTITUTE(SUBSTITUTE(LOWER(TRIM(D4)),"ё","е")," -","-"),"- ","-")," 2 разряда","")," 3 разряда","")," 4 разряда","")," 5 разряда","")," 6 разряда","")," 1 категории","")," 2 категории","")," 3 категории",""))="ведущий инженер",IF(ISNUMBER(SEARCH("диспетч",E4)),"ведущий инженер пдо",TRIM(SUBSTITUTE(SUBSTITUTE(SUBSTITUTE(SUBSTITUTE(SUBSTITUTE(SUBSTITUTE(SUBSTITUTE(SUBSTITUTE(SUBSTITUTE(SUBSTITUTE(SUBSTITUTE(LOWER(TRIM(D4)),"ё","е")," -","-"),"- ","-")," 2 разряда","")," 3 разряда","")," 4 разряда","")," 5 разряда","")," 6 разряда","")," 1 категории","")," 2 категории","")," 3 категории",""))),IF(TRIM(SUBSTITUTE(SUBSTITUTE(SUBSTITUTE(SUBSTITUTE(SUBSTITUTE(SUBSTITUTE(SUBSTITUTE(SUBSTITUTE(SUBSTITUTE(SUBSTITUTE(SUBSTITUTE(LOWER(TRIM(D4)),"ё","е")," -","-"),"- ","-")," 2 разряда","")," 3 разряда","")," 4 разряда","")," 5 разряда","")," 6 разряда","")," 1 категории","")," 2 категории","")," 3 категории",""))="контролер","контролер отк",TRIM(SUBSTITUTE(SUBSTITUTE(SUBSTITUTE(SUBSTITUTE(SUBSTITUTE(SUBSTITUTE(SUBSTITUTE(SUBSTITUTE(SUBSTITUTE(SUBSTITUTE(SUBSTITUTE(LOWER(TRIM(D4)),"ё","е")," -","-"),"- ","-")," 2 разряда","")," 3 разряда","")," 4 разряда","")," 5 разряда","")," 6 разряда","")," 1 категории","")," 2 категории","")," 3 категории",""))))) -> инженер отк | H4: =IFERROR(INDEX(Соответствие!$B$2:$B$76,MATCH(G4,Соответствие!$A$2:$A$76,0)),"?") -> 13 | I4: =IFERROR(INDEX('Перечень должностей'!$C$2:$C$46,MATCH(H4,'Перечень должностей'!$A$2:$A$46,0)),"") -> п.4.4, п.5.1, п.5.2 | J4: =IFERROR(INDEX('Перечень должностей'!$D$2:$D$46,MATCH(H4,'Перечень должностей'!$A$2:$A$46,0)),12) -> 12 | M4: =IF(K4="","",EDATE(IF(L4<>"",L4,K4),J4)) | N4: =IFERROR(INDEX('Перечень должностей'!$F$2:$F$46,MATCH(H4,'Перечень должностей'!$A$2:$A$46,0)),"") -> - | P4: =IF(O4="","",EDATE(O4,60)) | Q4: =IF(AND(K4<>"",F4<>"",K4>F4),"ДА","")
A5: 4 | B5: Москва | C5: Гудумак Анастасия Сергеевна | D5: Инженер 2 категории | E5: Отдел технического контроля М | F5: 44970 | G5: =IF(TRIM(SUBSTITUTE(SUBSTITUTE(SUBSTITUTE(SUBSTITUTE(SUBSTITUTE(SUBSTITUTE(SUBSTITUTE(SUBSTITUTE(SUBSTITUTE(SUBSTITUTE(SUBSTITUTE(LOWER(TRIM(D5)),"ё","е")," -","-"),"- ","-")," 2 разряда","")," 3 разряда","")," 4 разряда","")," 5 разряда","")," 6 разряда","")," 1 категории","")," 2 категории","")," 3 категории",""))="инженер",IF(AND(ISNUMBER(SEARCH("техническ",E5)),ISNUMBER(SEARCH("контрол",E5))),"инженер отк",IF(ISNUMBER(SEARCH("диспетч",E5)),"инженер пдо",TRIM(SUBSTITUTE(SUBSTITUTE(SUBSTITUTE(SUBSTITUTE(SUBSTITUTE(SUBSTITUTE(SUBSTITUTE(SUBSTITUTE(SUBSTITUTE(SUBSTITUTE(SUBSTITUTE(LOWER(TRIM(D5)),"ё","е")," -","-"),"- ","-")," 2 разряда","")," 3 разряда","")," 4 разряда","")," 5 разряда","")," 6 разряда","")," 1 категории","")," 2 категории","")," 3 категории","")))),IF(TRIM(SUBSTITUTE(SUBSTITUTE(SUBSTITUTE(SUBSTITUTE(SUBSTITUTE(SUBSTITUTE(SUBSTITUTE(SUBSTITUTE(SUBSTITUTE(SUBSTITUTE(SUBSTITUTE(LOWER(TRIM(D5)),"ё","е")," -","-"),"- ","-")," 2 разряда","")," 3 разряда","")," 4 разряда","")," 5 разряда","")," 6 разряда","")," 1 категории","")," 2 категории","")," 3 категории",""))="ведущий инженер",IF(ISNUMBER(SEARCH("диспетч",E5)),"ведущий инженер пдо",TRIM(SUBSTITUTE(SUBSTITUTE(SUBSTITUTE(SUBSTITUTE(SUBSTITUTE(SUBSTITUTE(SUBSTITUTE(SUBSTITUTE(SUBSTITUTE(SUBSTITUTE(SUBSTITUTE(LOWER(TRIM(D5)),"ё","е")," -","-"),"- ","-")," 2 разряда","")," 3 разряда","")," 4 разряда","")," 5 разряда","")," 6 разряда","")," 1 категории","")," 2 категории","")," 3 категории",""))),IF(TRIM(SUBSTITUTE(SUBSTITUTE(SUBSTITUTE(SUBSTITUTE(SUBSTITUTE(SUBSTITUTE(SUBSTITUTE(SUBSTITUTE(SUBSTITUTE(SUBSTITUTE(SUBSTITUTE(LOWER(TRIM(D5)),"ё","е")," -","-"),"- ","-")," 2 разряда","")," 3 разряда","")," 4 разряда","")," 5 разряда","")," 6 разряда","")," 1 категории","")," 2 категории","")," 3 категории",""))="контролер","контролер отк",TRIM(SUBSTITUTE(SUBSTITUTE(SUBSTITUTE(SUBSTITUTE(SUBSTITUTE(SUBSTITUTE(SUBSTITUTE(SUBSTITUTE(SUBSTITUTE(SUBSTITUTE(SUBSTITUTE(LOWER(TRIM(D5)),"ё","е")," -","-"),"- ","-")," 2 разряда","")," 3 разряда","")," 4 разряда","")," 5 разряда","")," 6 разряда","")," 1 категории","")," 2 категории","")," 3 категории",""))))) -> инженер отк | H5: =IFERROR(INDEX(Соответствие!$B$2:$B$76,MATCH(G5,Соответствие!$A$2:$A$76,0)),"?") -> 13 | I5: =IFERROR(INDEX('Перечень должностей'!$C$2:$C$46,MATCH(H5,'Перечень должностей'!$A$2:$A$46,0)),"") -> п.4.4, п.5.1, п.5.2 | J5: =IFERROR(INDEX('Перечень должностей'!$D$2:$D$46,MATCH(H5,'Перечень должностей'!$A$2:$A$46,0)),12) -> 12 | M5: =IF(K5="","",EDATE(IF(L5<>"",L5,K5),J5)) | N5: =IFERROR(INDEX('Перечень должностей'!$F$2:$F$46,MATCH(H5,'Перечень должностей'!$A$2:$A$46,0)),"") -> - | P5: =IF(O5="","",EDATE(O5,60)) | Q5: =IF(AND(K5<>"",F5<>"",K5>F5),"ДА","")
A6: 5 | B6: Машково | C6: Ермакова Наталья Васильевна | D6: Контролер 1 категории | E6: Отдел технического контроля М | F6: 45720 | G6: =IF(TRIM(SUBSTITUTE(SUBSTITUTE(SUBSTITUTE(SUBSTITUTE(SUBSTITUTE(SUBSTITUTE(SUBSTITUTE(SUBSTITUTE(SUBSTITUTE(SUBSTITUTE(SUBSTITUTE(LOWER(TRIM(D6)),"ё","е")," -","-"),"- ","-")," 2 разряда","")," 3 разряда","")," 4 разряда","")," 5 разряда","")," 6 разряда","")," 1 категории","")," 2 категории","")," 3 категории",""))="инженер",IF(AND(ISNUMBER(SEARCH("техническ",E6)),ISNUMBER(SEARCH("контрол",E6))),"инженер отк",IF(ISNUMBER(SEARCH("диспетч",E6)),"инженер пдо",TRIM(SUBSTITUTE(SUBSTITUTE(SUBSTITUTE(SUBSTITUTE(SUBSTITUTE(SUBSTITUTE(SUBSTITUTE(SUBSTITUTE(SUBSTITUTE(SUBSTITUTE(SUBSTITUTE(LOWER(TRIM(D6)),"ё","е")," -","-"),"- ","-")," 2 разряда","")," 3 разряда","")," 4 разряда","")," 5 разряда","")," 6 разряда","")," 1 категории","")," 2 категории","")," 3 категории","")))),IF(TRIM(SUBSTITUTE(SUBSTITUTE(SUBSTITUTE(SUBSTITUTE(SUBSTITUTE(SUBSTITUTE(SUBSTITUTE(SUBSTITUTE(SUBSTITUTE(SUBSTITUTE(SUBSTITUTE(LOWER(TRIM(D6)),"ё","е")," -","-"),"- ","-")," 2 разряда","")," 3 разряда","")," 4 разряда","")," 5 разряда","")," 6 разряда","")," 1 категории","")," 2 категории","")," 3 категории",""))="ведущий инженер",IF(ISNUMBER(SEARCH("диспетч",E6)),"ведущий инженер пдо",TRIM(SUBSTITUTE(SUBSTITUTE(SUBSTITUTE(SUBSTITUTE(SUBSTITUTE(SUBSTITUTE(SUBSTITUTE(SUBSTITUTE(SUBSTITUTE(SUBSTITUTE(SUBSTITUTE(LOWER(TRIM(D6)),"ё","е")," -","-"),"- ","-")," 2 разряда","")," 3 разряда","")," 4 разряда","")," 5 разряда","")," 6 разряда","")," 1 категории","")," 2 категории","")," 3 категории",""))),IF(TRIM(SUBSTITUTE(SUBSTITUTE(SUBSTITUTE(SUBSTITUTE(SUBSTITUTE(SUBSTITUTE(SUBSTITUTE(SUBSTITUTE(SUBSTITUTE(SUBSTITUTE(SUBSTITUTE(LOWER(TRIM(D6)),"ё","е")," -","-"),"- ","-")," 2 разряда","")," 3 разряда","")," 4 разряда","")," 5 разряда","")," 6 разряда","")," 1 категории","")," 2 категории","")," 3 категории",""))="контролер","контролер отк",TRIM(SUBSTITUTE(SUBSTITUTE(SUBSTITUTE(SUBSTITUTE(SUBSTITUTE(SUBSTITUTE(SUBSTITUTE(SUBSTITUTE(SUBSTITUTE(SUBSTITUTE(SUBSTITUTE(LOWER(TRIM(D6)),"ё","е")," -","-"),"- ","-")," 2 разряда","")," 3 разряда","")," 4 разряда","")," 5 разряда","")," 6 разряда","")," 1 категории","")," 2 категории","")," 3 категории",""))))) -> контролер отк | H6: =IFERROR(INDEX(Соответствие!$B$2:$B$76,MATCH(G6,Соответствие!$A$2:$A$76,0)),"?") -> 13 | I6: =IFERROR(INDEX('Перечень должностей'!$C$2:$C$46,MATCH(H6,'Перечень должностей'!$A$2:$A$46,0)),"") -> п.4.4, п.5.1, п.5.2 | J6: =IFERROR(INDEX('Перечень должностей'!$D$2:$D$46,MATCH(H6,'Перечень должностей'!$A$2:$A$46,0)),12) -> 12 | M6: =IF(K6="","",EDATE(IF(L6<>"",L6,K6),J6)) | N6: =IFERROR(INDEX('Перечень должностей'!$F$2:$F$46,MATCH(H6,'Перечень должностей'!$A$2:$A$46,0)),"") -> - | P6: =IF(O6="","",EDATE(O6,60)) | Q6: =IF(AND(K6<>"",F6<>"",K6>F6),"ДА","")
A7: 6 | B7: Машково | C7: Шрамко Наталья Викторовна | D7: Контролер 1 категории | E7: Отдел технического контроля М | F7: 45908 | G7: =IF(TRIM(SUBSTITUTE(SUBSTITUTE(SUBSTITUTE(SUBSTITUTE(SUBSTITUTE(SUBSTITUTE(SUBSTITUTE(SUBSTITUTE(SUBSTITUTE(SUBSTITUTE(SUBSTITUTE(LOWER(TRIM(D7)),"ё","е")," -","-"),"- ","-")," 2 разряда","")," 3 разряда","")," 4 разряда","")," 5 разряда","")," 6 разряда","")," 1 категории","")," 2 категории","")," 3 категории",""))="инженер",IF(AND(ISNUMBER(SEARCH("техническ",E7)),ISNUMBER(SEARCH("контрол",E7))),"инженер отк",IF(ISNUMBER(SEARCH("диспетч",E7)),"инженер пдо",TRIM(SUBSTITUTE(SUBSTITUTE(SUBSTITUTE(SUBSTITUTE(SUBSTITUTE(SUBSTITUTE(SUBSTITUTE(SUBSTITUTE(SUBSTITUTE(SUBSTITUTE(SUBSTITUTE(LOWER(TRIM(D7)),"ё","е")," -","-"),"- ","-")," 2 разряда","")," 3 разряда","")," 4 разряда","")," 5 разряда","")," 6 разряда","")," 1 категории","")," 2 категории","")," 3 категории","")))),IF(TRIM(SUBSTITUTE(SUBSTITUTE(SUBSTITUTE(SUBSTITUTE(SUBSTITUTE(SUBSTITUTE(SUBSTITUTE(SUBSTITUTE(SUBSTITUTE(SUBSTITUTE(SUBSTITUTE(LOWER(TRIM(D7)),"ё","е")," -","-"),"- ","-")," 2 разряда","")," 3 разряда","")," 4 разряда","")," 5 разряда","")," 6 разряда","")," 1 категории","")," 2 категории","")," 3 категории",""))="ведущий инженер",IF(ISNUMBER(SEARCH("диспетч",E7)),"ведущий инженер пдо",TRIM(SUBSTITUTE(SUBSTITUTE(SUBSTITUTE(SUBSTITUTE(SUBSTITUTE(SUBSTITUTE(SUBSTITUTE(SUBSTITUTE(SUBSTITUTE(SUBSTITUTE(SUBSTITUTE(LOWER(TRIM(D7)),"ё","е")," -","-"),"- ","-")," 2 разряда","")," 3 разряда","")," 4 разряда","")," 5 разряда","")," 6 разряда","")," 1 категории","")," 2 категории","")," 3 категории",""))),IF(TRIM(SUBSTITUTE(SUBSTITUTE(SUBSTITUTE(SUBSTITUTE(SUBSTITUTE(SUBSTITUTE(SUBSTITUTE(SUBSTITUTE(SUBSTITUTE(SUBSTITUTE(SUBSTITUTE(LOWER(TRIM(D7)),"ё","е")," -","-"),"- ","-")," 2 разряда","")," 3 разряда","")," 4 разряда","")," 5 разряда","")," 6 разряда","")," 1 категории","")," 2 категории","")," 3 категории",""))="контролер","контролер отк",TRIM(SUBSTITUTE(SUBSTITUTE(SUBSTITUTE(SUBSTITUTE(SUBSTITUTE(SUBSTITUTE(SUBSTITUTE(SUBSTITUTE(SUBSTITUTE(SUBSTITUTE(SUBSTITUTE(LOWER(TRIM(D7)),"ё","е")," -","-"),"- ","-")," 2 разряда","")," 3 разряда","")," 4 разряда","")," 5 разряда","")," 6 разряда","")," 1 категории","")," 2 категории","")," 3 категории",""))))) -> контролер отк | H7: =IFERROR(INDEX(Соответствие!$B$2:$B$76,MATCH(G7,Соответствие!$A$2:$A$76,0)),"?") -> 13 | I7: =IFERROR(INDEX('Перечень должностей'!$C$2:$C$46,MATCH(H7,'Перечень должностей'!$A$2:$A$46,0)),"") -> п.4.4, п.5.1, п.5.2 | J7: =IFERROR(INDEX('Перечень должностей'!$D$2:$D$46,MATCH(H7,'Перечень должностей'!$A$2:$A$46,0)),12) -> 12 | M7: =IF(K7="","",EDATE(IF(L7<>"",L7,K7),J7)) | N7: =IFERROR(INDEX('Перечень должностей'!$F$2:$F$46,MATCH(H7,'Перечень должностей'!$A$2:$A$46,0)),"") -> - | P7: =IF(O7="","",EDATE(O7,60)) | Q7: =IF(AND(K7<>"",F7<>"",K7>F7),"ДА","")
A8: 7 | B8: Москва | C8: Высокий Владимир Евгеньевич | D8: Водитель автомобиля (персональный 2 категории) | E8: Отдел транспортного обеспечения (М н/д) | F8: 41365 | G8: =IF(TRIM(SUBSTITUTE(SUBSTITUTE(SUBSTITUTE(SUBSTITUTE(SUBSTITUTE(SUBSTITUTE(SUBSTITUTE(SUBSTITUTE(SUBSTITUTE(SUBSTITUTE(SUBSTITUTE(LOWER(TRIM(D8)),"ё","е")," -","-"),"- ","-")," 2 разряда","")," 3 разряда","")," 4 разряда","")," 5 разряда","")," 6 разряда","")," 1 категории","")," 2 категории","")," 3 категории",""))="инженер",IF(AND(ISNUMBER(SEARCH("техническ",E8)),ISNUMBER(SEARCH("контрол",E8))),"инженер отк",IF(ISNUMBER(SEARCH("диспетч",E8)),"инженер пдо",TRIM(SUBSTITUTE(SUBSTITUTE(SUBSTITUTE(SUBSTITUTE(SUBSTITUTE(SUBSTITUTE(SUBSTITUTE(SUBSTITUTE(SUBSTITUTE(SUBSTITUTE(SUBSTITUTE(LOWER(TRIM(D8)),"ё","е")," -","-"),"- ","-")," 2 разряда","")," 3 разряда","")," 4 разряда","")," 5 разряда","")," 6 разряда","")," 1 категории","")," 2 категории","")," 3 категории","")))),IF(TRIM(SUBSTITUTE(SUBSTITUTE(SUBSTITUTE(SUBSTITUTE(SUBSTITUTE(SUBSTITUTE(SUBSTITUTE(SUBSTITUTE(SUBSTITUTE(SUBSTITUTE(SUBSTITUTE(LOWER(TRIM(D8)),"ё","е")," -","-"),"- ","-")," 2 разряда","")," 3 разряда","")," 4 разряда","")," 5 разряда","")," 6 разряда","")," 1 категории","")," 2 категории","")," 3 категории",""))="ведущий инженер",IF(ISNUMBER(SEARCH("диспетч",E8)),"ведущий инженер пдо",TRIM(SUBSTITUTE(SUBSTITUTE(SUBSTITUTE(SUBSTITUTE(SUBSTITUTE(SUBSTITUTE(SUBSTITUTE(SUBSTITUTE(SUBSTITUTE(SUBSTITUTE(SUBSTITUTE(LOWER(TRIM(D8)),"ё","е")," -","-"),"- ","-")," 2 разряда","")," 3 разряда","")," 4 разряда","")," 5 разряда","")," 6 разряда","")," 1 категории","")," 2 категории","")," 3 категории",""))),IF(TRIM(SUBSTITUTE(SUBSTITUTE(SUBSTITUTE(SUBSTITUTE(SUBSTITUTE(SUBSTITUTE(SUBSTITUTE(SUBSTITUTE(SUBSTITUTE(SUBSTITUTE(SUBSTITUTE(LOWER(TRIM(D8)),"ё","е")," -","-"),"- ","-")," 2 разряда","")," 3 разряда","")," 4 разряда","")," 5 разряда","")," 6 разряда","")," 1 категории","")," 2 категории","")," 3 категории",""))="контролер","контролер отк",TRIM(SUBSTITUTE(SUBSTITUTE(SUBSTITUTE(SUBSTITUTE(SUBSTITUTE(SUBSTITUTE(SUBSTITUTE(SUBSTITUTE(SUBSTITUTE(SUBSTITUTE(SUBSTITUTE(LOWER(TRIM(D8)),"ё","е")," -","-"),"- ","-")," 2 разряда","")," 3 разряда","")," 4 разряда","")," 5 разряда","")," 6 разряда","")," 1 категории","")," 2 категории","")," 3 категории",""))))) -> водитель автомобиля (персональный) | H8: =IFERROR(INDEX(Соответствие!$B$2:$B$76,MATCH(G8,Соответствие!$A$2:$A$76,0)),"?") -> 39 | I8: =IFERROR(INDEX('Перечень должностей'!$C$2:$C$46,MATCH(H8,'Перечень должностей'!$A$2:$A$46,0)),"") -> п.4.3.1, п.4.3.2, п.4.4, п.5.1, п.5.2, п.18.1 | J8: =IFERROR(INDEX('Перечень должностей'!$D$2:$D$46,MATCH(H8,'Перечень должностей'!$A$2:$A$46,0)),12) -> 12 | M8: =IF(K8="","",EDATE(IF(L8<>"",L8,K8),J8)) | N8: =IFERROR(INDEX('Перечень должностей'!$F$2:$F$46,MATCH(H8,'Перечень должностей'!$A$2:$A$46,0)),"") -> Да | P8: =IF(O8="","",EDATE(O8,60)) | Q8: =IF(AND(K8<>"",F8<>"",K8>F8),"ДА","")
A9: 8 | B9: Москва | C9: Богачева Мария Сергеевна | D9: Специалист | E9: Отдел управления качеством М | F9: 46097 | G9: =IF(TRIM(SUBSTITUTE(SUBSTITUTE(SUBSTITUTE(SUBSTITUTE(SUBSTITUTE(SUBSTITUTE(SUBSTITUTE(SUBSTITUTE(SUBSTITUTE(SUBSTITUTE(SUBSTITUTE(LOWER(TRIM(D9)),"ё","е")," -","-"),"- ","-")," 2 разряда","")," 3 разряда","")," 4 разряда","")," 5 разряда","")," 6 разряда","")," 1 категории","")," 2 категории","")," 3 категории",""))="инженер",IF(AND(ISNUMBER(SEARCH("техническ",E9)),ISNUMBER(SEARCH("контрол",E9))),"инженер отк",IF(ISNUMBER(SEARCH("диспетч",E9)),"инженер пдо",TRIM(SUBSTITUTE(SUBSTITUTE(SUBSTITUTE(SUBSTITUTE(SUBSTITUTE(SUBSTITUTE(SUBSTITUTE(SUBSTITUTE(SUBSTITUTE(SUBSTITUTE(SUBSTITUTE(LOWER(TRIM(D9)),"ё","е")," -","-"),"- ","-")," 2 разряда","")," 3 разряда","")," 4 разряда","")," 5 разряда","")," 6 разряда","")," 1 категории","")," 2 категории","")," 3 категории","")))),IF(TRIM(SUBSTITUTE(SUBSTITUTE(SUBSTITUTE(SUBSTITUTE(SUBSTITUTE(SUBSTITUTE(SUBSTITUTE(SUBSTITUTE(SUBSTITUTE(SUBSTITUTE(SUBSTITUTE(LOWER(TRIM(D9)),"ё","е")," -","-"),"- ","-")," 2 разряда","")," 3 разряда","")," 4 разряда","")," 5 разряда","")," 6 разряда","")," 1 категории","")," 2 категории","")," 3 категории",""))="ведущий инженер",IF(ISNUMBER(SEARCH("диспетч",E9)),"ведущий инженер пдо",TRIM(SUBSTITUTE(SUBSTITUTE(SUBSTITUTE(SUBSTITUTE(SUBSTITUTE(SUBSTITUTE(SUBSTITUTE(SUBSTITUTE(SUBSTITUTE(SUBSTITUTE(SUBSTITUTE(LOWER(TRIM(D9)),"ё","е")," -","-"),"- ","-")," 2 разряда","")," 3 разряда","")," 4 разряда","")," 5 разряда","")," 6 разряда","")," 1 категории","")," 2 категории","")," 3 категории",""))),IF(TRIM(SUBSTITUTE(SUBSTITUTE(SUBSTITUTE(SUBSTITUTE(SUBSTITUTE(SUBSTITUTE(SUBSTITUTE(SUBSTITUTE(SUBSTITUTE(SUBSTITUTE(SUBSTITUTE(LOWER(TRIM(D9)),"ё","е")," -","-"),"- ","-")," 2 разряда","")," 3 разряда","")," 4 разряда","")," 5 разряда","")," 6 разряда","")," 1 категории","")," 2 категории","")," 3 категории",""))="контролер","контролер отк",TRIM(SUBSTITUTE(SUBSTITUTE(SUBSTITUTE(SUBSTITUTE(SUBSTITUTE(SUBSTITUTE(SUBSTITUTE(SUBSTITUTE(SUBSTITUTE(SUBSTITUTE(SUBSTITUTE(LOWER(TRIM(D9)),"ё","е")," -","-"),"- ","-")," 2 разряда","")," 3 разряда","")," 4 разряда","")," 5 разряда","")," 6 разряда","")," 1 категории","")," 2 категории","")," 3 категории",""))))) -> специалист | H9: =IFERROR(INDEX(Соответствие!$B$2:$B$76,MATCH(G9,Соответствие!$A$2:$A$76,0)),"?") -> 12 | I9: =IFERROR(INDEX('Перечень должностей'!$C$2:$C$46,MATCH(H9,'Перечень должностей'!$A$2:$A$46,0)),"") -> п.4.4, п.5.1, п.5.2 | J9: =IFERROR(INDEX('Перечень должностей'!$D$2:$D$46,MATCH(H9,'Перечень должностей'!$A$2:$A$46,0)),12) -> 12 | M9: =IF(K9="","",EDATE(IF(L9<>"",L9,K9),J9)) | N9: =IFERROR(INDEX('Перечень должностей'!$F$2:$F$46,MATCH(H9,'Перечень должностей'!$A$2:$A$46,0)),"") -> - | P9: =IF(O9="","",EDATE(O9,60)) | Q9: =IF(AND(K9<>"",F9<>"",K9>F9),"ДА","")
A10: 9 | B10: Москва | C10: Рысева Полина Викторовна | D10: Специалист | E10: Отдел сертификации авиационной техники М | F10: 46266 | G10: =IF(TRIM(SUBSTITUTE(SUBSTITUTE(SUBSTITUTE(SUBSTITUTE(SUBSTITUTE(SUBSTITUTE(SUBSTITUTE(SUBSTITUTE(SUBSTITUTE(SUBSTITUTE(SUBSTITUTE(LOWER(TRIM(D10)),"ё","е")," -","-"),"- ","-")," 2 разряда","")," 3 разряда","")," 4 разряда","")," 5 разряда","")," 6 разряда","")," 1 категории","")," 2 категории","")," 3 категории",""))="инженер",IF(AND(ISNUMBER(SEARCH("техническ",E10)),ISNUMBER(SEARCH("контрол",E10))),"инженер отк",IF(ISNUMBER(SEARCH("диспетч",E10)),"инженер пдо",TRIM(SUBSTITUTE(SUBSTITUTE(SUBSTITUTE(SUBSTITUTE(SUBSTITUTE(SUBSTITUTE(SUBSTITUTE(SUBSTITUTE(SUBSTITUTE(SUBSTITUTE(SUBSTITUTE(LOWER(TRIM(D10)),"ё","е")," -","-"),"- ","-")," 2 разряда","")," 3 разряда","")," 4 разряда","")," 5 разряда","")," 6 разряда","")," 1 категории","")," 2 категории","")," 3 категории","")))),IF(TRIM(SUBSTITUTE(SUBSTITUTE(SUBSTITUTE(SUBSTITUTE(SUBSTITUTE(SUBSTITUTE(SUBSTITUTE(SUBSTITUTE(SUBSTITUTE(SUBSTITUTE(SUBSTITUTE(LOWER(TRIM(D10)),"ё","е")," -","-"),"- ","-")," 2 разряда","")," 3 разряда","")," 4 разряда","")," 5 разряда","")," 6 разряда","")," 1 категории","")," 2 категории","")," 3 категории",""))="ведущий инженер",IF(ISNUMBER(SEARCH("диспетч",E10)),"ведущий инженер пдо",TRIM(SUBSTITUTE(SUBSTITUTE(SUBSTITUTE(SUBSTITUTE(SUBSTITUTE(SUBSTITUTE(SUBSTITUTE(SUBSTITUTE(SUBSTITUTE(SUBSTITUTE(SUBSTITUTE(LOWER(TRIM(D10)),"ё","е")," -","-"),"- ","-")," 2 разряда","")," 3 разряда","")," 4 разряда","")," 5 разряда","")," 6 разряда","")," 1 категории","")," 2 категории","")," 3 категории",""))),IF(TRIM(SUBSTITUTE(SUBSTITUTE(SUBSTITUTE(SUBSTITUTE(SUBSTITUTE(SUBSTITUTE(SUBSTITUTE(SUBSTITUTE(SUBSTITUTE(SUBSTITUTE(SUBSTITUTE(LOWER(TRIM(D10)),"ё","е")," -","-"),"- ","-")," 2 разряда","")," 3 разряда","")," 4 разряда","")," 5 разряда","")," 6 разряда","")," 1 категории","")," 2 категории","")," 3 категории",""))="контролер","контролер отк",TRIM(SUBSTITUTE(SUBSTITUTE(SUBSTITUTE(SUBSTITUTE(SUBSTITUTE(SUBSTITUTE(SUBSTITUTE(SUBSTITUTE(SUBSTITUTE(SUBSTITUTE(SUBSTITUTE(LOWER(TRIM(D10)),"ё","е")," -","-"),"- ","-")," 2 разряда","")," 3 разряда","")," 4 разряда","")," 5 разряда","")," 6 разряда","")," 1 категории","")," 2 категории","")," 3 категории",""))))) -> специалист | H10: =IFERROR(INDEX(Соответствие!$B$2:$B$76,MATCH(G10,Соответствие!$A$2:$A$76,0)),"?") -> 12 | I10: =IFERROR(INDEX('Перечень должностей'!$C$2:$C$46,MATCH(H10,'Перечень должностей'!$A$2:$A$46,0)),"") -> п.4.4, п.5.1, п.5.2 | J10: =IFERROR(INDEX('Перечень должностей'!$D$2:$D$46,MATCH(H10,'Перечень должностей'!$A$2:$A$46,0)),12) -> 12 | M10: =IF(K10="","",EDATE(IF(L10<>"",L10,K10),J10)) | N10: =IFERROR(INDEX('Перечень должностей'!$F$2:$F$46,MATCH(H10,'Перечень должностей'!$A$2:$A$46,0)),"") -> - | P10: =IF(O10="","",EDATE(O10,60)) | Q10: =IF(AND(K10<>"",F10<>"",K10>F10),"ДА","")
A11: 10 | B11: Москва | C11: Медведева Светлана Евгеньевна | D11: Специалист | E11: Бухгалтерия М | F11: 46104 | G11: =IF(TRIM(SUBSTITUTE(SUBSTITUTE(SUBSTITUTE(SUBSTITUTE(SUBSTITUTE(SUBSTITUTE(SUBSTITUTE(SUBSTITUTE(SUBSTITUTE(SUBSTITUTE(SUBSTITUTE(LOWER(TRIM(D11)),"ё","е")," -","-"),"- ","-")," 2 разряда","")," 3 разряда","")," 4 разряда","")," 5 разряда","")," 6 разряда","")," 1 категории","")," 2 категории","")," 3 категории",""))="инженер",IF(AND(ISNUMBER(SEARCH("техническ",E11)),ISNUMBER(SEARCH("контрол",E11))),"инженер отк",IF(ISNUMBER(SEARCH("диспетч",E11)),"инженер пдо",TRIM(SUBSTITUTE(SUBSTITUTE(SUBSTITUTE(SUBSTITUTE(SUBSTITUTE(SUBSTITUTE(SUBSTITUTE(SUBSTITUTE(SUBSTITUTE(SUBSTITUTE(SUBSTITUTE(LOWER(TRIM(D11)),"ё","е")," -","-"),"- ","-")," 2 разряда","")," 3 разряда","")," 4 разряда","")," 5 разряда","")," 6 разряда","")," 1 категории","")," 2 категории","")," 3 категории","")))),IF(TRIM(SUBSTITUTE(SUBSTITUTE(SUBSTITUTE(SUBSTITUTE(SUBSTITUTE(SUBSTITUTE(SUBSTITUTE(SUBSTITUTE(SUBSTITUTE(SUBSTITUTE(SUBSTITUTE(LOWER(TRIM(D11)),"ё","е")," -","-"),"- ","-")," 2 разряда","")," 3 разряда","")," 4 разряда","")," 5 разряда","")," 6 разряда","")," 1 категории","")," 2 категории","")," 3 категории",""))="ведущий инженер",IF(ISNUMBER(SEARCH("диспетч",E11)),"ведущий инженер пдо",TRIM(SUBSTITUTE(SUBSTITUTE(SUBSTITUTE(SUBSTITUTE(SUBSTITUTE(SUBSTITUTE(SUBSTITUTE(SUBSTITUTE(SUBSTITUTE(SUBSTITUTE(SUBSTITUTE(LOWER(TRIM(D11)),"ё","е")," -","-"),"- ","-")," 2 разряда","")," 3 разряда","")," 4 разряда","")," 5 разряда","")," 6 разряда","")," 1 категории","")," 2 категории","")," 3 категории",""))),IF(TRIM(SUBSTITUTE(SUBSTITUTE(SUBSTITUTE(SUBSTITUTE(SUBSTITUTE(SUBSTITUTE(SUBSTITUTE(SUBSTITUTE(SUBSTITUTE(SUBSTITUTE(SUBSTITUTE(LOWER(TRIM(D11)),"ё","е")," -","-"),"- ","-")," 2 разряда","")," 3 разряда","")," 4 разряда","")," 5 разряда","")," 6 разряда","")," 1 категории","")," 2 категории","")," 3 категории",""))="контролер","контролер отк",TRIM(SUBSTITUTE(SUBSTITUTE(SUBSTITUTE(SUBSTITUTE(SUBSTITUTE(SUBSTITUTE(SUBSTITUTE(SUBSTITUTE(SUBSTITUTE(SUBSTITUTE(SUBSTITUTE(LOWER(TRIM(D11)),"ё","е")," -","-"),"- ","-")," 2 разряда","")," 3 разряда","")," 4 разряда","")," 5 разряда","")," 6 разряда","")," 1 категории","")," 2 категории","")," 3 категории",""))))) -> специалист | H11: =IFERROR(INDEX(Соответствие!$B$2:$B$76,MATCH(G11,Соответствие!$A$2:$A$76,0)),"?") -> 12 | I11: =IFERROR(INDEX('Перечень должностей'!$C$2:$C$46,MATCH(H11,'Перечень должностей'!$A$2:$A$46,0)),"") -> п.4.4, п.5.1, п.5.2 | J11: =IFERROR(INDEX('Перечень должностей'!$D$2:$D$46,MATCH(H11,'Перечень должностей'!$A$2:$A$46,0)),12) -> 12 | M11: =IF(K11="","",EDATE(IF(L11<>"",L11,K11),J11)) | N11: =IFERROR(INDEX('Перечень должностей'!$F$2:$F$46,MATCH(H11,'Перечень должностей'!$A$2:$A$46,0)),"") -> - | P11: =IF(O11="","",EDATE(O11,60)) | Q11: =IF(AND(K11<>"",F11<>"",K11>F11),"ДА","")
A12: 11 | B12: Москва | C12: Киреева Вера Антоновна | D12: Старший технический работник | E12: Административно-хозяйственный отдел М | F12: 43283 | G12: =IF(TRIM(SUBSTITUTE(SUBSTITUTE(SUBSTITUTE(SUBSTITUTE(SUBSTITUTE(SUBSTITUTE(SUBSTITUTE(SUBSTITUTE(SUBSTITUTE(SUBSTITUTE(SUBSTITUTE(LOWER(TRIM(D12)),"ё","е")," -","-"),"- ","-")," 2 разряда","")," 3 разряда","")," 4 разряда","")," 5 разряда","")," 6 разряда","")," 1 категории","")," 2 категории","")," 3 категории",""))="инженер",IF(AND(ISNUMBER(SEARCH("техническ",E12)),ISNUMBER(SEARCH("контрол",E12))),"инженер отк",IF(ISNUMBER(SEARCH("диспетч",E12)),"инженер пдо",TRIM(SUBSTITUTE(SUBSTITUTE(SUBSTITUTE(SUBSTITUTE(SUBSTITUTE(SUBSTITUTE(SUBSTITUTE(SUBSTITUTE(SUBSTITUTE(SUBSTITUTE(SUBSTITUTE(LOWER(TRIM(D12)),"ё","е")," -","-"),"- ","-")," 2 разряда","")," 3 разряда","")," 4 разряда","")," 5 разряда","")," 6 разряда","")," 1 категории","")," 2 категории","")," 3 категории","")))),IF(TRIM(SUBSTITUTE(SUBSTITUTE(SUBSTITUTE(SUBSTITUTE(SUBSTITUTE(SUBSTITUTE(SUBSTITUTE(SUBSTITUTE(SUBSTITUTE(SUBSTITUTE(SUBSTITUTE(LOWER(TRIM(D12)),"ё","е")," -","-"),"- ","-")," 2 разряда","")," 3 разряда","")," 4 разряда","")," 5 разряда","")," 6 разряда","")," 1 категории","")," 2 категории","")," 3 категории",""))="ведущий инженер",IF(ISNUMBER(SEARCH("диспетч",E12)),"ведущий инженер пдо",TRIM(SUBSTITUTE(SUBSTITUTE(SUBSTITUTE(SUBSTITUTE(SUBSTITUTE(SUBSTITUTE(SUBSTITUTE(SUBSTITUTE(SUBSTITUTE(SUBSTITUTE(SUBSTITUTE(LOWER(TRIM(D12)),"ё","е")," -","-"),"- ","-")," 2 разряда","")," 3 разряда","")," 4 разряда","")," 5 разряда","")," 6 разряда","")," 1 категории","")," 2 категории","")," 3 категории",""))),IF(TRIM(SUBSTITUTE(SUBSTITUTE(SUBSTITUTE(SUBSTITUTE(SUBSTITUTE(SUBSTITUTE(SUBSTITUTE(SUBSTITUTE(SUBSTITUTE(SUBSTITUTE(SUBSTITUTE(LOWER(TRIM(D12)),"ё","е")," -","-"),"- ","-")," 2 разряда","")," 3 разряда","")," 4 разряда","")," 5 разряда","")," 6 разряда","")," 1 категории","")," 2 категории","")," 3 категории",""))="контролер","контролер отк",TRIM(SUBSTITUTE(SUBSTITUTE(SUBSTITUTE(SUBSTITUTE(SUBSTITUTE(SUBSTITUTE(SUBSTITUTE(SUBSTITUTE(SUBSTITUTE(SUBSTITUTE(SUBSTITUTE(LOWER(TRIM(D12)),"ё","е")," -","-"),"- ","-")," 2 разряда","")," 3 разряда","")," 4 разряда","")," 5 разряда","")," 6 разряда","")," 1 категории","")," 2 категории","")," 3 категории",""))))) -> старший технический работник | H12: =IFERROR(INDEX(Соответствие!$B$2:$B$76,MATCH(G12,Соответствие!$A$2:$A$76,0)),"?") -> 10 | I12: =IFERROR(INDEX('Перечень должностей'!$C$2:$C$46,MATCH(H12,'Перечень должностей'!$A$2:$A$46,0)),"") -> п.1.48, п.4.3.1, п.4.4, п.5.1 | J12: =IFERROR(INDEX('Перечень должностей'!$D$2:$D$46,MATCH(H12,'Перечень должностей'!$A$2:$A$46,0)),12) -> 12 | M12: =IF(K12="","",EDATE(IF(L12<>"",L12,K12),J12)) | N12: =IFERROR(INDEX('Перечень должностей'!$F$2:$F$46,MATCH(H12,'Перечень должностей'!$A$2:$A$46,0)),"") -> - | P12: =IF(O12="","",EDATE(O12,60)) | Q12: =IF(AND(K12<>"",F12<>"",K12>F12),"ДА","")
A13: 12 | B13: Москва | C13: Лебедева Валентина Михайловна | D13: Старший технический работник | E13: Административно-хозяйственный отдел М | F13: 46065 | G13: =IF(TRIM(SUBSTITUTE(SUBSTITUTE(SUBSTITUTE(SUBSTITUTE(SUBSTITUTE(SUBSTITUTE(SUBSTITUTE(SUBSTITUTE(SUBSTITUTE(SUBSTITUTE(SUBSTITUTE(LOWER(TRIM(D13)),"ё","е")," -","-"),"- ","-")," 2 разряда","")," 3 разряда","")," 4 разряда","")," 5 разряда","")," 6 разряда","")," 1 категории","")," 2 категории","")," 3 категории",""))="инженер",IF(AND(ISNUMBER(SEARCH("техническ",E13)),ISNUMBER(SEARCH("контрол",E13))),"инженер отк",IF(ISNUMBER(SEARCH("диспетч",E13)),"инженер пдо",TRIM(SUBSTITUTE(SUBSTITUTE(SUBSTITUTE(SUBSTITUTE(SUBSTITUTE(SUBSTITUTE(SUBSTITUTE(SUBSTITUTE(SUBSTITUTE(SUBSTITUTE(SUBSTITUTE(LOWER(TRIM(D13)),"ё","е")," -","-"),"- ","-")," 2 разряда","")," 3 разряда","")," 4 разряда","")," 5 разряда","")," 6 разряда","")," 1 категории","")," 2 категории","")," 3 категории","")))),IF(TRIM(SUBSTITUTE(SUBSTITUTE(SUBSTITUTE(SUBSTITUTE(SUBSTITUTE(SUBSTITUTE(SUBSTITUTE(SUBSTITUTE(SUBSTITUTE(SUBSTITUTE(SUBSTITUTE(LOWER(TRIM(D13)),"ё","е")," -","-"),"- ","-")," 2 разряда","")," 3 разряда","")," 4 разряда","")," 5 разряда","")," 6 разряда","")," 1 категории","")," 2 категории","")," 3 категории",""))="ведущий инженер",IF(ISNUMBER(SEARCH("диспетч",E13)),"ведущий инженер пдо",TRIM(SUBSTITUTE(SUBSTITUTE(SUBSTITUTE(SUBSTITUTE(SUBSTITUTE(SUBSTITUTE(SUBSTITUTE(SUBSTITUTE(SUBSTITUTE(SUBSTITUTE(SUBSTITUTE(LOWER(TRIM(D13)),"ё","е")," -","-"),"- ","-")," 2 разряда","")," 3 разряда","")," 4 разряда","")," 5 разряда","")," 6 разряда","")," 1 категории","")," 2 категории","")," 3 категории",""))),IF(TRIM(SUBSTITUTE(SUBSTITUTE(SUBSTITUTE(SUBSTITUTE(SUBSTITUTE(SUBSTITUTE(SUBSTITUTE(SUBSTITUTE(SUBSTITUTE(SUBSTITUTE(SUBSTITUTE(LOWER(TRIM(D13)),"ё","е")," -","-"),"- ","-")," 2 разряда","")," 3 разряда","")," 4 разряда","")," 5 разряда","")," 6 разряда","")," 1 категории","")," 2 категории","")," 3 категории",""))="контролер","контролер отк",TRIM(SUBSTITUTE(SUBSTITUTE(SUBSTITUTE(SUBSTITUTE(SUBSTITUTE(SUBSTITUTE(SUBSTITUTE(SUBSTITUTE(SUBSTITUTE(SUBSTITUTE(SUBSTITUTE(LOWER(TRIM(D13)),"ё","е")," -","-"),"- ","-")," 2 разряда","")," 3 разряда","")," 4 разряда","")," 5 разряда","")," 6 разряда","")," 1 категории","")," 2 категории","")," 3 категории",""))))) -> старший технический работник | H13: =IFERROR(INDEX(Соответствие!$B$2:$B$76,MATCH(G13,Соответствие!$A$2:$A$76,0)),"?") -> 10 | I13: =IFERROR(INDEX('Перечень должностей'!$C$2:$C$46,MATCH(H13,'Перечень должностей'!$A$2:$A$46,0)),"") -> п.1.48, п.4.3.1, п.4.4, п.5.1 | J13: =IFERROR(INDEX('Перечень должностей'!$D$2:$D$46,MATCH(H13,'Перечень должностей'!$A$2:$A$46,0)),12) -> 12 | M13: =IF(K13="","",EDATE(IF(L13<>"",L13,K13),J13)) | N13: =IFERROR(INDEX('Перечень должностей'!$F$2:$F$46,MATCH(H13,'Перечень должностей'!$A$2:$A$46,0)),"") -> - | P13: =IF(O13="","",EDATE(O13,60)) | Q13: =IF(AND(K13<>"",F13<>"",K13>F13),"ДА","")
... A23: 22 | B23: Внуково | C23: Постульгин Александр Валентинович | D23: Слесарь-сборщик 5 разряда | E23: Производственное подразделение Внуково М | F23: 45208 | G23: =IF(TRIM(SUBSTITUTE(SUBSTITUTE(SUBSTITUTE(SUBSTITUTE(SUBSTITUTE(SUBSTITUTE(SUBSTITUTE(SUBSTITUTE(SUBSTITUTE(SUBSTITUTE(SUBSTITUTE(LOWER(TRIM(D23)),"ё","е")," -","-"),"- ","-")," 2 разряда","")," 3 разряда","")," 4 разряда","")," 5 разряда","")," 6 разряда","")," 1 категории","")," 2 категории","")," 3 категории",""))="инженер",IF(AND(ISNUMBER(SEARCH("техническ",E23)),ISNUMBER(SEARCH("контрол",E23))),"инженер отк",IF(ISNUMBER(SEARCH("диспетч",E23)),"инженер пдо",TRIM(SUBSTITUTE(SUBSTITUTE(SUBSTITUTE(SUBSTITUTE(SUBSTITUTE(SUBSTITUTE(SUBSTITUTE(SUBSTITUTE(SUBSTITUTE(SUBSTITUTE(SUBSTITUTE(LOWER(TRIM(D23)),"ё","е")," -","-"),"- ","-")," 2 разряда","")," 3 разряда","")," 4 разряда","")," 5 разряда","")," 6 разряда","")," 1 категории","")," 2 категории","")," 3 категории","")))),IF(TRIM(SUBSTITUTE(SUBSTITUTE(SUBSTITUTE(SUBSTITUTE(SUBSTITUTE(SUBSTITUTE(SUBSTITUTE(SUBSTITUTE(SUBSTITUTE(SUBSTITUTE(SUBSTITUTE(LOWER(TRIM(D23)),"ё","е")," -","-"),"- ","-")," 2 разряда","")," 3 разряда","")," 4 разряда","")," 5 разряда","")," 6 разряда","")," 1 категории","")," 2 категории","")," 3 категории",""))="ведущий инженер",IF(ISNUMBER(SEARCH("диспетч",E23)),"ведущий инженер пдо",TRIM(SUBSTITUTE(SUBSTITUTE(SUBSTITUTE(SUBSTITUTE(SUBSTITUTE(SUBSTITUTE(SUBSTITUTE(SUBSTITUTE(SUBSTITUTE(SUBSTITUTE(SUBSTITUTE(LOWER(TRIM(D23)),"ё","е")," -","-"),"- ","-")," 2 разряда","")," 3 разряда","")," 4 разряда","")," 5 разряда","")," 6 разряда","")," 1 категории","")," 2 категории","")," 3 категории",""))),IF(TRIM(SUBSTITUTE(SUBSTITUTE(SUBSTITUTE(SUBSTITUTE(SUBSTITUTE(SUBSTITUTE(SUBSTITUTE(SUBSTITUTE(SUBSTITUTE(SUBSTITUTE(SUBSTITUTE(LOWER(TRIM(D23)),"ё","е")," -","-"),"- ","-")," 2 разряда","")," 3 разряда","")," 4 разряда","")," 5 разряда","")," 6 разряда","")," 1 категории","")," 2 категории","")," 3 категории",""))="контролер","контролер отк",TRIM(SUBSTITUTE(SUBSTITUTE(SUBSTITUTE(SUBSTITUTE(SUBSTITUTE(SUBSTITUTE(SUBSTITUTE(SUBSTITUTE(SUBSTITUTE(SUBSTITUTE(SUBSTITUTE(LOWER(TRIM(D23)),"ё","е")," -","-"),"- ","-")," 2 разряда","")," 3 разряда","")," 4 разряда","")," 5 разряда","")," 6 разряда","")," 1 категории","")," 2 категории","")," 3 категории",""))))) -> слесарь-сборщик | H23: =IFERROR(INDEX(Соответствие!$B$2:$B$76,MATCH(G23,Соответствие!$A$2:$A$76,0)),"?") -> 19 | I23: =IFERROR(INDEX('Перечень должностей'!$C$2:$C$46,MATCH(H23,'Перечень должностей'!$A$2:$A$46,0)),"") -> п.4.3.1, п.4.3.2, п.4.4, п.5.1, п.6.2, п.15 | J23: =IFERROR(INDEX('Перечень должностей'!$D$2:$D$46,MATCH(H23,'Перечень должностей'!$A$2:$A$46,0)),12) -> 12 | M23: =IF(K23="","",EDATE(IF(L23<>"",L23,K23),J23)) | N23: =IFERROR(INDEX('Перечень должностей'!$F$2:$F$46,MATCH(H23,'Перечень должностей'!$A$2:$A$46,0)),"") -> - | P23: =IF(O23="","",EDATE(O23,60)) | Q23: =IF(AND(K23<>"",F23<>"",K23>F23),"ДА","")
