Workbook

Sheet Сводка
A1: Сводка по площадкам: медицинские осмотры и психиатрическое освидетельствование, 2026 год
A2: Источник: «Учёт медосмотров» на 15.10.2026; статусы на 16.10.2026. Графы C–H считаются формулами по листам «Периодический 2026» и «Психиатрическое».
A4: Площадка | B4: Всего работников в журнале | C4: Периодический осмотр — всего | D4: в т.ч. нет сведений об осмотрах | E4: в т.ч. просрочен | F4: в т.ч. предстоит | G4: в т.ч. принятые в 2026 г. | H4: Психиатрическое освидетельствование
A5: Машково | B5: 175 | C5: =COUNTIF('Периодический 2026'!$B$5:$B$1000,A5) -> 165 | D5: =COUNTIFS('Периодический 2026'!$B$5:$B$1000,A5,'Периодический 2026'!$J$5:$J$1000,"Нет сведений об осмотрах") -> 159 | E5: =COUNTIFS('Периодический 2026'!$B$5:$B$1000,A5,'Периодический 2026'!$J$5:$J$1000,"Просрочен") -> 6 | F5: =COUNTIFS('Периодический 2026'!$B$5:$B$1000,A5,'Периодический 2026'!$J$5:$J$1000,"Предстоит") -> 0 | G5: =COUNTIFS('Периодический 2026'!$B$5:$B$1000,A5,'Периодический 2026'!$G$5:$G$1000,">="&DATE(2026,1,1)) -> 22 | H5: =COUNTIF(Психиатрическое!$B$5:$B$1000,A5) -> 19
A6: Руднево | B6: 69 | C6: =COUNTIF('Периодический 2026'!$B$5:$B$1000,A6) -> 54 | D6: =COUNTIFS('Периодический 2026'!$B$5:$B$1000,A6,'Периодический 2026'!$J$5:$J$1000,"Нет сведений об осмотрах") -> 48 | E6: =COUNTIFS('Периодический 2026'!$B$5:$B$1000,A6,'Периодический 2026'!$J$5:$J$1000,"Просрочен") -> 5 | F6: =COUNTIFS('Периодический 2026'!$B$5:$B$1000,A6,'Периодический 2026'!$J$5:$J$1000,"Предстоит") -> 1 | G6: =COUNTIFS('Периодический 2026'!$B$5:$B$1000,A6,'Периодический 2026'!$G$5:$G$1000,">="&DATE(2026,1,1)) -> 13 | H6: =COUNTIF(Психиатрическое!$B$5:$B$1000,A6) -> 1
A7: Воронеж | B7: 65 | C7: =COUNTIF('Периодический 2026'!$B$5:$B$1000,A7) -> 61 | D7: =COUNTIFS('Периодический 2026'!$B$5:$B$1000,A7,'Периодический 2026'!$J$5:$J$1000,"Нет сведений об осмотрах") -> 46 | E7: =COUNTIFS('Периодический 2026'!$B$5:$B$1000,A7,'Периодический 2026'!$J$5:$J$1000,"Просрочен") -> 14 | F7: =COUNTIFS('Периодический 2026'!$B$5:$B$1000,A7,'Периодический 2026'!$J$5:$J$1000,"Предстоит") -> 1 | G7: =COUNTIFS('Периодический 2026'!$B$5:$B$1000,A7,'Периодический 2026'!$G$5:$G$1000,">="&DATE(2026,1,1)) -> 9 | H7: =COUNTIF(Психиатрическое!$B$5:$B$1000,A7) -> 17
A8: Ульяновск | B8: 20 | C8: =COUNTIF('Периодический 2026'!$B$5:$B$1000,A8) -> 17 | D8: =COUNTIFS('Периодический 2026'!$B$5:$B$1000,A8,'Периодический 2026'!$J$5:$J$1000,"Нет сведений об осмотрах") -> 8 | E8: =COUNTIFS('Периодический 2026'!$B$5:$B$1000,A8,'Периодический 2026'!$J$5:$J$1000,"Просрочен") -> 4 | F8: =COUNTIFS('Периодический 2026'!$B$5:$B$1000,A8,'Периодический 2026'!$J$5:$J$1000,"Предстоит") -> 5 | G8: =COUNTIFS('Периодический 2026'!$B$5:$B$1000,A8,'Периодический 2026'!$G$5:$G$1000,">="&DATE(2026,1,1)) -> 0 | H8: =COUNTIF(Психиатрическое!$B$5:$B$1000,A8) -> 5
A9: Казань | B9: 16 | C9: =COUNTIF('Периодический 2026'!$B$5:$B$1000,A9) -> 14 | D9: =COUNTIFS('Периодический 2026'!$B$5:$B$1000,A9,'Периодический 2026'!$J$5:$J$1000,"Нет сведений об осмотрах") -> 8 | E9: =COUNTIFS('Периодический 2026'!$B$5:$B$1000,A9,'Периодический 2026'!$J$5:$J$1000,"Просрочен") -> 4 | F9: =COUNTIFS('Периодический 2026'!$B$5:$B$1000,A9,'Периодический 2026'!$J$5:$J$1000,"Предстоит") -> 2 | G9: =COUNTIFS('Периодический 2026'!$B$5:$B$1000,A9,'Периодический 2026'!$G$5:$G$1000,">="&DATE(2026,1,1)) -> 2 | H9: =COUNTIF(Психиатрическое!$B$5:$B$1000,A9) -> 6
A10: Внуково | B10: 10 | C10: =COUNTIF('Периодический 2026'!$B$5:$B$1000,A10) -> 10 | D10: =COUNTIFS('Периодический 2026'!$B$5:$B$1000,A10,'Периодический 2026'!$J$5:$J$1000,"Нет сведений об осмотрах") -> 9 | E10: =COUNTIFS('Периодический 2026'!$B$5:$B$1000,A10,'Периодический 2026'!$J$5:$J$1000,"Просрочен") -> 1 | F10: =COUNTIFS('Периодический 2026'!$B$5:$B$1000,A10,'Периодический 2026'!$J$5:$J$1000,"Предстоит") -> 0 | G10: =COUNTIFS('Периодический 2026'!$B$5:$B$1000,A10,'Периодический 2026'!$G$5:$G$1000,">="&DATE(2026,1,1)) -> 0 | H10: =COUNTIF(Психиатрическое!$B$5:$B$1000,A10) -> 2
A11: Москва | B11: 9 | C11: =COUNTIF('Периодический 2026'!$B$5:$B$1000,A11) -> 9 | D11: =COUNTIFS('Периодический 2026'!$B$5:$B$1000,A11,'Периодический 2026'!$J$5:$J$1000,"Нет сведений об осмотрах") -> 9 | E11: =COUNTIFS('Периодический 2026'!$B$5:$B$1000,A11,'Периодический 2026'!$J$5:$J$1000,"Просрочен") -> 0 | F11: =COUNTIFS('Периодический 2026'!$B$5:$B$1000,A11,'Периодический 2026'!$J$5:$J$1000,"Предстоит") -> 0 | G11: =COUNTIFS('Периодический 2026'!$B$5:$B$1000,A11,'Периодический 2026'!$G$5:$G$1000,">="&DATE(2026,1,1)) -> 2 | H11: =COUNTIF(Психиатрическое!$B$5:$B$1000,A11) -> 1
A12: Жуковский | B12: 1 | C12: =COUNTIF('Периодический 2026'!$B$5:$B$1000,A12) -> 1 | D12: =COUNTIFS('Периодический 2026'!$B$5:$B$1000,A12,'Периодический 2026'!$J$5:$J$1000,"Нет сведений об осмотрах") -> 1 | E12: =COUNTIFS('Периодический 2026'!$B$5:$B$1000,A12,'Периодический 2026'!$J$5:$J$1000,"Просрочен") -> 0 | F12: =COUNTIFS('Периодический 2026'!$B$5:$B$1000,A12,'Периодический 2026'!$J$5:$J$1000,"Предстоит") -> 0 | G12: =COUNTIFS('Периодический 2026'!$B$5:$B$1000,A12,'Периодический 2026'!$G$5:$G$1000,">="&DATE(2026,1,1)) -> 0 | H12: =COUNTIF(Психиатрическое!$B$5:$B$1000,A12) -> 0
A13: Итого | B13: =SUM(B5:B12) -> 365 | C13: =SUM(C5:C12) -> 331 | D13: =SUM(D5:D12) -> 288 | E13: =SUM(E5:E12) -> 34 | F13: =SUM(F5:F12) -> 9 | G13: =SUM(G5:G12) -> 48 | H13: =SUM(H5:H12) -> 51
A14: Контроль: «Периодический — всего» = «нет сведений» + «просрочен» + «предстоит» | C14: =IF(C13=D13+E13+F13,"сходится","ОШИБКА") -> сходится
A15: Контроль: итог по площадкам = число строк в списке | C15: =IF(C13=COUNTA('Периодический 2026'!$C$5:$C$1000),"сходится","ОШИБКА") -> сходится | H15: =IF(H13=COUNTA(Психиатрическое!$C$5:$C$1000),"сходится","ОШИБКА") -> сходится
A16: Графа B — число работников площадки в журнале (значение, не формула).

Sheet Периодический 2026
A1: Список работников, подлежащих периодическому медицинскому осмотру в 2026 году
A2: Источник: «Учёт медосмотров» на 15.10.2026. Всего: 331 чел.
A4: № | B4: Площадка | C4: ФИО | D4: Должность | E4: Подразделение | F4: Пункты приказа №29н | G4: Дата приёма | H4: Дата предварит. осмотра | I4: Дата периодич. осмотра (план) | J4: Статус на 16.10.2026
A5: 1 | B5: Внуково | C5: Алфимов Дмитрий Юрьевич | D5: Электромонтажник 5 разряда | E5: Производственное подразделение Внуково М | F5: п.4.3.1, п.4.3.2, п.4.4, п.4.9, п.5.1, п.5.2, п.6.2, п.9 | G5: 44327 | J5: Нет сведений об осмотрах
A6: 2 | B6: Внуково | C6: Варламов Олег Владимирович | D6: Менеджер-комплектовщик | E6: Производственное подразделение Внуково М | F6: п.4.4, п.5.1, п.6.2 | G6: 44152 | J6: Нет сведений об осмотрах
A7: 3 | B7: Внуково | C7: Зосимов Александр Геннадиевич | D7: Слесарь-сборщик 6 разряда | E7: Производственное подразделение Внуково М | F7: п.4.3.1, п.4.3.2, п.4.4, п.5.1, п.6.2, п.15 | G7: 40087 | J7: Нет сведений об осмотрах
A8: 4 | B8: Внуково | C8: Климачев Сергей Валерьевич | D8: Заместитель директора департамента-Начальник производственного подразделения | E8: Производственное подразделение Внуково М | F8: п.4.3.2, п.4.4, п.5.1, п.5.2, п.6.2 | G8: 41334 | J8: Нет сведений об осмотрах
A9: 5 | B9: Внуково | C9: Кукин Эрнст Валерьевич | D9: Реставратор | E9: Производственное подразделение Внуково М | F9: п.4.3.1, п.4.4, п.5.1, п.5.2, п.15 | G9: 45789 | J9: Нет сведений об осмотрах
A10: 6 | B10: Внуково | C10: Луданцев Алексей Владимирович | D10: Слесарь-сборщик 4 разряда | E10: Производственное подразделение Внуково М | F10: п.4.3.1, п.4.3.2, п.4.4, п.5.1, п.6.2, п.15 | G10: 45950 | H10: 45940 | I10: 46305 | J10: Просрочен
A11: 7 | B11: Внуково | C11: Нитяговский Сергей Александрович | D11: Слесарь-сборщик 5 разряда | E11: Производственное подразделение Внуково М | F11: п.4.3.1, п.4.3.2, п.4.4, п.5.1, п.6.2, п.15 | G11: 42438 | J11: Нет сведений об осмотрах
A12: 8 | B12: Внуково | C12: Постульгин Александр Валентинович | D12: Слесарь-сборщик 5 разряда | E12: Производственное подразделение Внуково М | F12: п.4.3.1, п.4.3.2, п.4.4, п.5.1, п.6.2, п.15 | G12: 45208 | J12: Нет сведений об осмотрах
A13: 9 | B13: Внуково | C13: Туманов Сергей Дмитриевич | D13: Электромонтажник 4 разряда | E13: Производственное подразделение Внуково М | F13: п.4.3.1, п.4.3.2, п.4.4, п.4.9, п.5.1, п.5.2, п.6.2, п.9 | G13: 45429 | J13: Нет сведений об осмотрах
A14: 10 | B14: Внуково | C14: Шевченко Сергей Васильевич | D14: Ведущий специалист по реставрации | E14: Производственное подразделение Внуково М | F14: п.4.3.1, п.4.4, п.5.1, п.5.2, п.15 | G14: 40210 | J14: Нет сведений об осмотрах
A15: 11 | B15: Воронеж | C15: Гуровская Ирина Александровна | D15: Инженер 3 категории | E15: Отдел технического контроля В | F15: п.4.4, п.5.1, п.5.2 | G15: 41351 | J15: Нет сведений об осмотрах
A16: 12 | B16: Воронеж | C16: Симоненко Дмитрий Андреевич | D16: Контролер 1 категории | E16: Отдел технического контроля В | F16: п.4.4, п.5.1, п.5.2 | G16: 45852 | J16: Нет сведений об осмотрах
A17: 13 | B17: Воронеж | C17: Свиридова Ирина Александровна | D17: Диспетчер | E17: Планово-диспетчерский отдел В | F17: п.4.4, п.5.1, п.5.2 | G17: 46245 | J17: Нет сведений об осмотрах
A18: 14 | B18: Воронеж | C18: Дуленков Александр Вячеславович | D18: Инженер по авиационному и радиоэлектронному оборудованию | E18: Производственное подразделение Воронеж | F18: п.4.4, п.4.6, п.5.1, п.6.2 | G18: 44966 | J18: Нет сведений об осмотрах
A19: 15 | B19: Воронеж | C19: Боровенский Андрей Алексеевич | D19: Слесарь - сборщик 4 разряда | E19: Производственное подразделение №6 (В н/д) | F19: п.4.3.1, п.4.3.2, п.4.4, п.5.1, п.6.2, п.15 | G19: 45693 | J19: Нет сведений об осмотрах
A20: 16 | B20: Воронеж | C20: Будавских Вадим Григорьевич | D20: Мастер участка сборки интерьера | E20: Производственное подразделение №6 (В н/д) | F20: п.4.4, п.5.1, п.5.2 | G20: 42121 | J20: Нет сведений об осмотрах
A21: 17 | B21: Воронеж | C21: Галактионов Александр Александрович | D21: Слесарь - сборщик 5 разряда | E21: Производственное подразделение №6 (В н/д) | F21: п.4.3.1, п.4.3.2, п.4.4, п.5.1, п.6.2, п.15 | G21: 45425 | H21: 45461 | I21: 45826 | J21: Просрочен
A22: 18 | B22: Воронеж | C22: Гаршин Сергей Александрович | D22: Слесарь - сборщик 4 разряда | E22: Производственное подразделение №6 (В н/д) | F22: п.4.3.1, п.4.3.2, п.4.4, п.5.1, п.6.2, п.15 | G22: 45901 | J22: Нет сведений об осмотрах
A23: 19 | B23: Воронеж | C23: Гунькин Юрий Игоревич | D23: Слесарь - сборщик 4 разряда | E23: Производственное подразделение №6 (В н/д) | F23: п.4.3.1, п.4.3.2, п.4.4, п.5.1, п.6.2, п.15 | G23: 46043 | J23: Нет сведений об осмотрах
A24: 20 | B24: Воронеж | C24: Зеленов Михаил Валерьевич | D24: Электромонтажник 5 разряда | E24: Производственное подразделение №6 (В н/д) | F24: п.4.3.1, п.4.3.2, п.4.4, п.4.9, п.5.1, п.5.2, п.6.2, п.9 | G24: 44124 | H24: 44662 | I24: 45027 | J24: Просрочен
A25: 21 | B25: Воронеж | C25: Зиновьев Вадим Дмитриевич | D25: Слесарь - сборщик 4 разряда | E25: Производственное подразделение №6 (В н/д) | F25: п.4.3.1, п.4.3.2, п.4.4, п.5.1, п.6.2, п.15 | G25: 45911 | J25: Нет сведений об осмотрах
A26: 22 | B26: Воронеж | C26: Иванов Алексей Николаевич | D26: Слесарь - сборщик 5 разряда | E26: Производственное подразделение №6 (В н/д) | F26: п.4.3.1, п.4.3.2, п.4.4, п.5.1, п.6.2, п.15 | G26: 44368 | J26: Нет сведений об осмотрах
A27: 23 | B27: Воронеж | C27: Ковряков Дмитрий Александрович | D27: Слесарь - сборщик 4 разряда | E27: Производственное подразделение №6 (В н/д) | F27: п.4.3.1, п.4.3.2, п.4.4, п.5.1, п.6.2, п.15 | G27: 45782 | J27: Нет сведений об осмотрах
A28: 24 | B28: Воронеж | C28: Кумицкий Алексей Иванович | D28: Слесарь - сборщик 4 разряда | E28: Производственное подразделение №6 (В н/д) | F28: п.4.3.1, п.4.3.2, п.4.4, п.5.1, п.6.2, п.15 | G28: 45847 | J28: Нет сведений об осмотрах
A29: 25 | B29: Воронеж | C29: Павлов Александр Сергеевич | D29: Мастер участка электромонтажных работ | E29: Производственное подразделение №6 (В н/д) | F29: п.4.3.1, п.4.3.2, п.4.4, п.4.9, п.5.1, п.5.2, п.6.2, п.9 | G29: 42983 | H29: 44662 | I29: 45027 | J29: Просрочен
A30: 26 | B30: Воронеж | C30: Самсонов Виталий Игоревич | D30: Слесарь-сборщик 3 разряда | E30: Производственное подразделение №6 (В н/д) | F30: п.4.3.1, п.4.3.2, п.4.4, п.5.1, п.6.2, п.15 | G30: 45782 | J30: Нет сведений об осмотрах
A31: 27 | B31: Воронеж | C31: Сухинин Андрей Алексеевич | D31: Слесарь - сборщик 4 разряда | E31: Производственное подразделение №6 (В н/д) | F31: п.4.3.1, п.4.3.2, п.4.4, п.5.1, п.6.2, п.15 | G31: 45765 | J31: Нет сведений об осмотрах
A32: 28 | B32: Воронеж | C32: Червяков Владислав Вячеславович | D32: Слесарь - сборщик 4 разряда | E32: Производственное подразделение №6 (В н/д) | F32: п.4.3.1, п.4.3.2, п.4.4, п.5.1, п.6.2, п.15 | G32: 45666 | J32: Нет сведений об осмотрах
A33: 29 | B33: Воронеж | C33: Юрьев Александр Николаевич | D33: Слесарь - сборщик 4 разряда | E33: Производственное подразделение №6 (В н/д) | F33: п.4.3.1, п.4.3.2, п.4.4, п.5.1, п.6.2, п.15 | G33: 46062 | J33: Нет сведений об осмотрах
A34: 30 | B34: Воронеж | C34: Белоусова Людмила Владимировна | D34: Кладовщик | E34: Склад В | F34: п.4.4, п.5.1, п.6.2 | G34: 46127 | J34: Нет сведений об осмотрах
A35: 31 | B35: Воронеж | C35: Басов Вадим Романович | D35: Электромонтажник 5 разряда | E35: Участок РЭО В | F35: п.4.3.1, п.4.3.2, п.4.4, п.4.9, п.5.1, п.5.2, п.6.2, п.9 | G35: 45852 | J35: Нет сведений об осмотрах
A36: 32 | B36: Воронеж | C36: Власова Ольга Вячеславовна | D36: Электромонтажник 3 разряда | E36: Участок РЭО В | F36: п.4.3.1, п.4.3.2, п.4.4, п.4.9, п.5.1, п.5.2, п.6.2, п.9 | G36: 46293 | J36: Нет сведений об осмотрах
A37: 33 | B37: Воронеж | C37: Воробьев Николай Александрович | D37: Электромонтажник 5 разряда | E37: Участок РЭО В | F37: п.4.3.1, п.4.3.2, п.4.4, п.4.9, п.5.1, п.5.2, п.6.2, п.9 | G37: 45797 | H37: 45768 | I37: 46133 | J37: Просрочен
A38: 34 | B38: Воронеж | C38: Золотарев Сергей Константинович | D38: Электромонтажник 5 разряда | E38: Участок РЭО В | F38: п.4.3.1, п.4.3.2, п.4.4, п.4.9, п.5.1, п.5.2, п.6.2, п.9 | G38: 45793 | H38: 45791 | I38: 46156 | J38: Просрочен
A39: 35 | B39: Воронеж | C39: Ковалёв Алексей Александрович | D39: Электромонтажник 5 разряда | E39: Участок РЭО В | F39: п.4.3.1, п.4.3.2, п.4.4, п.4.9, п.5.1, п.5.2, п.6.2, п.9 | G39: 44322 | H39: 44662 | I39: 45027 | J39: Просрочен
A40: 36 | B40: Воронеж | C40: Левин Александр Владимирович | D40: Электромонтажник 4 разряда | E40: Участок РЭО В | F40: п.4.3.1, п.4.3.2, п.4.4, п.4.9, п.5.1, п.5.2, п.6.2, п.9 | G40: 46140 | J40: Нет сведений об осмотрах
A41: 37 | B41: Воронеж | C41: Лисунов Кирилл Андреевич | D41: Электромонтажник 4 разряда | E41: Участок РЭО В | F41: п.4.3.1, п.4.3.2, п.4.4, п.4.9, п.5.1, п.5.2, п.6.2, п.9 | G41: 45796 | H41: 45784 | I41: 46149 | J41: Просрочен
...

Sheet Психиатрическое
A1: Список работников, подлежащих психиатрическому освидетельствованию (графа «Подлежит» = «Да»)
A2: Источник: «Учёт медосмотров» на 15.10.2026. Всего: 51 чел.
A4: № | B4: Площадка | C4: ФИО | D4: Должность | E4: Подразделение | F4: Основание (Перечень)
A5: 1 | B5: Казань | C5: Андреев Алексей Владимирович | D5: Электромонтажник 5 разряда | E5: Обособленное подразделение Казань | F5: п.11 Прил.№2: монтаж, наладка, техническое обслуживание, ремонт электроустановок.
A6: 2 | B6: Казань | C6: Аюпов Булат Фаилевич | D6: Электромонтажник 4 разряда | E6: Обособленное подразделение Казань | F6: п.11 Прил.№2: монтаж, наладка, техническое обслуживание, ремонт электроустановок.
A7: 3 | B7: Казань | C7: Булатова Лия Рустэмовна | D7: Электромонтажник 3 разряда | E7: Обособленное подразделение Казань | F7: п.11 Прил.№2: монтаж, наладка, техническое обслуживание, ремонт электроустановок.
A8: 4 | B8: Казань | C8: Матвеев Александр Николаевич | D8: Мастер электромонтажного участка | E8: Обособленное подразделение Казань | F8: п.11 Прил.№2: руководство работами по монтажу, наладке, ремонту электроустановок. Относится также мастер участка РЭО.
A9: 5 | B9: Казань | C9: Обухов Андрей Евгеньевич | D9: Электромонтажник 5 разряда | E9: Обособленное подразделение Казань | F9: п.11 Прил.№2: монтаж, наладка, техническое обслуживание, ремонт электроустановок.
A10: 6 | B10: Казань | C10: Юсупов Азат Рафаэлевич | D10: Электромонтажник 3 разряда | E10: Обособленное подразделение Казань | F10: п.11 Прил.№2: монтаж, наладка, техническое обслуживание, ремонт электроустановок.
A11: 7 | B11: Москва | C11: Высокий Владимир Евгеньевич | D11: Водитель автомобиля (персональный 2 категории) | E11: Отдел транспортного обеспечения (М н/д) | F11: п.1 Прил.№2: управление транспортными средствами.
A12: 8 | B12: Машково | C12: Акимов Михаил Александрович | D12: Водитель автомобиля-экспедитор | E12: Отдел транспортного обеспечения МШ | F12: п.1 Прил.№2: управление транспортными средствами.
A13: 9 | B13: Машково | C13: Батуревич Юрий Викторович | D13: Водитель автомобиля-экспедитор | E13: Отдел транспортного обеспечения МШ | F13: п.1 Прил.№2: управление транспортными средствами.
A14: 10 | B14: Машково | C14: Василенко Александр Иванович | D14: Водитель автомобиля-экспедитор | E14: Отдел транспортного обеспечения МШ | F14: п.1 Прил.№2: управление транспортными средствами.
A15: 11 | B15: Машково | C15: Грязнов Анатолий Николаевич | D15: Водитель автомобиля-экспедитор | E15: Отдел транспортного обеспечения МШ | F15: п.1 Прил.№2: управление транспортными средствами.
A16: 12 | B16: Машково | C16: Евдокимов Игорь Валентинович | D16: Водитель автомобиля-экспедитор | E16: Отдел транспортного обеспечения МШ | F16: п.1 Прил.№2: управление транспортными средствами.
... A55: 51 | B55: Ульяновск | C55: Рычков Александр Анатольевич | D55: Электромонтажник 3 разряда | E55: Электромонтажный участок (У н/д) | F55: п.11 Прил.№2: монтаж, наладка, техническое обслуживание, ремонт электроустановок.
