Workbook

Sheet Инструкция
A1: Порядок ведения учёта медицинских осмотров
A2: ООО «Авиационные интерьеры-СН». Редакция от 19.10.2026.
A4: 1. Общие положения
A5: Назначение | B5: Учёт предварительных и периодических медицинских осмотров и психиатрического освидетельствования работников, занятых на должностях (профессиях) по Перечню Приказа №43 от 03.04.2026.
A6: Состав файла | B6: «Сводка» — показатели по предприятию и площадкам; «Учёт медосмотров» — журнал по работникам; «Перечень» — должности, пункты вредных факторов, периодичность и признак психиатрического освидетельствования.
A7: Ответственный | B7: Отдел охраны труда и промышленной безопасности.
A9: 2. Порядок заполнения
A10: Приём работника | B10: Внести данные в первую свободную строку журнала: площадка, ФИО, должность по штатному расписанию, подразделение, дата приёма. Номер, пункт Перечня, периодичность и признак психиатрического освидетельствования заполнятся автоматически.
A11: Предварительный осмотр | B11: Дата — в графу «Предварительный».
A12: Периодический осмотр | B12: Дата последнего пройденного осмотра — в графу «Последний периодический» (прежняя дата заменяется). Если сведений о предварительном осмотре нет, дата периодического всё равно вносится — срок следующего осмотра рассчитается от неё.
A13: Психиатрическое освид. | B13: Дата — в графу «Дата прохождения». Требуется, если в графе «Подлежит» стоит «Да».
A14: Увольнение, перевод | B14: Строку работника удалить целиком (правая кнопка мыши → «Удалить» → «Строку»). При переводе — изменить должность и подразделение.
A15: Новая должность | B15: Если в графе «№ по Перечню» появился знак «?», должность отсутствует в Перечне — требуется внести её в Приказ №43 и в лист «Перечень».
A16: Контроль сроков | B16: Фильтр по графе «Периодический осмотр»: «Просрочен», «Истекает», «Нет сведений». По графе «Психиатр. освид.»: «Не пройдено».
A17: Резерв строк | B17: В конце журнала подготовлено 35 пустых строк. При их исчерпании — вставлять строки внутри таблицы, выше последней заполненной.
A19: 3. Условные обозначения
B20: Поле для заполнения.
B21: Срок не наступил.
B22: Срок наступает в течение 30 дней; нет даты предварительного осмотра при наличии периодического.
B23: Срок прошёл; нет сведений об осмотрах; осмотр пройден позже даты приёма.
B24: Подлежит психиатрическому освидетельствованию / освидетельствование не пройдено.
A26: 4. Психиатрическое освидетельствование
A27: Подлежат | B27: Электромонтёр по ремонту и обслуживанию электрооборудования, инженер-электрик (п.2); главный энергетик (п.5); электромонтажник (п.20); мастер электромонтажного участка, мастер участка РЭО (п.29) — п.11–12 Приложения №2 к Приказу №342н. Водители (п.38, 39), кладовщик-комплектовщик (п.46) — п.1 Приложения №2.
A28: Не подлежат | B28: Главный механик (п.6), сборщик стеклопластиковых изделий (п.26), охрана (п.45) — по решению ОТиПБ. Пересматривается при непосредственном обслуживании оборудования под давлением, поставленного на учёт в Ростехнадзоре (п.13 Прил.№2); для кладовщиков (п.14) — при управлении кранами (п.6 Прил.№2).
A29: Периодичность | B29: Не установлена (письмо Минздрава России №30-0/3066769). Освидетельствование проводится при приёме (переводе) и по направлению по итогам медосмотра. Контрольная дата +5 лет — внутренняя мера.
A31: 5. Нормативные документы
A32: ТК РФ | B32: ст. 76, 214, 220.
A33: Приказ №29н | B33: Минздрава России от 28.01.2021 «Об утверждении Порядка проведения обязательных предварительных и периодических медицинских осмотров работников…».
A34: Приказ №988н/1420н | B34: Минтруда России / Минздрава России от 31.12.2020 — перечень вредных и (или) опасных производственных факторов и работ.
A35: Приказ №342н | B35: Минздрава России от 20.05.2022 — порядок прохождения обязательного психиатрического освидетельствования (изм. Приказ №392н от 02.07.2025).
A36: Приказ №43 | B36: от 03.04.2026 — перечень должностей и профессий, подлежащих медицинским осмотрам.
A38: 6. Вопросы к решению
A39: Приказ №43 | B39: Внести должности «Техник-сборщик» и «Техник» (Машково; учитываются по п.21 и п.36). Внести должности «Контролер КПП» и «Контролер КПП-старший смены» (Машково, переименование должностей «Сторож», «Старший сторож»; учитываются по п.45).
A40: Приказ №342н | B40: Сверить номера пунктов Приложения №2 с редакцией Приказа №392н.
A41: Даты осмотров | B41: Запросить в медицинском центре сведения об осмотрах работников, по которым дат нет.
A43: 7. Лист регистрации изменений
A44: 10.09.2026 | B44: Журнал сформирован по штатному расписанию на 04.09.2026.
A45: 13.10.2026 | B45: Сверка со штатным расписанием на 05.10.2026: добавлено 12 работников, исключено 6.
A46: 15.10.2026 | B46: Электромонтажник (п.20), мастер электромонтажного участка и мастер участка РЭО (п.29) отнесены к подлежащим психиатрическому освидетельствованию.
A47: 15.10.2026 | B47: Исключены из учёта: Максимов Ю.А. (перевод на должность вне Перечня); Богачева М.С., Рысева П.В., Медведева С.Е., Костин А.И., Андреева Н.В. (специалисты, Москва).
...

Sheet Сводка
A1: Сводка по медицинским осмотрам
A2: ООО «Авиационные интерьеры-СН»
A3: по состоянию на | B3: =TODAY() -> 46314
A5: Медицинские осмотры
A6: Показатель | B6: чел. | C6: %
A7: Всего работников, подлежащих осмотру | B7: =COUNTA('Учёт медосмотров'!$C$6:$C$405) -> 369 | C7: =IF($B$7=0,"",B7/$B$7) -> 1
A8: Указана дата предварительного осмотра | B8: =COUNTIF('Учёт медосмотров'!$K$6:$K$405,"<>") -> 83 | C8: =IF($B$7=0,"",B8/$B$7) -> 0.22493225
A9: Не указана дата предварительного осмотра | B9: =COUNTIFS('Учёт медосмотров'!$C$6:$C$405,"<>",'Учёт медосмотров'!$K$6:$K$405,"") -> 286 | C9: =IF($B$7=0,"",B9/$B$7) -> 0.77506775
A10: в т.ч. принятые более года назад | B10: =COUNTIFS('Учёт медосмотров'!$C$6:$C$405,"<>",'Учёт медосмотров'!$F$6:$F$405,"<"&(TODAY()-365),'Учёт медосмотров'!$K$6:$K$405,"") -> 221 | C10: =IF($B$7=0,"",B10/$B$7) -> 0.59891599
A11: Указана дата периодического осмотра | B11: =COUNTIF('Учёт медосмотров'!$L$6:$L$405,"<>") -> 0 | C11: =IF($B$7=0,"",B11/$B$7) -> 0
A12: Периодический осмотр: в срок | B12: =COUNTIF('Учёт медосмотров'!$R$6:$R$405,"В срок") -> 43 | C12: =IF($B$7=0,"",B12/$B$7) -> 0.11653117
A13: Периодический осмотр: истекает в течение 30 дней | B13: =COUNTIF('Учёт медосмотров'!$R$6:$R$405,"Истекает") -> 5 | C13: =IF($B$7=0,"",B13/$B$7) -> 0.013550136
A14: Периодический осмотр: просрочен | B14: =COUNTIF('Учёт медосмотров'!$R$6:$R$405,"Просрочен") -> 35 | C14: =IF($B$7=0,"",B14/$B$7) -> 0.094850949
A15: Нет сведений об осмотрах | B15: =COUNTIF('Учёт медосмотров'!$R$6:$R$405,"Нет сведений") -> 286 | C15: =IF($B$7=0,"",B15/$B$7) -> 0.77506775
A16: Предварительный осмотр пройден позже даты приёма | B16: =COUNTIF('Учёт медосмотров'!$Q$6:$Q$405,"Да") -> 5 | C16: =IF($B$7=0,"",B16/$B$7) -> 0.013550136
A18: Психиатрическое освидетельствование
A19: Показатель | B19: чел. | C19: %
A20: Подлежат освидетельствованию | B20: =COUNTIF('Учёт медосмотров'!$N$6:$N$405,"Да") -> 59 | C20: =IF($B$7=0,"",B20/$B$7) -> 0.1598916
A21: дата прохождения указана | B21: =COUNTIFS('Учёт медосмотров'!$N$6:$N$405,"Да",'Учёт медосмотров'!$O$6:$O$405,"<>") -> 0 | C21: =IF($B$7=0,"",B21/$B$7) -> 0
A22: дата прохождения не указана | B22: =COUNTIF('Учёт медосмотров'!$S$6:$S$405,"Не пройдено") -> 59 | C22: =IF($B$7=0,"",B22/$B$7) -> 0.1598916
A23: Истёк внутренний контрольный срок (5 лет) | B23: =COUNTIFS('Учёт медосмотров'!$P$6:$P$405,"<>",'Учёт медосмотров'!$P$6:$P$405,"<"&TODAY()) -> 0 | C23: =IF($B$7=0,"",B23/$B$7) -> 0
A25: По площадкам
A26: Площадка | B26: Всего | C26: В срок | D26: Истекает (30 дн.) | E26: Просрочен | F26: Нет сведений | G26: Психиатр.: подлежат | H26: Психиатр.: не пройдено
A27: Внуково | B27: =COUNTIF('Учёт медосмотров'!$B$6:$B$405,$A27) -> 10 | C27: =COUNTIFS('Учёт медосмотров'!$B$6:$B$405,$A27,'Учёт медосмотров'!$R$6:$R$405,"В срок") -> 0 | D27: =COUNTIFS('Учёт медосмотров'!$B$6:$B$405,$A27,'Учёт медосмотров'!$R$6:$R$405,"Истекает") -> 0 | E27: =COUNTIFS('Учёт медосмотров'!$B$6:$B$405,$A27,'Учёт медосмотров'!$R$6:$R$405,"Просрочен") -> 1 | F27: =COUNTIFS('Учёт медосмотров'!$B$6:$B$405,$A27,'Учёт медосмотров'!$R$6:$R$405,"Нет сведений") -> 9 | G27: =COUNTIFS('Учёт медосмотров'!$B$6:$B$405,$A27,'Учёт медосмотров'!$N$6:$N$405,"Да") -> 2 | H27: =COUNTIFS('Учёт медосмотров'!$B$6:$B$405,$A27,'Учёт медосмотров'!$S$6:$S$405,"Не пройдено") -> 2
A28: Воронеж | B28: =COUNTIF('Учёт медосмотров'!$B$6:$B$405,$A28) -> 66 | C28: =COUNTIFS('Учёт медосмотров'!$B$6:$B$405,$A28,'Учёт медосмотров'!$R$6:$R$405,"В срок") -> 5 | D28: =COUNTIFS('Учёт медосмотров'!$B$6:$B$405,$A28,'Учёт медосмотров'!$R$6:$R$405,"Истекает") -> 0 | E28: =COUNTIFS('Учёт медосмотров'!$B$6:$B$405,$A28,'Учёт медосмотров'!$R$6:$R$405,"Просрочен") -> 15 | F28: =COUNTIFS('Учёт медосмотров'!$B$6:$B$405,$A28,'Учёт медосмотров'!$R$6:$R$405,"Нет сведений") -> 46 | G28: =COUNTIFS('Учёт медосмотров'!$B$6:$B$405,$A28,'Учёт медосмотров'!$N$6:$N$405,"Да") -> 17 | H28: =COUNTIFS('Учёт медосмотров'!$B$6:$B$405,$A28,'Учёт медосмотров'!$S$6:$S$405,"Не пройдено") -> 17
A29: Жуковский | B29: =COUNTIF('Учёт медосмотров'!$B$6:$B$405,$A29) -> 1 | C29: =COUNTIFS('Учёт медосмотров'!$B$6:$B$405,$A29,'Учёт медосмотров'!$R$6:$R$405,"В срок") -> 0 | D29: =COUNTIFS('Учёт медосмотров'!$B$6:$B$405,$A29,'Учёт медосмотров'!$R$6:$R$405,"Истекает") -> 0 | E29: =COUNTIFS('Учёт медосмотров'!$B$6:$B$405,$A29,'Учёт медосмотров'!$R$6:$R$405,"Просрочен") -> 0 | F29: =COUNTIFS('Учёт медосмотров'!$B$6:$B$405,$A29,'Учёт медосмотров'!$R$6:$R$405,"Нет сведений") -> 1 | G29: =COUNTIFS('Учёт медосмотров'!$B$6:$B$405,$A29,'Учёт медосмотров'!$N$6:$N$405,"Да") -> 0 | H29: =COUNTIFS('Учёт медосмотров'!$B$6:$B$405,$A29,'Учёт медосмотров'!$S$6:$S$405,"Не пройдено") -> 0
A30: Казань | B30: =COUNTIF('Учёт медосмотров'!$B$6:$B$405,$A30) -> 16 | C30: =COUNTIFS('Учёт медосмотров'!$B$6:$B$405,$A30,'Учёт медосмотров'!$R$6:$R$405,"В срок") -> 2 | D30: =COUNTIFS('Учёт медосмотров'!$B$6:$B$405,$A30,'Учёт медосмотров'!$R$6:$R$405,"Истекает") -> 2 | E30: =COUNTIFS('Учёт медосмотров'!$B$6:$B$405,$A30,'Учёт медосмотров'!$R$6:$R$405,"Просрочен") -> 4 | F30: =COUNTIFS('Учёт медосмотров'!$B$6:$B$405,$A30,'Учёт медосмотров'!$R$6:$R$405,"Нет сведений") -> 8 | G30: =COUNTIFS('Учёт медосмотров'!$B$6:$B$405,$A30,'Учёт медосмотров'!$N$6:$N$405,"Да") -> 6 | H30: =COUNTIFS('Учёт медосмотров'!$B$6:$B$405,$A30,'Учёт медосмотров'!$S$6:$S$405,"Не пройдено") -> 6
A31: Машково | B31: =COUNTIF('Учёт медосмотров'!$B$6:$B$405,$A31) -> 178 | C31: =COUNTIFS('Учёт медосмотров'!$B$6:$B$405,$A31,'Учёт медосмотров'!$R$6:$R$405,"В срок") -> 13 | D31: =COUNTIFS('Учёт медосмотров'!$B$6:$B$405,$A31,'Учёт медосмотров'!$R$6:$R$405,"Истекает") -> 0 | E31: =COUNTIFS('Учёт медосмотров'!$B$6:$B$405,$A31,'Учёт медосмотров'!$R$6:$R$405,"Просрочен") -> 6 | F31: =COUNTIFS('Учёт медосмотров'!$B$6:$B$405,$A31,'Учёт медосмотров'!$R$6:$R$405,"Нет сведений") -> 159 | G31: =COUNTIFS('Учёт медосмотров'!$B$6:$B$405,$A31,'Учёт медосмотров'!$N$6:$N$405,"Да") -> 24 | H31: =COUNTIFS('Учёт медосмотров'!$B$6:$B$405,$A31,'Учёт медосмотров'!$S$6:$S$405,"Не пройдено") -> 24
A32: Москва | B32: =COUNTIF('Учёт медосмотров'!$B$6:$B$405,$A32) -> 9 | C32: =COUNTIFS('Учёт медосмотров'!$B$6:$B$405,$A32,'Учёт медосмотров'!$R$6:$R$405,"В срок") -> 0 | D32: =COUNTIFS('Учёт медосмотров'!$B$6:$B$405,$A32,'Учёт медосмотров'!$R$6:$R$405,"Истекает") -> 0 | E32: =COUNTIFS('Учёт медосмотров'!$B$6:$B$405,$A32,'Учёт медосмотров'!$R$6:$R$405,"Просрочен") -> 0 | F32: =COUNTIFS('Учёт медосмотров'!$B$6:$B$405,$A32,'Учёт медосмотров'!$R$6:$R$405,"Нет сведений") -> 9 | G32: =COUNTIFS('Учёт медосмотров'!$B$6:$B$405,$A32,'Учёт медосмотров'!$N$6:$N$405,"Да") -> 1 | H32: =COUNTIFS('Учёт медосмотров'!$B$6:$B$405,$A32,'Учёт медосмотров'!$S$6:$S$405,"Не пройдено") -> 1
A33: Руднево | B33: =COUNTIF('Учёт медосмотров'!$B$6:$B$405,$A33) -> 70 | C33: =COUNTIFS('Учёт медосмотров'!$B$6:$B$405,$A33,'Учёт медосмотров'!$R$6:$R$405,"В срок") -> 17 | D33: =COUNTIFS('Учёт медосмотров'!$B$6:$B$405,$A33,'Учёт медосмотров'!$R$6:$R$405,"Истекает") -> 1 | E33: =COUNTIFS('Учёт медосмотров'!$B$6:$B$405,$A33,'Учёт медосмотров'!$R$6:$R$405,"Просрочен") -> 5 | F33: =COUNTIFS('Учёт медосмотров'!$B$6:$B$405,$A33,'Учёт медосмотров'!$R$6:$R$405,"Нет сведений") -> 47 | G33: =COUNTIFS('Учёт медосмотров'!$B$6:$B$405,$A33,'Учёт медосмотров'!$N$6:$N$405,"Да") -> 4 | H33: =COUNTIFS('Учёт медосмотров'!$B$6:$B$405,$A33,'Учёт медосмотров'!$S$6:$S$405,"Не пройдено") -> 4
A34: Ульяновск | B34: =COUNTIF('Учёт медосмотров'!$B$6:$B$405,$A34) -> 19 | C34: =COUNTIFS('Учёт медосмотров'!$B$6:$B$405,$A34,'Учёт медосмотров'!$R$6:$R$405,"В срок") -> 6 | D34: =COUNTIFS('Учёт медосмотров'!$B$6:$B$405,$A34,'Учёт медосмотров'!$R$6:$R$405,"Истекает") -> 2 | E34: =COUNTIFS('Учёт медосмотров'!$B$6:$B$405,$A34,'Учёт медосмотров'!$R$6:$R$405,"Просрочен") -> 4 | F34: =COUNTIFS('Учёт медосмотров'!$B$6:$B$405,$A34,'Учёт медосмотров'!$R$6:$R$405,"Нет сведений") -> 7 | G34: =COUNTIFS('Учёт медосмотров'!$B$6:$B$405,$A34,'Учёт медосмотров'!$N$6:$N$405,"Да") -> 5 | H34: =COUNTIFS('Учёт медосмотров'!$B$6:$B$405,$A34,'Учёт медосмотров'!$S$6:$S$405,"Не пройдено") -> 5
A35: Итого | B35: =SUM(B27:B34) -> 369 | C35: =SUM(C27:C34) -> 43 | D35: =SUM(D27:D34) -> 5 | E35: =SUM(E27:E34) -> 35 | F35: =SUM(F27:F34) -> 286 | G35: =SUM(G27:G34) -> 59 | H35: =SUM(H27:H34) -> 59
A36: =IF(B35=B7,"","Внимание: итог по площадкам не совпадает с общей численностью — проверьте графу «Площадка».")

Sheet Учёт медосмотров
A1: Учет обязательных медицинских осмотров работников | P1: на дату: | Q1: =TODAY() -> 46314
A2: основание: Приказ №43 от 03.04.2026, Приказ Минздрава России №29н от 28.01.2021, Приказ №342н от 20.05.2022
A4: Работник | H4: Перечень (Приказ №43) | K4: Медицинский осмотр, дата | N4: Психиатрическое освидетельствование | Q4: Контроль
A5: № | B5: Площадка | C5: ФИО работника | D5: Должность (профессия) | E5: Структурное подразделение | F5: Дата приёма | G5: ключ | H5: № по Перечню | I5: Пункты приказа №29н | J5: Период., мес. | K5: Предварительный | L5: Последний периодический | M5: Следующий (план) | N5: Подлежит | O5: Дата прохождения | P5: Контрольная дата | Q5: Осмотр позже приёма | R5: Периодический осмотр | S5: Психиатр. освид.
A6: =IF(C6="","",ROW()-5) -> 1 | B6: Ульяновск | C6: Юдакова Регина Юрьевна | D6: Инженер 3 категории | E6: Отдел технического контроля М | F6: 45874 | G6: =IF(C6="","",IF(TRIM(SUBSTITUTE(SUBSTITUTE(SUBSTITUTE(SUBSTITUTE(SUBSTITUTE(SUBSTITUTE(SUBSTITUTE(SUBSTITUTE(SUBSTITUTE(SUBSTITUTE(SUBSTITUTE(LOWER(TRIM(D6)),"ё","е")," -","-"),"- ","-")," 2 разряда","")," 3 разряда","")," 4 разряда","")," 5 разряда","")," 6 разряда","")," 1 категории","")," 2 категории","")," 3 категории",""))="инженер",IF(AND(ISNUMBER(SEARCH("техническ",E6)),ISNUMBER(SEARCH("контрол",E6))),"инженер отк",IF(ISNUMBER(SEARCH("диспетч",E6)),"инженер пдо",TRIM(SUBSTITUTE(SUBSTITUTE(SUBSTITUTE(SUBSTITUTE(SUBSTITUTE(SUBSTITUTE(SUBSTITUTE(SUBSTITUTE(SUBSTITUTE(SUBSTITUTE(SUBSTITUTE(LOWER(TRIM(D6)),"ё","е")," -","-"),"- ","-")," 2 разряда","")," 3 разряда","")," 4 разряда","")," 5 разряда","")," 6 разряда","")," 1 категории","")," 2 категории","")," 3 категории","")))),IF(TRIM(SUBSTITUTE(SUBSTITUTE(SUBSTITUTE(SUBSTITUTE(SUBSTITUTE(SUBSTITUTE(SUBSTITUTE(SUBSTITUTE(SUBSTITUTE(SUBSTITUTE(SUBSTITUTE(LOWER(TRIM(D6)),"ё","е")," -","-"),"- ","-")," 2 разряда","")," 3 разряда","")," 4 разряда","")," 5 разряда","")," 6 разряда","")," 1 категории","")," 2 категории","")," 3 категории",""))="ведущий инженер",IF(ISNUMBER(SEARCH("диспетч",E6)),"ведущий инженер пдо",TRIM(SUBSTITUTE(SUBSTITUTE(SUBSTITUTE(SUBSTITUTE(SUBSTITUTE(SUBSTITUTE(SUBSTITUTE(SUBSTITUTE(SUBSTITUTE(SUBSTITUTE(SUBSTITUTE(LOWER(TRIM(D6)),"ё","е")," -","-"),"- ","-")," 2 разряда","")," 3 разряда","")," 4 разряда","")," 5 разряда","")," 6 разряда","")," 1 категории","")," 2 категории","")," 3 категории",""))),IF(TRIM(SUBSTITUTE(SUBSTITUTE(SUBSTITUTE(SUBSTITUTE(SUBSTITUTE(SUBSTITUTE(SUBSTITUTE(SUBSTITUTE(SUBSTITUTE(SUBSTITUTE(SUBSTITUTE(LOWER(TRIM(D6)),"ё","е")," -","-"),"- ","-")," 2 разряда","")," 3 разряда","")," 4 разряда","")," 5 разряда","")," 6 разряда","")," 1 категории","")," 2 категории","")," 3 категории",""))="контролер","контролер отк",TRIM(SUBSTITUTE(SUBSTITUTE(SUBSTITUTE(SUBSTITUTE(SUBSTITUTE(SUBSTITUTE(SUBSTITUTE(SUBSTITUTE(SUBSTITUTE(SUBSTITUTE(SUBSTITUTE(LOWER(TRIM(D6)),"ё","е")," -","-"),"- ","-")," 2 разряда","")," 3 разряда","")," 4 разряда","")," 5 разряда","")," 6 разряда","")," 1 категории","")," 2 категории","")," 3 категории","")))))) -> инженер отк | H6: =IF(C6="","",IF(AND(G6="мастер участка",ISNUMBER(SEARCH("РЭО",E6))),29,IFERROR(INDEX(Соответствие!$B$2:$B$100,MATCH(G6,Соответствие!$A$2:$A$100,0)),"?"))) -> 13 | I6: =IF(C6="","",IFERROR(INDEX(Перечень!$C$6:$C$52,MATCH(H6,Перечень!$A$6:$A$52,0)),"")) -> п.4.4, п.5.2 | J6: =IF(C6="","",IFERROR(INDEX(Перечень!$D$6:$D$52,MATCH(H6,Перечень!$A$6:$A$52,0)),12)) -> 12 | M6: =IF(AND(K6="",L6=""),"",EDATE(MAX(K6,L6),J6)) | N6: =IF(C6="","",IFERROR(INDEX(Перечень!$F$6:$F$52,MATCH(H6,Перечень!$A$6:$A$52,0)),"")) -> - | P6: =IF(O6="","",EDATE(O6,60)) | Q6: =IF(AND(K6<>"",F6<>"",K6>F6),"Да","") | R6: =IF(C6="","",IF(M6="","Нет сведений",IF(M6<TODAY(),"Просрочен",IF(M6-TODAY()<=30,"Истекает","В срок")))) -> Нет сведений | S6: =IF(AND(N6="Да",O6=""),"Не пройдено","")
A7: =IF(C7="","",ROW()-5) -> 2 | B7: Казань | C7: Петрунина Людмила Александровна | D7: Инженер 1 категории | E7: Отдел технического контроля М | F7: 45870 | G7: =IF(C7="","",IF(TRIM(SUBSTITUTE(SUBSTITUTE(SUBSTITUTE(SUBSTITUTE(SUBSTITUTE(SUBSTITUTE(SUBSTITUTE(SUBSTITUTE(SUBSTITUTE(SUBSTITUTE(SUBSTITUTE(LOWER(TRIM(D7)),"ё","е")," -","-"),"- ","-")," 2 разряда","")," 3 разряда","")," 4 разряда","")," 5 разряда","")," 6 разряда","")," 1 категории","")," 2 категории","")," 3 категории",""))="инженер",IF(AND(ISNUMBER(SEARCH("техническ",E7)),ISNUMBER(SEARCH("контрол",E7))),"инженер отк",IF(ISNUMBER(SEARCH("диспетч",E7)),"инженер пдо",TRIM(SUBSTITUTE(SUBSTITUTE(SUBSTITUTE(SUBSTITUTE(SUBSTITUTE(SUBSTITUTE(SUBSTITUTE(SUBSTITUTE(SUBSTITUTE(SUBSTITUTE(SUBSTITUTE(LOWER(TRIM(D7)),"ё","е")," -","-"),"- ","-")," 2 разряда","")," 3 разряда","")," 4 разряда","")," 5 разряда","")," 6 разряда","")," 1 категории","")," 2 категории","")," 3 категории","")))),IF(TRIM(SUBSTITUTE(SUBSTITUTE(SUBSTITUTE(SUBSTITUTE(SUBSTITUTE(SUBSTITUTE(SUBSTITUTE(SUBSTITUTE(SUBSTITUTE(SUBSTITUTE(SUBSTITUTE(LOWER(TRIM(D7)),"ё","е")," -","-"),"- ","-")," 2 разряда","")," 3 разряда","")," 4 разряда","")," 5 разряда","")," 6 разряда","")," 1 категории","")," 2 категории","")," 3 категории",""))="ведущий инженер",IF(ISNUMBER(SEARCH("диспетч",E7)),"ведущий инженер пдо",TRIM(SUBSTITUTE(SUBSTITUTE(SUBSTITUTE(SUBSTITUTE(SUBSTITUTE(SUBSTITUTE(SUBSTITUTE(SUBSTITUTE(SUBSTITUTE(SUBSTITUTE(SUBSTITUTE(LOWER(TRIM(D7)),"ё","е")," -","-"),"- ","-")," 2 разряда","")," 3 разряда","")," 4 разряда","")," 5 разряда","")," 6 разряда","")," 1 категории","")," 2 категории","")," 3 категории",""))),IF(TRIM(SUBSTITUTE(SUBSTITUTE(SUBSTITUTE(SUBSTITUTE(SUBSTITUTE(SUBSTITUTE(SUBSTITUTE(SUBSTITUTE(SUBSTITUTE(SUBSTITUTE(SUBSTITUTE(LOWER(TRIM(D7)),"ё","е")," -","-"),"- ","-")," 2 разряда","")," 3 разряда","")," 4 разряда","")," 5 разряда","")," 6 разряда","")," 1 категории","")," 2 категории","")," 3 категории",""))="контролер","контролер отк",TRIM(SUBSTITUTE(SUBSTITUTE(SUBSTITUTE(SUBSTITUTE(SUBSTITUTE(SUBSTITUTE(SUBSTITUTE(SUBSTITUTE(SUBSTITUTE(SUBSTITUTE(SUBSTITUTE(LOWER(TRIM(D7)),"ё","е")," -","-"),"- ","-")," 2 разряда","")," 3 разряда","")," 4 разряда","")," 5 разряда","")," 6 разряда","")," 1 категории","")," 2 категории","")," 3 категории","")))))) -> инженер отк | H7: =IF(C7="","",IF(AND(G7="мастер участка",ISNUMBER(SEARCH("РЭО",E7))),29,IFERROR(INDEX(Соответствие!$B$2:$B$100,MATCH(G7,Соответствие!$A$2:$A$100,0)),"?"))) -> 13 | I7: =IF(C7="","",IFERROR(INDEX(Перечень!$C$6:$C$52,MATCH(H7,Перечень!$A$6:$A$52,0)),"")) -> п.4.4, п.5.2 | J7: =IF(C7="","",IFERROR(INDEX(Перечень!$D$6:$D$52,MATCH(H7,Перечень!$A$6:$A$52,0)),12)) -> 12 | M7: =IF(AND(K7="",L7=""),"",EDATE(MAX(K7,L7),J7)) | N7: =IF(C7="","",IFERROR(INDEX(Перечень!$F$6:$F$52,MATCH(H7,Перечень!$A$6:$A$52,0)),"")) -> - | P7: =IF(O7="","",EDATE(O7,60)) | Q7: =IF(AND(K7<>"",F7<>"",K7>F7),"Да","") | R7: =IF(C7="","",IF(M7="","Нет сведений",IF(M7<TODAY(),"Просрочен",IF(M7-TODAY()<=30,"Истекает","В срок")))) -> Нет сведений | S7: =IF(AND(N7="Да",O7=""),"Не пройдено","")
A8: =IF(C8="","",ROW()-5) -> 3 | B8: Машково | C8: Ястребов Александр Сергеевич | D8: Инженер 1 категории | E8: Отдел технического контроля | F8: 38664 | G8: =IF(C8="","",IF(TRIM(SUBSTITUTE(SUBSTITUTE(SUBSTITUTE(SUBSTITUTE(SUBSTITUTE(SUBSTITUTE(SUBSTITUTE(SUBSTITUTE(SUBSTITUTE(SUBSTITUTE(SUBSTITUTE(LOWER(TRIM(D8)),"ё","е")," -","-"),"- ","-")," 2 разряда","")," 3 разряда","")," 4 разряда","")," 5 разряда","")," 6 разряда","")," 1 категории","")," 2 категории","")," 3 категории",""))="инженер",IF(AND(ISNUMBER(SEARCH("техническ",E8)),ISNUMBER(SEARCH("контрол",E8))),"инженер отк",IF(ISNUMBER(SEARCH("диспетч",E8)),"инженер пдо",TRIM(SUBSTITUTE(SUBSTITUTE(SUBSTITUTE(SUBSTITUTE(SUBSTITUTE(SUBSTITUTE(SUBSTITUTE(SUBSTITUTE(SUBSTITUTE(SUBSTITUTE(SUBSTITUTE(LOWER(TRIM(D8)),"ё","е")," -","-"),"- ","-")," 2 разряда","")," 3 разряда","")," 4 разряда","")," 5 разряда","")," 6 разряда","")," 1 категории","")," 2 категории","")," 3 категории","")))),IF(TRIM(SUBSTITUTE(SUBSTITUTE(SUBSTITUTE(SUBSTITUTE(SUBSTITUTE(SUBSTITUTE(SUBSTITUTE(SUBSTITUTE(SUBSTITUTE(SUBSTITUTE(SUBSTITUTE(LOWER(TRIM(D8)),"ё","е")," -","-"),"- ","-")," 2 разряда","")," 3 разряда","")," 4 разряда","")," 5 разряда","")," 6 разряда","")," 1 категории","")," 2 категории","")," 3 категории",""))="ведущий инженер",IF(ISNUMBER(SEARCH("диспетч",E8)),"ведущий инженер пдо",TRIM(SUBSTITUTE(SUBSTITUTE(SUBSTITUTE(SUBSTITUTE(SUBSTITUTE(SUBSTITUTE(SUBSTITUTE(SUBSTITUTE(SUBSTITUTE(SUBSTITUTE(SUBSTITUTE(LOWER(TRIM(D8)),"ё","е")," -","-"),"- ","-")," 2 разряда","")," 3 разряда","")," 4 разряда","")," 5 разряда","")," 6 разряда","")," 1 категории","")," 2 категории","")," 3 категории",""))),IF(TRIM(SUBSTITUTE(SUBSTITUTE(SUBSTITUTE(SUBSTITUTE(SUBSTITUTE(SUBSTITUTE(SUBSTITUTE(SUBSTITUTE(SUBSTITUTE(SUBSTITUTE(SUBSTITUTE(LOWER(TRIM(D8)),"ё","е")," -","-"),"- ","-")," 2 разряда","")," 3 разряда","")," 4 разряда","")," 5 разряда","")," 6 разряда","")," 1 категории","")," 2 категории","")," 3 категории",""))="контролер","контролер отк",TRIM(SUBSTITUTE(SUBSTITUTE(SUBSTITUTE(SUBSTITUTE(SUBSTITUTE(SUBSTITUTE(SUBSTITUTE(SUBSTITUTE(SUBSTITUTE(SUBSTITUTE(SUBSTITUTE(LOWER(TRIM(D8)),"ё","е")," -","-"),"- ","-")," 2 разряда","")," 3 разряда","")," 4 разряда","")," 5 разряда","")," 6 разряда","")," 1 категории","")," 2 категории","")," 3 категории","")))))) -> инженер отк | H8: =IF(C8="","",IF(AND(G8="мастер участка",ISNUMBER(SEARCH("РЭО",E8))),29,IFERROR(INDEX(Соответствие!$B$2:$B$100,MATCH(G8,Соответствие!$A$2:$A$100,0)),"?"))) -> 13 | I8: =IF(C8="","",IFERROR(INDEX(Перечень!$C$6:$C$52,MATCH(H8,Перечень!$A$6:$A$52,0)),"")) -> п.4.4, п.5.2 | J8: =IF(C8="","",IFERROR(INDEX(Перечень!$D$6:$D$52,MATCH(H8,Перечень!$A$6:$A$52,0)),12)) -> 12 | M8: =IF(AND(K8="",L8=""),"",EDATE(MAX(K8,L8),J8)) | N8: =IF(C8="","",IFERROR(INDEX(Перечень!$F$6:$F$52,MATCH(H8,Перечень!$A$6:$A$52,0)),"")) -> - | P8: =IF(O8="","",EDATE(O8,60)) | Q8: =IF(AND(K8<>"",F8<>"",K8>F8),"Да","") | R8: =IF(C8="","",IF(M8="","Нет сведений",IF(M8<TODAY(),"Просрочен",IF(M8-TODAY()<=30,"Истекает","В срок")))) -> Нет сведений | S8: =IF(AND(N8="Да",O8=""),"Не пройдено","")
A9: =IF(C9="","",ROW()-5) -> 4 | B9: Москва | C9: Гудумак Анастасия Сергеевна | D9: Инженер 2 категории | E9: Отдел технического контроля М | F9: 44970 | G9: =IF(C9="","",IF(TRIM(SUBSTITUTE(SUBSTITUTE(SUBSTITUTE(SUBSTITUTE(SUBSTITUTE(SUBSTITUTE(SUBSTITUTE(SUBSTITUTE(SUBSTITUTE(SUBSTITUTE(SUBSTITUTE(LOWER(TRIM(D9)),"ё","е")," -","-"),"- ","-")," 2 разряда","")," 3 разряда","")," 4 разряда","")," 5 разряда","")," 6 разряда","")," 1 категории","")," 2 категории","")," 3 категории",""))="инженер",IF(AND(ISNUMBER(SEARCH("техническ",E9)),ISNUMBER(SEARCH("контрол",E9))),"инженер отк",IF(ISNUMBER(SEARCH("диспетч",E9)),"инженер пдо",TRIM(SUBSTITUTE(SUBSTITUTE(SUBSTITUTE(SUBSTITUTE(SUBSTITUTE(SUBSTITUTE(SUBSTITUTE(SUBSTITUTE(SUBSTITUTE(SUBSTITUTE(SUBSTITUTE(LOWER(TRIM(D9)),"ё","е")," -","-"),"- ","-")," 2 разряда","")," 3 разряда","")," 4 разряда","")," 5 разряда","")," 6 разряда","")," 1 категории","")," 2 категории","")," 3 категории","")))),IF(TRIM(SUBSTITUTE(SUBSTITUTE(SUBSTITUTE(SUBSTITUTE(SUBSTITUTE(SUBSTITUTE(SUBSTITUTE(SUBSTITUTE(SUBSTITUTE(SUBSTITUTE(SUBSTITUTE(LOWER(TRIM(D9)),"ё","е")," -","-"),"- ","-")," 2 разряда","")," 3 разряда","")," 4 разряда","")," 5 разряда","")," 6 разряда","")," 1 категории","")," 2 категории","")," 3 категории",""))="ведущий инженер",IF(ISNUMBER(SEARCH("диспетч",E9)),"ведущий инженер пдо",TRIM(SUBSTITUTE(SUBSTITUTE(SUBSTITUTE(SUBSTITUTE(SUBSTITUTE(SUBSTITUTE(SUBSTITUTE(SUBSTITUTE(SUBSTITUTE(SUBSTITUTE(SUBSTITUTE(LOWER(TRIM(D9)),"ё","е")," -","-"),"- ","-")," 2 разряда","")," 3 разряда","")," 4 разряда","")," 5 разряда","")," 6 разряда","")," 1 категории","")," 2 категории","")," 3 категории",""))),IF(TRIM(SUBSTITUTE(SUBSTITUTE(SUBSTITUTE(SUBSTITUTE(SUBSTITUTE(SUBSTITUTE(SUBSTITUTE(SUBSTITUTE(SUBSTITUTE(SUBSTITUTE(SUBSTITUTE(LOWER(TRIM(D9)),"ё","е")," -","-"),"- ","-")," 2 разряда","")," 3 разряда","")," 4 разряда","")," 5 разряда","")," 6 разряда","")," 1 категории","")," 2 категории","")," 3 категории",""))="контролер","контролер отк",TRIM(SUBSTITUTE(SUBSTITUTE(SUBSTITUTE(SUBSTITUTE(SUBSTITUTE(SUBSTITUTE(SUBSTITUTE(SUBSTITUTE(SUBSTITUTE(SUBSTITUTE(SUBSTITUTE(LOWER(TRIM(D9)),"ё","е")," -","-"),"- ","-")," 2 разряда","")," 3 разряда","")," 4 разряда","")," 5 разряда","")," 6 разряда","")," 1 категории","")," 2 категории","")," 3 категории","")))))) -> инженер отк | H9: =IF(C9="","",IF(AND(G9="мастер участка",ISNUMBER(SEARCH("РЭО",E9))),29,IFERROR(INDEX(Соответствие!$B$2:$B$100,MATCH(G9,Соответствие!$A$2:$A$100,0)),"?"))) -> 13 | I9: =IF(C9="","",IFERROR(INDEX(Перечень!$C$6:$C$52,MATCH(H9,Перечень!$A$6:$A$52,0)),"")) -> п.4.4, п.5.2 | J9: =IF(C9="","",IFERROR(INDEX(Перечень!$D$6:$D$52,MATCH(H9,Перечень!$A$6:$A$52,0)),12)) -> 12 | M9: =IF(AND(K9="",L9=""),"",EDATE(MAX(K9,L9),J9)) | N9: =IF(C9="","",IFERROR(INDEX(Перечень!$F$6:$F$52,MATCH(H9,Перечень!$A$6:$A$52,0)),"")) -> - | P9: =IF(O9="","",EDATE(O9,60)) | Q9: =IF(AND(K9<>"",F9<>"",K9>F9),"Да","") | R9: =IF(C9="","",IF(M9="","Нет сведений",IF(M9<TODAY(),"Просрочен",IF(M9-TODAY()<=30,"Истекает","В срок")))) -> Нет сведений | S9: =IF(AND(N9="Да",O9=""),"Не пройдено","")
A10: =IF(C10="","",ROW()-5) -> 5 | B10: Машково | C10: Ермакова Наталья Васильевна | D10: Контролер 1 категории | E10: Отдел технического контроля | F10: 45720 | G10: =IF(C10="","",IF(TRIM(SUBSTITUTE(SUBSTITUTE(SUBSTITUTE(SUBSTITUTE(SUBSTITUTE(SUBSTITUTE(SUBSTITUTE(SUBSTITUTE(SUBSTITUTE(SUBSTITUTE(SUBSTITUTE(LOWER(TRIM(D10)),"ё","е")," -","-"),"- ","-")," 2 разряда","")," 3 разряда","")," 4 разряда","")," 5 разряда","")," 6 разряда","")," 1 категории","")," 2 категории","")," 3 категории",""))="инженер",IF(AND(ISNUMBER(SEARCH("техническ",E10)),ISNUMBER(SEARCH("контрол",E10))),"инженер отк",IF(ISNUMBER(SEARCH("диспетч",E10)),"инженер пдо",TRIM(SUBSTITUTE(SUBSTITUTE(SUBSTITUTE(SUBSTITUTE(SUBSTITUTE(SUBSTITUTE(SUBSTITUTE(SUBSTITUTE(SUBSTITUTE(SUBSTITUTE(SUBSTITUTE(LOWER(TRIM(D10)),"ё","е")," -","-"),"- ","-")," 2 разряда","")," 3 разряда","")," 4 разряда","")," 5 разряда","")," 6 разряда","")," 1 категории","")," 2 категории","")," 3 категории","")))),IF(TRIM(SUBSTITUTE(SUBSTITUTE(SUBSTITUTE(SUBSTITUTE(SUBSTITUTE(SUBSTITUTE(SUBSTITUTE(SUBSTITUTE(SUBSTITUTE(SUBSTITUTE(SUBSTITUTE(LOWER(TRIM(D10)),"ё","е")," -","-"),"- ","-")," 2 разряда","")," 3 разряда","")," 4 разряда","")," 5 разряда","")," 6 разряда","")," 1 категории","")," 2 категории","")," 3 категории",""))="ведущий инженер",IF(ISNUMBER(SEARCH("диспетч",E10)),"ведущий инженер пдо",TRIM(SUBSTITUTE(SUBSTITUTE(SUBSTITUTE(SUBSTITUTE(SUBSTITUTE(SUBSTITUTE(SUBSTITUTE(SUBSTITUTE(SUBSTITUTE(SUBSTITUTE(SUBSTITUTE(LOWER(TRIM(D10)),"ё","е")," -","-"),"- ","-")," 2 разряда","")," 3 разряда","")," 4 разряда","")," 5 разряда","")," 6 разряда","")," 1 категории","")," 2 категории","")," 3 категории",""))),IF(TRIM(SUBSTITUTE(SUBSTITUTE(SUBSTITUTE(SUBSTITUTE(SUBSTITUTE(SUBSTITUTE(SUBSTITUTE(SUBSTITUTE(SUBSTITUTE(SUBSTITUTE(SUBSTITUTE(LOWER(TRIM(D10)),"ё","е")," -","-"),"- ","-")," 2 разряда","")," 3 разряда","")," 4 разряда","")," 5 разряда","")," 6 разряда","")," 1 категории","")," 2 категории","")," 3 категории",""))="контролер","контролер отк",TRIM(SUBSTITUTE(SUBSTITUTE(SUBSTITUTE(SUBSTITUTE(SUBSTITUTE(SUBSTITUTE(SUBSTITUTE(SUBSTITUTE(SUBSTITUTE(SUBSTITUTE(SUBSTITUTE(LOWER(TRIM(D10)),"ё","е")," -","-"),"- ","-")," 2 разряда","")," 3 разряда","")," 4 разряда","")," 5 разряда","")," 6 разряда","")," 1 категории","")," 2 категории","")," 3 категории","")))))) -> контролер отк | H10: =IF(C10="","",IF(AND(G10="мастер участка",ISNUMBER(SEARCH("РЭО",E10))),29,IFERROR(INDEX(Соответствие!$B$2:$B$100,MATCH(G10,Соответствие!$A$2:$A$100,0)),"?"))) -> 13 | I10: =IF(C10="","",IFERROR(INDEX(Перечень!$C$6:$C$52,MATCH(H10,Перечень!$A$6:$A$52,0)),"")) -> п.4.4, п.5.2 | J10: =IF(C10="","",IFERROR(INDEX(Перечень!$D$6:$D$52,MATCH(H10,Перечень!$A$6:$A$52,0)),12)) -> 12 | M10: =IF(AND(K10="",L10=""),"",EDATE(MAX(K10,L10),J10)) | N10: =IF(C10="","",IFERROR(INDEX(Перечень!$F$6:$F$52,MATCH(H10,Перечень!$A$6:$A$52,0)),"")) -> - | P10: =IF(O10="","",EDATE(O10,60)) | Q10: =IF(AND(K10<>"",F10<>"",K10>F10),"Да","") | R10: =IF(C10="","",IF(M10="","Нет сведений",IF(M10<TODAY(),"Просрочен",IF(M10-TODAY()<=30,"Истекает","В срок")))) -> Нет сведений | S10: =IF(AND(N10="Да",O10=""),"Не пройдено","")
A11: =IF(C11="","",ROW()-5) -> 6 | B11: Машково | C11: Шрамко Наталья Викторовна | D11: Контролер 1 категории | E11: Отдел технического контроля | F11: 45908 | G11: =IF(C11="","",IF(TRIM(SUBSTITUTE(SUBSTITUTE(SUBSTITUTE(SUBSTITUTE(SUBSTITUTE(SUBSTITUTE(SUBSTITUTE(SUBSTITUTE(SUBSTITUTE(SUBSTITUTE(SUBSTITUTE(LOWER(TRIM(D11)),"ё","е")," -","-"),"- ","-")," 2 разряда","")," 3 разряда","")," 4 разряда","")," 5 разряда","")," 6 разряда","")," 1 категории","")," 2 категории","")," 3 категории",""))="инженер",IF(AND(ISNUMBER(SEARCH("техническ",E11)),ISNUMBER(SEARCH("контрол",E11))),"инженер отк",IF(ISNUMBER(SEARCH("диспетч",E11)),"инженер пдо",TRIM(SUBSTITUTE(SUBSTITUTE(SUBSTITUTE(SUBSTITUTE(SUBSTITUTE(SUBSTITUTE(SUBSTITUTE(SUBSTITUTE(SUBSTITUTE(SUBSTITUTE(SUBSTITUTE(LOWER(TRIM(D11)),"ё","е")," -","-"),"- ","-")," 2 разряда","")," 3 разряда","")," 4 разряда","")," 5 разряда","")," 6 разряда","")," 1 категории","")," 2 категории","")," 3 категории","")))),IF(TRIM(SUBSTITUTE(SUBSTITUTE(SUBSTITUTE(SUBSTITUTE(SUBSTITUTE(SUBSTITUTE(SUBSTITUTE(SUBSTITUTE(SUBSTITUTE(SUBSTITUTE(SUBSTITUTE(LOWER(TRIM(D11)),"ё","е")," -","-"),"- ","-")," 2 разряда","")," 3 разряда","")," 4 разряда","")," 5 разряда","")," 6 разряда","")," 1 категории","")," 2 категории","")," 3 категории",""))="ведущий инженер",IF(ISNUMBER(SEARCH("диспетч",E11)),"ведущий инженер пдо",TRIM(SUBSTITUTE(SUBSTITUTE(SUBSTITUTE(SUBSTITUTE(SUBSTITUTE(SUBSTITUTE(SUBSTITUTE(SUBSTITUTE(SUBSTITUTE(SUBSTITUTE(SUBSTITUTE(LOWER(TRIM(D11)),"ё","е")," -","-"),"- ","-")," 2 разряда","")," 3 разряда","")," 4 разряда","")," 5 разряда","")," 6 разряда","")," 1 категории","")," 2 категории","")," 3 категории",""))),IF(TRIM(SUBSTITUTE(SUBSTITUTE(SUBSTITUTE(SUBSTITUTE(SUBSTITUTE(SUBSTITUTE(SUBSTITUTE(SUBSTITUTE(SUBSTITUTE(SUBSTITUTE(SUBSTITUTE(LOWER(TRIM(D11)),"ё","е")," -","-"),"- ","-")," 2 разряда","")," 3 разряда","")," 4 разряда","")," 5 разряда","")," 6 разряда","")," 1 категории","")," 2 категории","")," 3 категории",""))="контролер","контролер отк",TRIM(SUBSTITUTE(SUBSTITUTE(SUBSTITUTE(SUBSTITUTE(SUBSTITUTE(SUBSTITUTE(SUBSTITUTE(SUBSTITUTE(SUBSTITUTE(SUBSTITUTE(SUBSTITUTE(LOWER(TRIM(D11)),"ё","е")," -","-"),"- ","-")," 2 разряда","")," 3 разряда","")," 4 разряда","")," 5 разряда","")," 6 разряда","")," 1 категории","")," 2 категории","")," 3 категории","")))))) -> контролер отк | H11: =IF(C11="","",IF(AND(G11="мастер участка",ISNUMBER(SEARCH("РЭО",E11))),29,IFERROR(INDEX(Соответствие!$B$2:$B$100,MATCH(G11,Соответствие!$A$2:$A$100,0)),"?"))) -> 13 | I11: =IF(C11="","",IFERROR(INDEX(Перечень!$C$6:$C$52,MATCH(H11,Перечень!$A$6:$A$52,0)),"")) -> п.4.4, п.5.2 | J11: =IF(C11="","",IFERROR(INDEX(Перечень!$D$6:$D$52,MATCH(H11,Перечень!$A$6:$A$52,0)),12)) -> 12 | M11: =IF(AND(K11="",L11=""),"",EDATE(MAX(K11,L11),J11)) | N11: =IF(C11="","",IFERROR(INDEX(Перечень!$F$6:$F$52,MATCH(H11,Перечень!$A$6:$A$52,0)),"")) -> - | P11: =IF(O11="","",EDATE(O11,60)) | Q11: =IF(AND(K11<>"",F11<>"",K11>F11),"Да","") | R11: =IF(C11="","",IF(M11="","Нет сведений",IF(M11<TODAY(),"Просрочен",IF(M11-TODAY()<=30,"Истекает","В срок")))) -> Нет сведений | S11: =IF(AND(N11="Да",O11=""),"Не пройдено","")
A12: =IF(C12="","",ROW()-5) -> 7 | B12: Москва | C12: Высокий Владимир Евгеньевич | D12: Водитель автомобиля (персональный 2 категории) | E12: Отдел транспортного обеспечения (М н/д) | F12: 41365 | G12: =IF(C12="","",IF(TRIM(SUBSTITUTE(SUBSTITUTE(SUBSTITUTE(SUBSTITUTE(SUBSTITUTE(SUBSTITUTE(SUBSTITUTE(SUBSTITUTE(SUBSTITUTE(SUBSTITUTE(SUBSTITUTE(LOWER(TRIM(D12)),"ё","е")," -","-"),"- ","-")," 2 разряда","")," 3 разряда","")," 4 разряда","")," 5 разряда","")," 6 разряда","")," 1 категории","")," 2 категории","")," 3 категории",""))="инженер",IF(AND(ISNUMBER(SEARCH("техническ",E12)),ISNUMBER(SEARCH("контрол",E12))),"инженер отк",IF(ISNUMBER(SEARCH("диспетч",E12)),"инженер пдо",TRIM(SUBSTITUTE(SUBSTITUTE(SUBSTITUTE(SUBSTITUTE(SUBSTITUTE(SUBSTITUTE(SUBSTITUTE(SUBSTITUTE(SUBSTITUTE(SUBSTITUTE(SUBSTITUTE(LOWER(TRIM(D12)),"ё","е")," -","-"),"- ","-")," 2 разряда","")," 3 разряда","")," 4 разряда","")," 5 разряда","")," 6 разряда","")," 1 категории","")," 2 категории","")," 3 категории","")))),IF(TRIM(SUBSTITUTE(SUBSTITUTE(SUBSTITUTE(SUBSTITUTE(SUBSTITUTE(SUBSTITUTE(SUBSTITUTE(SUBSTITUTE(SUBSTITUTE(SUBSTITUTE(SUBSTITUTE(LOWER(TRIM(D12)),"ё","е")," -","-"),"- ","-")," 2 разряда","")," 3 разряда","")," 4 разряда","")," 5 разряда","")," 6 разряда","")," 1 категории","")," 2 категории","")," 3 категории",""))="ведущий инженер",IF(ISNUMBER(SEARCH("диспетч",E12)),"ведущий инженер пдо",TRIM(SUBSTITUTE(SUBSTITUTE(SUBSTITUTE(SUBSTITUTE(SUBSTITUTE(SUBSTITUTE(SUBSTITUTE(SUBSTITUTE(SUBSTITUTE(SUBSTITUTE(SUBSTITUTE(LOWER(TRIM(D12)),"ё","е")," -","-"),"- ","-")," 2 разряда","")," 3 разряда","")," 4 разряда","")," 5 разряда","")," 6 разряда","")," 1 категории","")," 2 категории","")," 3 категории",""))),IF(TRIM(SUBSTITUTE(SUBSTITUTE(SUBSTITUTE(SUBSTITUTE(SUBSTITUTE(SUBSTITUTE(SUBSTITUTE(SUBSTITUTE(SUBSTITUTE(SUBSTITUTE(SUBSTITUTE(LOWER(TRIM(D12)),"ё","е")," -","-"),"- ","-")," 2 разряда","")," 3 разряда","")," 4 разряда","")," 5 разряда","")," 6 разряда","")," 1 категории","")," 2 категории","")," 3 категории",""))="контролер","контролер отк",TRIM(SUBSTITUTE(SUBSTITUTE(SUBSTITUTE(SUBSTITUTE(SUBSTITUTE(SUBSTITUTE(SUBSTITUTE(SUBSTITUTE(SUBSTITUTE(SUBSTITUTE(SUBSTITUTE(LOWER(TRIM(D12)),"ё","е")," -","-"),"- ","-")," 2 разряда","")," 3 разряда","")," 4 разряда","")," 5 разряда","")," 6 разряда","")," 1 категории","")," 2 категории","")," 3 категории","")))))) -> водитель автомобиля (персональный) | H12: =IF(C12="","",IF(AND(G12="мастер участка",ISNUMBER(SEARCH("РЭО",E12))),29,IFERROR(INDEX(Соответствие!$B$2:$B$100,MATCH(G12,Соответствие!$A$2:$A$100,0)),"?"))) -> 39 | I12: =IF(C12="","",IFERROR(INDEX(Перечень!$C$6:$C$52,MATCH(H12,Перечень!$A$6:$A$52,0)),"")) -> п.4.3.1, п.4.3.2, п.4.4, п.5.1, п.5.2, п.18.1 | J12: =IF(C12="","",IFERROR(INDEX(Перечень!$D$6:$D$52,MATCH(H12,Перечень!$A$6:$A$52,0)),12)) -> 12 | M12: =IF(AND(K12="",L12=""),"",EDATE(MAX(K12,L12),J12)) | N12: =IF(C12="","",IFERROR(INDEX(Перечень!$F$6:$F$52,MATCH(H12,Перечень!$A$6:$A$52,0)),"")) -> Да | P12: =IF(O12="","",EDATE(O12,60)) | Q12: =IF(AND(K12<>"",F12<>"",K12>F12),"Да","") | R12: =IF(C12="","",IF(M12="","Нет сведений",IF(M12<TODAY(),"Просрочен",IF(M12-TODAY()<=30,"Истекает","В срок")))) -> Нет сведений | S12: =IF(AND(N12="Да",O12=""),"Не пройдено","") -> Не пройдено
A13: =IF(C13="","",ROW()-5) -> 8 | B13: Москва | C13: Киреева Вера Антоновна | D13: Старший технический работник | E13: Административно-хозяйственный отдел М | F13: 43283 | G13: =IF(C13="","",IF(TRIM(SUBSTITUTE(SUBSTITUTE(SUBSTITUTE(SUBSTITUTE(SUBSTITUTE(SUBSTITUTE(SUBSTITUTE(SUBSTITUTE(SUBSTITUTE(SUBSTITUTE(SUBSTITUTE(LOWER(TRIM(D13)),"ё","е")," -","-"),"- ","-")," 2 разряда","")," 3 разряда","")," 4 разряда","")," 5 разряда","")," 6 разряда","")," 1 категории","")," 2 категории","")," 3 категории",""))="инженер",IF(AND(ISNUMBER(SEARCH("техническ",E13)),ISNUMBER(SEARCH("контрол",E13))),"инженер отк",IF(ISNUMBER(SEARCH("диспетч",E13)),"инженер пдо",TRIM(SUBSTITUTE(SUBSTITUTE(SUBSTITUTE(SUBSTITUTE(SUBSTITUTE(SUBSTITUTE(SUBSTITUTE(SUBSTITUTE(SUBSTITUTE(SUBSTITUTE(SUBSTITUTE(LOWER(TRIM(D13)),"ё","е")," -","-"),"- ","-")," 2 разряда","")," 3 разряда","")," 4 разряда","")," 5 разряда","")," 6 разряда","")," 1 категории","")," 2 категории","")," 3 категории","")))),IF(TRIM(SUBSTITUTE(SUBSTITUTE(SUBSTITUTE(SUBSTITUTE(SUBSTITUTE(SUBSTITUTE(SUBSTITUTE(SUBSTITUTE(SUBSTITUTE(SUBSTITUTE(SUBSTITUTE(LOWER(TRIM(D13)),"ё","е")," -","-"),"- ","-")," 2 разряда","")," 3 разряда","")," 4 разряда","")," 5 разряда","")," 6 разряда","")," 1 категории","")," 2 категории","")," 3 категории",""))="ведущий инженер",IF(ISNUMBER(SEARCH("диспетч",E13)),"ведущий инженер пдо",TRIM(SUBSTITUTE(SUBSTITUTE(SUBSTITUTE(SUBSTITUTE(SUBSTITUTE(SUBSTITUTE(SUBSTITUTE(SUBSTITUTE(SUBSTITUTE(SUBSTITUTE(SUBSTITUTE(LOWER(TRIM(D13)),"ё","е")," -","-"),"- ","-")," 2 разряда","")," 3 разряда","")," 4 разряда","")," 5 разряда","")," 6 разряда","")," 1 категории","")," 2 категории","")," 3 категории",""))),IF(TRIM(SUBSTITUTE(SUBSTITUTE(SUBSTITUTE(SUBSTITUTE(SUBSTITUTE(SUBSTITUTE(SUBSTITUTE(SUBSTITUTE(SUBSTITUTE(SUBSTITUTE(SUBSTITUTE(LOWER(TRIM(D13)),"ё","е")," -","-"),"- ","-")," 2 разряда","")," 3 разряда","")," 4 разряда","")," 5 разряда","")," 6 разряда","")," 1 категории","")," 2 категории","")," 3 категории",""))="контролер","контролер отк",TRIM(SUBSTITUTE(SUBSTITUTE(SUBSTITUTE(SUBSTITUTE(SUBSTITUTE(SUBSTITUTE(SUBSTITUTE(SUBSTITUTE(SUBSTITUTE(SUBSTITUTE(SUBSTITUTE(LOWER(TRIM(D13)),"ё","е")," -","-"),"- ","-")," 2 разряда","")," 3 разряда","")," 4 разряда","")," 5 разряда","")," 6 разряда","")," 1 категории","")," 2 категории","")," 3 категории","")))))) -> старший технический работник | H13: =IF(C13="","",IF(AND(G13="мастер участка",ISNUMBER(SEARCH("РЭО",E13))),29,IFERROR(INDEX(Соответствие!$B$2:$B$100,MATCH(G13,Соответствие!$A$2:$A$100,0)),"?"))) -> 10 | I13: =IF(C13="","",IFERROR(INDEX(Перечень!$C$6:$C$52,MATCH(H13,Перечень!$A$6:$A$52,0)),"")) -> п.1.48, п.4.4, п.5.1 | J13: =IF(C13="","",IFERROR(INDEX(Перечень!$D$6:$D$52,MATCH(H13,Перечень!$A$6:$A$52,0)),12)) -> 12 | M13: =IF(AND(K13="",L13=""),"",EDATE(MAX(K13,L13),J13)) | N13: =IF(C13="","",IFERROR(INDEX(Перечень!$F$6:$F$52,MATCH(H13,Перечень!$A$6:$A$52,0)),"")) -> - | P13: =IF(O13="","",EDATE(O13,60)) | Q13: =IF(AND(K13<>"",F13<>"",K13>F13),"Да","") | R13: =IF(C13="","",IF(M13="","Нет сведений",IF(M13<TODAY(),"Просрочен",IF(M13-TODAY()<=30,"Истекает","В срок")))) -> Нет сведений | S13: =IF(AND(N13="Да",O13=""),"Не пройдено","")
A14: =IF(C14="","",ROW()-5) -> 9 | B14: Москва | C14: Лебедева Валентина Михайловна | D14: Старший технический работник | E14: Административно-хозяйственный отдел М | F14: 46065 | G14: =IF(C14="","",IF(TRIM(SUBSTITUTE(SUBSTITUTE(SUBSTITUTE(SUBSTITUTE(SUBSTITUTE(SUBSTITUTE(SUBSTITUTE(SUBSTITUTE(SUBSTITUTE(SUBSTITUTE(SUBSTITUTE(LOWER(TRIM(D14)),"ё","е")," -","-"),"- ","-")," 2 разряда","")," 3 разряда","")," 4 разряда","")," 5 разряда","")," 6 разряда","")," 1 категории","")," 2 категории","")," 3 категории",""))="инженер",IF(AND(ISNUMBER(SEARCH("техническ",E14)),ISNUMBER(SEARCH("контрол",E14))),"инженер отк",IF(ISNUMBER(SEARCH("диспетч",E14)),"инженер пдо",TRIM(SUBSTITUTE(SUBSTITUTE(SUBSTITUTE(SUBSTITUTE(SUBSTITUTE(SUBSTITUTE(SUBSTITUTE(SUBSTITUTE(SUBSTITUTE(SUBSTITUTE(SUBSTITUTE(LOWER(TRIM(D14)),"ё","е")," -","-"),"- ","-")," 2 разряда","")," 3 разряда","")," 4 разряда","")," 5 разряда","")," 6 разряда","")," 1 категории","")," 2 категории","")," 3 категории","")))),IF(TRIM(SUBSTITUTE(SUBSTITUTE(SUBSTITUTE(SUBSTITUTE(SUBSTITUTE(SUBSTITUTE(SUBSTITUTE(SUBSTITUTE(SUBSTITUTE(SUBSTITUTE(SUBSTITUTE(LOWER(TRIM(D14)),"ё","е")," -","-"),"- ","-")," 2 разряда","")," 3 разряда","")," 4 разряда","")," 5 разряда","")," 6 разряда","")," 1 категории","")," 2 категории","")," 3 категории",""))="ведущий инженер",IF(ISNUMBER(SEARCH("диспетч",E14)),"ведущий инженер пдо",TRIM(SUBSTITUTE(SUBSTITUTE(SUBSTITUTE(SUBSTITUTE(SUBSTITUTE(SUBSTITUTE(SUBSTITUTE(SUBSTITUTE(SUBSTITUTE(SUBSTITUTE(SUBSTITUTE(LOWER(TRIM(D14)),"ё","е")," -","-"),"- ","-")," 2 разряда","")," 3 разряда","")," 4 разряда","")," 5 разряда","")," 6 разряда","")," 1 категории","")," 2 категории","")," 3 категории",""))),IF(TRIM(SUBSTITUTE(SUBSTITUTE(SUBSTITUTE(SUBSTITUTE(SUBSTITUTE(SUBSTITUTE(SUBSTITUTE(SUBSTITUTE(SUBSTITUTE(SUBSTITUTE(SUBSTITUTE(LOWER(TRIM(D14)),"ё","е")," -","-"),"- ","-")," 2 разряда","")," 3 разряда","")," 4 разряда","")," 5 разряда","")," 6 разряда","")," 1 категории","")," 2 категории","")," 3 категории",""))="контролер","контролер отк",TRIM(SUBSTITUTE(SUBSTITUTE(SUBSTITUTE(SUBSTITUTE(SUBSTITUTE(SUBSTITUTE(SUBSTITUTE(SUBSTITUTE(SUBSTITUTE(SUBSTITUTE(SUBSTITUTE(LOWER(TRIM(D14)),"ё","е")," -","-"),"- ","-")," 2 разряда","")," 3 разряда","")," 4 разряда","")," 5 разряда","")," 6 разряда","")," 1 категории","")," 2 категории","")," 3 категории","")))))) -> старший технический работник | H14: =IF(C14="","",IF(AND(G14="мастер участка",ISNUMBER(SEARCH("РЭО",E14))),29,IFERROR(INDEX(Соответствие!$B$2:$B$100,MATCH(G14,Соответствие!$A$2:$A$100,0)),"?"))) -> 10 | I14: =IF(C14="","",IFERROR(INDEX(Перечень!$C$6:$C$52,MATCH(H14,Перечень!$A$6:$A$52,0)),"")) -> п.1.48, п.4.4, п.5.1 | J14: =IF(C14="","",IFERROR(INDEX(Перечень!$D$6:$D$52,MATCH(H14,Перечень!$A$6:$A$52,0)),12)) -> 12 | M14: =IF(AND(K14="",L14=""),"",EDATE(MAX(K14,L14),J14)) | N14: =IF(C14="","",IFERROR(INDEX(Перечень!$F$6:$F$52,MATCH(H14,Перечень!$A$6:$A$52,0)),"")) -> - | P14: =IF(O14="","",EDATE(O14,60)) | Q14: =IF(AND(K14<>"",F14<>"",K14>F14),"Да","") | R14: =IF(C14="","",IF(M14="","Нет сведений",IF(M14<TODAY(),"Просрочен",IF(M14-TODAY()<=30,"Истекает","В срок")))) -> Нет сведений | S14: =IF(AND(N14="Да",O14=""),"Не пройдено","")
A15: =IF(C15="","",ROW()-5) -> 10 | B15: Москва | C15: Никонова Наталия Евгеньевна | D15: Старший технический работник | E15: Административно-хозяйственный отдел М | F15: 43845 | G15: =IF(C15="","",IF(TRIM(SUBSTITUTE(SUBSTITUTE(SUBSTITUTE(SUBSTITUTE(SUBSTITUTE(SUBSTITUTE(SUBSTITUTE(SUBSTITUTE(SUBSTITUTE(SUBSTITUTE(SUBSTITUTE(LOWER(TRIM(D15)),"ё","е")," -","-"),"- ","-")," 2 разряда","")," 3 разряда","")," 4 разряда","")," 5 разряда","")," 6 разряда","")," 1 категории","")," 2 категории","")," 3 категории",""))="инженер",IF(AND(ISNUMBER(SEARCH("техническ",E15)),ISNUMBER(SEARCH("контрол",E15))),"инженер отк",IF(ISNUMBER(SEARCH("диспетч",E15)),"инженер пдо",TRIM(SUBSTITUTE(SUBSTITUTE(SUBSTITUTE(SUBSTITUTE(SUBSTITUTE(SUBSTITUTE(SUBSTITUTE(SUBSTITUTE(SUBSTITUTE(SUBSTITUTE(SUBSTITUTE(LOWER(TRIM(D15)),"ё","е")," -","-"),"- ","-")," 2 разряда","")," 3 разряда","")," 4 разряда","")," 5 разряда","")," 6 разряда","")," 1 категории","")," 2 категории","")," 3 категории","")))),IF(TRIM(SUBSTITUTE(SUBSTITUTE(SUBSTITUTE(SUBSTITUTE(SUBSTITUTE(SUBSTITUTE(SUBSTITUTE(SUBSTITUTE(SUBSTITUTE(SUBSTITUTE(SUBSTITUTE(LOWER(TRIM(D15)),"ё","е")," -","-"),"- ","-")," 2 разряда","")," 3 разряда","")," 4 разряда","")," 5 разряда","")," 6 разряда","")," 1 категории","")," 2 категории","")," 3 категории",""))="ведущий инженер",IF(ISNUMBER(SEARCH("диспетч",E15)),"ведущий инженер пдо",TRIM(SUBSTITUTE(SUBSTITUTE(SUBSTITUTE(SUBSTITUTE(SUBSTITUTE(SUBSTITUTE(SUBSTITUTE(SUBSTITUTE(SUBSTITUTE(SUBSTITUTE(SUBSTITUTE(LOWER(TRIM(D15)),"ё","е")," -","-"),"- ","-")," 2 разряда","")," 3 разряда","")," 4 разряда","")," 5 разряда","")," 6 разряда","")," 1 категории","")," 2 категории","")," 3 категории",""))),IF(TRIM(SUBSTITUTE(SUBSTITUTE(SUBSTITUTE(SUBSTITUTE(SUBSTITUTE(SUBSTITUTE(SUBSTITUTE(SUBSTITUTE(SUBSTITUTE(SUBSTITUTE(SUBSTITUTE(LOWER(TRIM(D15)),"ё","е")," -","-"),"- ","-")," 2 разряда","")," 3 разряда","")," 4 разряда","")," 5 разряда","")," 6 разряда","")," 1 категории","")," 2 категории","")," 3 категории",""))="контролер","контролер отк",TRIM(SUBSTITUTE(SUBSTITUTE(SUBSTITUTE(SUBSTITUTE(SUBSTITUTE(SUBSTITUTE(SUBSTITUTE(SUBSTITUTE(SUBSTITUTE(SUBSTITUTE(SUBSTITUTE(LOWER(TRIM(D15)),"ё","е")," -","-"),"- ","-")," 2 разряда","")," 3 разряда","")," 4 разряда","")," 5 разряда","")," 6 разряда","")," 1 категории","")," 2 категории","")," 3 категории","")))))) -> старший технический работник | H15: =IF(C15="","",IF(AND(G15="мастер участка",ISNUMBER(SEARCH("РЭО",E15))),29,IFERROR(INDEX(Соответствие!$B$2:$B$100,MATCH(G15,Соответствие!$A$2:$A$100,0)),"?"))) -> 10 | I15: =IF(C15="","",IFERROR(INDEX(Перечень!$C$6:$C$52,MATCH(H15,Перечень!$A$6:$A$52,0)),"")) -> п.1.48, п.4.4, п.5.1 | J15: =IF(C15="","",IFERROR(INDEX(Перечень!$D$6:$D$52,MATCH(H15,Перечень!$A$6:$A$52,0)),12)) -> 12 | M15: =IF(AND(K15="",L15=""),"",EDATE(MAX(K15,L15),J15)) | N15: =IF(C15="","",IFERROR(INDEX(Перечень!$F$6:$F$52,MATCH(H15,Перечень!$A$6:$A$52,0)),"")) -> - | P15: =IF(O15="","",EDATE(O15,60)) | Q15: =IF(AND(K15<>"",F15<>"",K15>F15),"Да","") | R15: =IF(C15="","",IF(M15="","Нет сведений",IF(M15<TODAY(),"Просрочен",IF(M15-TODAY()<=30,"Истекает","В срок")))) -> Нет сведений | S15: =IF(AND(N15="Да",O15=""),"Не пройдено","")
A16: =IF(C16="","",ROW()-5) -> 11 | B16: Внуково | C16: Кукин Эрнст Валерьевич | D16: Реставратор | E16: Производственное подразделение Внуково М | F16: 45789 | G16: =IF(C16="","",IF(TRIM(SUBSTITUTE(SUBSTITUTE(SUBSTITUTE(SUBSTITUTE(SUBSTITUTE(SUBSTITUTE(SUBSTITUTE(SUBSTITUTE(SUBSTITUTE(SUBSTITUTE(SUBSTITUTE(LOWER(TRIM(D16)),"ё","е")," -","-"),"- ","-")," 2 разряда","")," 3 разряда","")," 4 разряда","")," 5 разряда","")," 6 разряда","")," 1 категории","")," 2 категории","")," 3 категории",""))="инженер",IF(AND(ISNUMBER(SEARCH("техническ",E16)),ISNUMBER(SEARCH("контрол",E16))),"инженер отк",IF(ISNUMBER(SEARCH("диспетч",E16)),"инженер пдо",TRIM(SUBSTITUTE(SUBSTITUTE(SUBSTITUTE(SUBSTITUTE(SUBSTITUTE(SUBSTITUTE(SUBSTITUTE(SUBSTITUTE(SUBSTITUTE(SUBSTITUTE(SUBSTITUTE(LOWER(TRIM(D16)),"ё","е")," -","-"),"- ","-")," 2 разряда","")," 3 разряда","")," 4 разряда","")," 5 разряда","")," 6 разряда","")," 1 категории","")," 2 категории","")," 3 категории","")))),IF(TRIM(SUBSTITUTE(SUBSTITUTE(SUBSTITUTE(SUBSTITUTE(SUBSTITUTE(SUBSTITUTE(SUBSTITUTE(SUBSTITUTE(SUBSTITUTE(SUBSTITUTE(SUBSTITUTE(LOWER(TRIM(D16)),"ё","е")," -","-"),"- ","-")," 2 разряда","")," 3 разряда","")," 4 разряда","")," 5 разряда","")," 6 разряда","")," 1 категории","")," 2 категории","")," 3 категории",""))="ведущий инженер",IF(ISNUMBER(SEARCH("диспетч",E16)),"ведущий инженер пдо",TRIM(SUBSTITUTE(SUBSTITUTE(SUBSTITUTE(SUBSTITUTE(SUBSTITUTE(SUBSTITUTE(SUBSTITUTE(SUBSTITUTE(SUBSTITUTE(SUBSTITUTE(SUBSTITUTE(LOWER(TRIM(D16)),"ё","е")," -","-"),"- ","-")," 2 разряда","")," 3 разряда","")," 4 разряда","")," 5 разряда","")," 6 разряда","")," 1 категории","")," 2 категории","")," 3 категории",""))),IF(TRIM(SUBSTITUTE(SUBSTITUTE(SUBSTITUTE(SUBSTITUTE(SUBSTITUTE(SUBSTITUTE(SUBSTITUTE(SUBSTITUTE(SUBSTITUTE(SUBSTITUTE(SUBSTITUTE(LOWER(TRIM(D16)),"ё","е")," -","-"),"- ","-")," 2 разряда","")," 3 разряда","")," 4 разряда","")," 5 разряда","")," 6 разряда","")," 1 категории","")," 2 категории","")," 3 категории",""))="контролер","контролер отк",TRIM(SUBSTITUTE(SUBSTITUTE(SUBSTITUTE(SUBSTITUTE(SUBSTITUTE(SUBSTITUTE(SUBSTITUTE(SUBSTITUTE(SUBSTITUTE(SUBSTITUTE(SUBSTITUTE(LOWER(TRIM(D16)),"ё","е")," -","-"),"- ","-")," 2 разряда","")," 3 разряда","")," 4 разряда","")," 5 разряда","")," 6 разряда","")," 1 категории","")," 2 категории","")," 3 категории","")))))) -> реставратор | H16: =IF(C16="","",IF(AND(G16="мастер участка",ISNUMBER(SEARCH("РЭО",E16))),29,IFERROR(INDEX(Соответствие!$B$2:$B$100,MATCH(G16,Соответствие!$A$2:$A$100,0)),"?"))) -> 9 | I16: =IF(C16="","",IFERROR(INDEX(Перечень!$C$6:$C$52,MATCH(H16,Перечень!$A$6:$A$52,0)),"")) -> п.4.3.1, п.4.4, п.5.1, п.5.2, п.15 | J16: =IF(C16="","",IFERROR(INDEX(Перечень!$D$6:$D$52,MATCH(H16,Перечень!$A$6:$A$52,0)),12)) -> 12 | M16: =IF(AND(K16="",L16=""),"",EDATE(MAX(K16,L16),J16)) | N16: =IF(C16="","",IFERROR(INDEX(Перечень!$F$6:$F$52,MATCH(H16,Перечень!$A$6:$A$52,0)),"")) -> - | P16: =IF(O16="","",EDATE(O16,60)) | Q16: =IF(AND(K16<>"",F16<>"",K16>F16),"Да","") | R16: =IF(C16="","",IF(M16="","Нет сведений",IF(M16<TODAY(),"Просрочен",IF(M16-TODAY()<=30,"Истекает","В срок")))) -> Нет сведений | S16: =IF(AND(N16="Да",O16=""),"Не пройдено","")
A17: =IF(C17="","",ROW()-5) -> 12 | B17: Внуково | C17: Туманов Сергей Дмитриевич | D17: Электромонтажник 4 разряда | E17: Производственное подразделение Внуково М | F17: 45429 | G17: =IF(C17="","",IF(TRIM(SUBSTITUTE(SUBSTITUTE(SUBSTITUTE(SUBSTITUTE(SUBSTITUTE(SUBSTITUTE(SUBSTITUTE(SUBSTITUTE(SUBSTITUTE(SUBSTITUTE(SUBSTITUTE(LOWER(TRIM(D17)),"ё","е")," -","-"),"- ","-")," 2 разряда","")," 3 разряда","")," 4 разряда","")," 5 разряда","")," 6 разряда","")," 1 категории","")," 2 категории","")," 3 категории",""))="инженер",IF(AND(ISNUMBER(SEARCH("техническ",E17)),ISNUMBER(SEARCH("контрол",E17))),"инженер отк",IF(ISNUMBER(SEARCH("диспетч",E17)),"инженер пдо",TRIM(SUBSTITUTE(SUBSTITUTE(SUBSTITUTE(SUBSTITUTE(SUBSTITUTE(SUBSTITUTE(SUBSTITUTE(SUBSTITUTE(SUBSTITUTE(SUBSTITUTE(SUBSTITUTE(LOWER(TRIM(D17)),"ё","е")," -","-"),"- ","-")," 2 разряда","")," 3 разряда","")," 4 разряда","")," 5 разряда","")," 6 разряда","")," 1 категории","")," 2 категории","")," 3 категории","")))),IF(TRIM(SUBSTITUTE(SUBSTITUTE(SUBSTITUTE(SUBSTITUTE(SUBSTITUTE(SUBSTITUTE(SUBSTITUTE(SUBSTITUTE(SUBSTITUTE(SUBSTITUTE(SUBSTITUTE(LOWER(TRIM(D17)),"ё","е")," -","-"),"- ","-")," 2 разряда","")," 3 разряда","")," 4 разряда","")," 5 разряда","")," 6 разряда","")," 1 категории","")," 2 категории","")," 3 категории",""))="ведущий инженер",IF(ISNUMBER(SEARCH("диспетч",E17)),"ведущий инженер пдо",TRIM(SUBSTITUTE(SUBSTITUTE(SUBSTITUTE(SUBSTITUTE(SUBSTITUTE(SUBSTITUTE(SUBSTITUTE(SUBSTITUTE(SUBSTITUTE(SUBSTITUTE(SUBSTITUTE(LOWER(TRIM(D17)),"ё","е")," -","-"),"- ","-")," 2 разряда","")," 3 разряда","")," 4 разряда","")," 5 разряда","")," 6 разряда","")," 1 категории","")," 2 категории","")," 3 категории",""))),IF(TRIM(SUBSTITUTE(SUBSTITUTE(SUBSTITUTE(SUBSTITUTE(SUBSTITUTE(SUBSTITUTE(SUBSTITUTE(SUBSTITUTE(SUBSTITUTE(SUBSTITUTE(SUBSTITUTE(LOWER(TRIM(D17)),"ё","е")," -","-"),"- ","-")," 2 разряда","")," 3 разряда","")," 4 разряда","")," 5 разряда","")," 6 разряда","")," 1 категории","")," 2 категории","")," 3 категории",""))="контролер","контролер отк",TRIM(SUBSTITUTE(SUBSTITUTE(SUBSTITUTE(SUBSTITUTE(SUBSTITUTE(SUBSTITUTE(SUBSTITUTE(SUBSTITUTE(SUBSTITUTE(SUBSTITUTE(SUBSTITUTE(LOWER(TRIM(D17)),"ё","е")," -","-"),"- ","-")," 2 разряда","")," 3 разряда","")," 4 разряда","")," 5 разряда","")," 6 разряда","")," 1 категории","")," 2 категории","")," 3 категории","")))))) -> электромонтажник | H17: =IF(C17="","",IF(AND(G17="мастер участка",ISNUMBER(SEARCH("РЭО",E17))),29,IFERROR(INDEX(Соответствие!$B$2:$B$100,MATCH(G17,Соответствие!$A$2:$A$100,0)),"?"))) -> 20 | I17: =IF(C17="","",IFERROR(INDEX(Перечень!$C$6:$C$52,MATCH(H17,Перечень!$A$6:$A$52,0)),"")) -> п.4.3.1, п.4.3.2, п.4.4, п.4.9, п.5.1, п.5.2, п.6.2, п.9 | J17: =IF(C17="","",IFERROR(INDEX(Перечень!$D$6:$D$52,MATCH(H17,Перечень!$A$6:$A$52,0)),12)) -> 12 | M17: =IF(AND(K17="",L17=""),"",EDATE(MAX(K17,L17),J17)) | N17: =IF(C17="","",IFERROR(INDEX(Перечень!$F$6:$F$52,MATCH(H17,Перечень!$A$6:$A$52,0)),"")) -> Да | P17: =IF(O17="","",EDATE(O17,60)) | Q17: =IF(AND(K17<>"",F17<>"",K17>F17),"Да","") | R17: =IF(C17="","",IF(M17="","Нет сведений",IF(M17<TODAY(),"Просрочен",IF(M17-TODAY()<=30,"Истекает","В срок")))) -> Нет сведений | S17: =IF(AND(N17="Да",O17=""),"Не пройдено","") -> Не пройдено
... A22: =IF(C22="","",ROW()-5) -> 17 | B22: Внуково | C22: Постульгин Александр Валентинович | D22: Слесарь-сборщик 5 разряда | E22: Производственное подразделение Внуково М | F22: 45208 | G22: =IF(C22="","",IF(TRIM(SUBSTITUTE(SUBSTITUTE(SUBSTITUTE(SUBSTITUTE(SUBSTITUTE(SUBSTITUTE(SUBSTITUTE(SUBSTITUTE(SUBSTITUTE(SUBSTITUTE(SUBSTITUTE(LOWER(TRIM(D22)),"ё","е")," -","-"),"- ","-")," 2 разряда","")," 3 разряда","")," 4 разряда","")," 5 разряда","")," 6 разряда","")," 1 категории","")," 2 категории","")," 3 категории",""))="инженер",IF(AND(ISNUMBER(SEARCH("техническ",E22)),ISNUMBER(SEARCH("контрол",E22))),"инженер отк",IF(ISNUMBER(SEARCH("диспетч",E22)),"инженер пдо",TRIM(SUBSTITUTE(SUBSTITUTE(SUBSTITUTE(SUBSTITUTE(SUBSTITUTE(SUBSTITUTE(SUBSTITUTE(SUBSTITUTE(SUBSTITUTE(SUBSTITUTE(SUBSTITUTE(LOWER(TRIM(D22)),"ё","е")," -","-"),"- ","-")," 2 разряда","")," 3 разряда","")," 4 разряда","")," 5 разряда","")," 6 разряда","")," 1 категории","")," 2 категории","")," 3 категории","")))),IF(TRIM(SUBSTITUTE(SUBSTITUTE(SUBSTITUTE(SUBSTITUTE(SUBSTITUTE(SUBSTITUTE(SUBSTITUTE(SUBSTITUTE(SUBSTITUTE(SUBSTITUTE(SUBSTITUTE(LOWER(TRIM(D22)),"ё","е")," -","-"),"- ","-")," 2 разряда","")," 3 разряда","")," 4 разряда","")," 5 разряда","")," 6 разряда","")," 1 категории","")," 2 категории","")," 3 категории",""))="ведущий инженер",IF(ISNUMBER(SEARCH("диспетч",E22)),"ведущий инженер пдо",TRIM(SUBSTITUTE(SUBSTITUTE(SUBSTITUTE(SUBSTITUTE(SUBSTITUTE(SUBSTITUTE(SUBSTITUTE(SUBSTITUTE(SUBSTITUTE(SUBSTITUTE(SUBSTITUTE(LOWER(TRIM(D22)),"ё","е")," -","-"),"- ","-")," 2 разряда","")," 3 разряда","")," 4 разряда","")," 5 разряда","")," 6 разряда","")," 1 категории","")," 2 категории","")," 3 категории",""))),IF(TRIM(SUBSTITUTE(SUBSTITUTE(SUBSTITUTE(SUBSTITUTE(SUBSTITUTE(SUBSTITUTE(SUBSTITUTE(SUBSTITUTE(SUBSTITUTE(SUBSTITUTE(SUBSTITUTE(LOWER(TRIM(D22)),"ё","е")," -","-"),"- ","-")," 2 разряда","")," 3 разряда","")," 4 разряда","")," 5 разряда","")," 6 разряда","")," 1 категории","")," 2 категории","")," 3 категории",""))="контролер","контролер отк",TRIM(SUBSTITUTE(SUBSTITUTE(SUBSTITUTE(SUBSTITUTE(SUBSTITUTE(SUBSTITUTE(SUBSTITUTE(SUBSTITUTE(SUBSTITUTE(SUBSTITUTE(SUBSTITUTE(LOWER(TRIM(D22)),"ё","е")," -","-"),"- ","-")," 2 разряда","")," 3 разряда","")," 4 разряда","")," 5 разряда","")," 6 разряда","")," 1 категории","")," 2 категории","")," 3 категории","")))))) -> слесарь-сборщик | H22: =IF(C22="","",IF(AND(G22="мастер участка",ISNUMBER(SEARCH("РЭО",E22))),29,IFERROR(INDEX(Соответствие!$B$2:$B$100,MATCH(G22,Соответствие!$A$2:$A$100,0)),"?"))) -> 19 | I22: =IF(C22="","",IFERROR(INDEX(Перечень!$C$6:$C$52,MATCH(H22,Перечень!$A$6:$A$52,0)),"")) -> п.4.3.1, п.4.3.2, п.4.4, п.5.1, п.6.2, п.15 | J22: =IF(C22="","",IFERROR(INDEX(Перечень!$D$6:$D$52,MATCH(H22,Перечень!$A$6:$A$52,0)),12)) -> 12 | M22: =IF(AND(K22="",L22=""),"",EDATE(MAX(K22,L22),J22)) | N22: =IF(C22="","",IFERROR(INDEX(Перечень!$F$6:$F$52,MATCH(H22,Перечень!$A$6:$A$52,0)),"")) -> - | P22: =IF(O22="","",EDATE(O22,60)) | Q22: =IF(AND(K22<>"",F22<>"",K22>F22),"Да","") | R22: =IF(C22="","",IF(M22="","Нет сведений",IF(M22<TODAY(),"Просрочен",IF(M22-TODAY()<=30,"Истекает","В срок")))) -> Нет сведений | S22: =IF(AND(N22="Да",O22=""),"Не пройдено","")
A23: =IF(C23="","",ROW()-5) -> 18 | B23: Внуково | C23: Луданцев Алексей Владимирович | D23: Слесарь-сборщик 4 разряда | E23: Производственное подразделение Внуково М | F23: 45950 | G23: =IF(C23="","",IF(TRIM(SUBSTITUTE(SUBSTITUTE(SUBSTITUTE(SUBSTITUTE(SUBSTITUTE(SUBSTITUTE(SUBSTITUTE(SUBSTITUTE(SUBSTITUTE(SUBSTITUTE(SUBSTITUTE(LOWER(TRIM(D23)),"ё","е")," -","-"),"- ","-")," 2 разряда","")," 3 разряда","")," 4 разряда","")," 5 разряда","")," 6 разряда","")," 1 категории","")," 2 категории","")," 3 категории",""))="инженер",IF(AND(ISNUMBER(SEARCH("техническ",E23)),ISNUMBER(SEARCH("контрол",E23))),"инженер отк",IF(ISNUMBER(SEARCH("диспетч",E23)),"инженер пдо",TRIM(SUBSTITUTE(SUBSTITUTE(SUBSTITUTE(SUBSTITUTE(SUBSTITUTE(SUBSTITUTE(SUBSTITUTE(SUBSTITUTE(SUBSTITUTE(SUBSTITUTE(SUBSTITUTE(LOWER(TRIM(D23)),"ё","е")," -","-"),"- ","-")," 2 разряда","")," 3 разряда","")," 4 разряда","")," 5 разряда","")," 6 разряда","")," 1 категории","")," 2 категории","")," 3 категории","")))),IF(TRIM(SUBSTITUTE(SUBSTITUTE(SUBSTITUTE(SUBSTITUTE(SUBSTITUTE(SUBSTITUTE(SUBSTITUTE(SUBSTITUTE(SUBSTITUTE(SUBSTITUTE(SUBSTITUTE(LOWER(TRIM(D23)),"ё","е")," -","-"),"- ","-")," 2 разряда","")," 3 разряда","")," 4 разряда","")," 5 разряда","")," 6 разряда","")," 1 категории","")," 2 категории","")," 3 категории",""))="ведущий инженер",IF(ISNUMBER(SEARCH("диспетч",E23)),"ведущий инженер пдо",TRIM(SUBSTITUTE(SUBSTITUTE(SUBSTITUTE(SUBSTITUTE(SUBSTITUTE(SUBSTITUTE(SUBSTITUTE(SUBSTITUTE(SUBSTITUTE(SUBSTITUTE(SUBSTITUTE(LOWER(TRIM(D23)),"ё","е")," -","-"),"- ","-")," 2 разряда","")," 3 разряда","")," 4 разряда","")," 5 разряда","")," 6 разряда","")," 1 категории","")," 2 категории","")," 3 категории",""))),IF(TRIM(SUBSTITUTE(SUBSTITUTE(SUBSTITUTE(SUBSTITUTE(SUBSTITUTE(SUBSTITUTE(SUBSTITUTE(SUBSTITUTE(SUBSTITUTE(SUBSTITUTE(SUBSTITUTE(LOWER(TRIM(D23)),"ё","е")," -","-"),"- ","-")," 2 разряда","")," 3 разряда","")," 4 разряда","")," 5 разряда","")," 6 разряда","")," 1 категории","")," 2 категории","")," 3 категории",""))="контролер","контролер отк",TRIM(SUBSTITUTE(SUBSTITUTE(SUBSTITUTE(SUBSTITUTE(SUBSTITUTE(SUBSTITUTE(SUBSTITUTE(SUBSTITUTE(SUBSTITUTE(SUBSTITUTE(SUBSTITUTE(LOWER(TRIM(D23)),"ё","е")," -","-"),"- ","-")," 2 разряда","")," 3 разряда","")," 4 разряда","")," 5 разряда","")," 6 разряда","")," 1 категории","")," 2 категории","")," 3 категории","")))))) -> слесарь-сборщик | H23: =IF(C23="","",IF(AND(G23="мастер участка",ISNUMBER(SEARCH("РЭО",E23))),29,IFERROR(INDEX(Соответствие!$B$2:$B$100,MATCH(G23,Соответствие!$A$2:$A$100,0)),"?"))) -> 19 | I23: =IF(C23="","",IFERROR(INDEX(Перечень!$C$6:$C$52,MATCH(H23,Перечень!$A$6:$A$52,0)),"")) -> п.4.3.1, п.4.3.2, п.4.4, п.5.1, п.6.2, п.15 | J23: =IF(C23="","",IFERROR(INDEX(Перечень!$D$6:$D$52,MATCH(H23,Перечень!$A$6:$A$52,0)),12)) -> 12 | K23: 45940 | M23: =IF(AND(K23="",L23=""),"",EDATE(MAX(K23,L23),J23)) -> 46305 | N23: =IF(C23="","",IFERROR(INDEX(Перечень!$F$6:$F$52,MATCH(H23,Перечень!$A$6:$A$52,0)),"")) -> - | P23: =IF(O23="","",EDATE(O23,60)) | Q23: =IF(AND(K23<>"",F23<>"",K23>F23),"Да","") | R23: =IF(C23="","",IF(M23="","Нет сведений",IF(M23<TODAY(),"Просрочен",IF(M23-TODAY()<=30,"Истекает","В срок")))) -> Просрочен | S23: =IF(AND(N23="Да",O23=""),"Не пройдено","")
